File: examples/pyrolysis/single_element/1D/gold/experiment_comp/10degpermin_run1.csv
Time (min),Temperature (degC),Weight (mg),Heat Flow (mW),Temperature Difference (degC),Temperature Difference (muV),Sample Purge Flow (mL/min)
0.002555556,50.50644,14.68787,-8.032394,-0.1231909,-0.596403,142.5301
0.1291666,50.29219,14.68843,-8.007421,-0.12061,-0.5834639,100.001
0.2625,50.14282,14.6885,-7.973139,-0.1166175,-0.5638082,99.98384
0.3958334,50.09707,14.68851,-7.929844,-0.1110833,-0.5369004,100.0164
0.5291666,50.20232,14.68872,-7.894394,-0.1061218,-0.5130212,100.029
0.6625,50.48578,14.6888,-7.886218,-0.1042313,-0.5042828,99.98155
0.7958334,50.9718,14.68905,-7.916984,-0.1069092,-0.517993,100.0027
0.9291668,51.65722,14.68923,-7.99377,-0.1150327,-0.5585562,99.98628
1.0625,52.54526,14.68946,-8.123564,-0.1294794,-0.6305027,99.98812
1.195833,53.62124,14.68943,-8.300574,-0.1494276,-0.7302053,99.97297
1.329166,54.85624,14.68966,-8.521707,-0.1744619,-0.8560284,99.97375
1.4625,56.23588,14.68961,-8.777785,-0.2033437,-1.002316,100.0391
1.595833,57.72098,14.68987,-9.059653,-0.2348832,-1.163539,99.97553
1.729166,59.29444,14.68982,-9.358501,-0.2679647,-1.334404,100.0069
1.8625,60.92122,14.68941,-9.667999,-0.3018809,-1.511154,99.99141
1.995833,62.57224,14.68935,-9.976775,-0.3353043,-1.686922,100.0256
2.129166,64.24328,14.68876,-10.27756,-0.3672794,-1.857177,99.95549
2.2625,65.88649,14.68875,-10.56165,-0.3968313,-2.0167,99.96911
2.395833,67.50862,14.68849,-10.82825,-0.423964,-2.165221,100.0043
2.529167,69.09134,14.68798,-11.06963,-0.4477675,-2.29781,99.9779
2.6625,70.63329,14.68739,-11.28774,-0.4685946,-2.415923,100.0256
2.795834,72.12465,14.68677,-11.4803,-0.4862379,-2.518176,100.0527
2.929166,73.56356,14.68611,-11.64189,-0.5000554,-2.600998,100.0016
3.0625,74.95889,14.68533,-11.77705,-0.51067,-2.667348,99.99156
3.195834,76.3097,14.68474,-11.8818,-0.5176334,-2.714646,100.0451
3.329167,77.62558,14.68394,-11.97168,-0.5228816,-2.752886,100.0067
3.4625,78.90376,14.68322,-12.03623,-0.5251355,-2.775178,100.0346
3.595833,80.15375,14.68238,-12.0887,-0.5261663,-2.79006,100.0215
3.729167,81.3902,14.68133,-12.12477,-0.5252885,-2.794602,100.0006
3.8625,82.61456,14.68062,-12.15144,-0.5233287,-2.793236,100.0407
3.995834,83.82715,14.6798,-12.16998,-0.5204388,-2.78675,99.98504
4.129166,85.04338,14.67844,-12.17989,-0.5165217,-2.774648,99.98813
4.2625,86.25886,14.67781,-12.19178,-0.512858,-2.763794,99.98219
4.395834,87.48928,14.67678,-12.20117,-0.5088834,-2.751195,99.97059
4.529167,88.73601,14.67592,-12.21246,-0.5051041,-2.739616,100.0146
4.6625,89.9873,14.67463,-12.2253,-0.5014944,-2.728896,100.0531
4.795833,91.26031,14.6738,-12.24082,-0.498143,-2.719602,100.0841
4.929167,92.55613,14.67273,-12.25789,-0.4949307,-2.711065,99.99866
5.0625,93.86476,14.67133,-12.28916,-0.493338,-2.711452,99.98628
5.195833,95.18949,14.67029,-12.31632,-0.4912234,-2.708982,99.99539
5.329168,96.52914,14.66918,-12.34603,-0.4893418,-2.707865,99.97074
5.4625,97.88394,14.66798,-12.38356,-0.4883666,-2.711649,100.0015
5.595832,99.25138,14.66644,-12.42008,-0.4873547,-2.714576,99.96554
5.729166,100.6256,14.66539,-12.45606,-0.4862484,-2.716985,100.0159
5.8625,102.0164,14.66405,-12.49953,-0.485979,-2.724108,99.96711
5.995834,103.405,14.66243,-12.53731,-0.4850444,-2.727498,100.0127
6.129166,104.7965,14.66131,-12.57622,-0.484245,-2.73162,99.97582
6.2625,106.184,14.65995,-12.61288,-0.4831867,-2.734254,100.012
6.395834,107.579,14.65849,-12.64802,-0.4819617,-2.735905,100.0135
6.529166,108.9572,14.65713,-12.68189,-0.4806297,-2.736854,100.0141
6.6625,110.3384,14.65586,-12.70969,-0.4786317,-2.733925,99.99522
6.795832,111.7142,14.6542,-12.73348,-0.4762112,-2.728472,100.0839
6.929168,113.084,14.65262,-12.75339,-0.4733989,-2.72063,99.98749
7.0625,114.4438,14.65094,-12.76972,-0.4702282,-2.710578,100.0044
7.195832,115.7992,14.64933,-12.784,-0.4668758,-2.699316,100.0102
7.329168,117.1458,14.64761,-12.7907,-0.4627799,-2.683255,100.0155
7.4625,118.4841,14.64574,-12.79928,-0.4590092,-2.668545,100.0371
7.595834,119.8201,14.64401,-12.80526,-0.4549916,-2.652242,99.99618
7.729166,121.1561,14.64221,-12.80955,-0.4508242,-2.634918,100.0454
7.8625,122.4829,14.64038,-12.81244,-0.4465389,-2.61675,99.98638
7.995834,123.8108,14.63902,-12.81139,-0.4418541,-2.596081,99.97356
8.129166,125.1448,14.6372,-12.80963,-0.437116,-2.574954,100.0007
8.2625,126.4717,14.63536,-12.80565,-0.4321679,-2.552428,100.0296
8.395832,127.7945,14.63317,-12.80261,-0.4273648,-2.530585,100.0186
8.529166,129.1248,14.6313,-12.7969,-0.4222859,-2.506969,100.0043
8.6625,130.4494,14.62931,-12.79625,-0.417804,-2.486725,100.0161
8.795834,131.784,14.62732,-12.79144,-0.4128782,-2.463716,100.0283
8.929168,133.1208,14.62511,-12.79262,-0.4086195,-2.444559,99.99103
9.0625,134.4564,14.62296,-12.79066,-0.4040456,-2.423375,99.9722
9.195832,135.796,14.62095,-12.79042,-0.3997017,-2.403329,99.97152
9.329166,137.14,14.61878,-12.79004,-0.3954267,-2.383154,100.0236
9.4625,138.482,14.61664,-12.7917,-0.3913925,-2.364307,99.98041
9.595834,139.8302,14.6146,-12.79052,-0.3870672,-2.343591,100.0219
9.729168,141.1762,14.61218,-12.79187,-0.383055,-2.324626,99.99989
9.8625,142.5255,14.61005,-12.79876,-0.3796386,-2.30919,99.98182
9.995834,143.8724,14.6076,-12.79879,-0.375516,-2.289342,100.0373
10.12917,145.2261,14.60546,-12.79925,-0.3714638,-2.269802,99.97978
10.2625,146.5772,14.60311,-12.8042,-0.3679201,-2.253248,100.0026
10.39583,147.9228,14.60078,-12.80146,-0.3635889,-2.231748,99.94246
10.52916,149.2698,14.59838,-12.80488,-0.3599358,-2.214289,100.0188
10.6625,150.6155,14.59594,-12.80518,-0.3559794,-2.194848,100.0053
10.79584,151.9654,14.59356,-12.80405,-0.3518998,-2.174526,100.045
10.92917,153.3062,14.5908,-12.80465,-0.3480325,-2.155391,99.97869
11.0625,154.6532,14.58868,-12.80058,-0.3436962,-2.133236,100.0217
11.19583,155.9991,14.58588,-12.80051,-0.339854,-2.113754,100.0225
11.32916,157.3416,14.58369,-12.803,-0.33633,-2.096025,100.0021
11.4625,158.6816,14.58124,-12.79816,-0.332056,-2.073526,100.0112
11.59584,160.0174,14.57863,-12.79037,-0.327517,-2.049237,100.004
11.72917,161.3571,14.5759,-12.78457,-0.3232028,-2.026244,99.98481
11.8625,162.6949,14.57323,-12.77568,-0.3186026,-2.001329,100.0181
11.99584,164.0331,14.57054,-12.77412,-0.3147793,-1.981189,99.97478
12.12916,165.3767,14.5681,-12.77383,-0.3111096,-1.961915,99.98101
12.2625,166.7099,14.56564,-12.76458,-0.306542,-1.936867,99.99059
12.39583,168.0504,14.56295,-12.75957,-0.3024319,-1.914599,100.0248
12.52916,169.3896,14.56039,-12.75602,-0.2984961,-1.893327,100.0317
12.6625,170.7223,14.55751,-12.75086,-0.2944228,-1.871074,100.0016
12.79584,172.0564,14.55512,-12.74666,-0.2904681,-1.849471,100.0096
12.92917,173.3938,14.55228,-12.74162,-0.2864413,-1.827313,100.0066
13.0625,174.7267,14.54986,-12.7324,-0.2820188,-1.802515,99.97578
13.19583,176.0646,14.54714,-12.72848,-0.2781822,-1.781159,99.98809
13.32916,177.3971,14.54451,-12.7258,-0.2745041,-1.760645,100.0036
13.4625,178.7389,14.54202,-12.71994,-0.2705211,-1.738088,99.9675
13.59584,180.0771,14.53905,-12.71355,-0.2664995,-1.715192,100.0002
13.72917,181.4128,14.53669,-12.70618,-0.2623987,-1.691693,99.99456
13.8625,182.7516,14.53375,-12.7081,-0.2592525,-1.674263,100.0005
13.99583,184.0897,14.53115,-12.70023,-0.2551406,-1.65051,99.96144
14.12917,185.4244,14.52871,-12.69299,-0.2511053,-1.627164,99.98699
14.2625,186.7683,14.52601,-12.68866,-0.2473732,-1.605699,99.9958
14.39583,188.1086,14.52313,-12.68401,-0.2436202,-1.584016,100.0175
14.52916,189.4497,14.52052,-12.67204,-0.2391621,-1.55765,100.0167
14.6625,190.7865,14.51791,-12.66981,-0.2356956,-1.53765,99.98405
14.79584,192.1324,14.5151,-12.65783,-0.2312735,-1.511327,100.0083
14.92917,193.4675,14.51258,-12.64833,-0.2271146,-1.486629,100.0678
15.0625,194.8052,14.50996,-12.64034,-0.2231228,-1.462933,99.97695
15.19583,196.1445,14.50733,-12.63082,-0.2190136,-1.438301,100.0389
15.32916,197.4757,14.50449,-12.61932,-0.214743,-1.412402,100.005
15.4625,198.8138,14.50204,-12.60584,-0.2102905,-1.38522,100.0094
15.59584,200.1525,14.49922,-12.59715,-0.2056912,-1.356975,99.99069
15.72917,201.491,14.49647,-12.6058,-0.2010223,-1.328182,100.014
15.8625,202.8338,14.49378,-12.60423,-0.1967036,-1.301612,99.99879
15.99583,204.1716,14.49142,-12.59351,-0.1916194,-1.269876,100.0167
16.12917,205.511,14.48878,-12.59276,-0.1875886,-1.245035,100.0053
16.2625,206.8512,14.48614,-12.58418,-0.1828902,-1.215673,100.0055
16.39584,208.1939,14.48361,-12.57483,-0.1781933,-1.186224,99.994
16.52917,209.5353,14.48094,-12.56244,-0.1733052,-1.155409,100.0005
16.6625,210.8725,14.47831,-12.54752,-0.1682764,-1.123553,100.0437
16.79584,212.2135,14.47559,-12.52796,-0.162884,-1.089166,99.99794
16.92917,213.5494,14.47307,-12.50997,-0.1577327,-1.056282,100.0382
17.0625,214.8893,14.47047,-12.4848,-0.1519856,-1.019301,99.95569
17.19583,216.2311,14.46782,-12.45958,-0.1463075,-0.9826704,99.99468
17.32916,217.5664,14.46513,-12.43705,-0.1409783,-0.948188,99.99216
17.4625,218.9095,14.46246,-12.41272,-0.1355315,-0.9127919,100.0297
17.59583,220.2496,14.45981,-12.38337,-0.1297074,-0.8747509,99.97111
17.72916,221.592,14.45711,-12.35605,-0.1241266,-0.8382492,99.97678
17.8625,222.9283,14.45442,-12.32559,-0.118342,-0.8002632,100.056
17.99583,224.2673,14.45188,-12.2896,-0.1121203,-0.7592119,99.93497
18.12917,225.6064,14.44919,-12.25662,-0.1062232,-0.7202485,99.99134
18.2625,226.9477,14.44638,-12.21665,-0.0997633,-0.6773559,100.0324
18.39584,228.2902,14.44368,-12.18382,-0.0939778,-0.63893,100.0278
18.52917,229.627,14.44076,-12.14253,-0.08752478,-0.5958544,100.0155
18.6625,230.964,14.43818,-12.10377,-0.08134001,-0.5544882,100.0046
18.79584,232.3071,14.43539,-12.06222,-0.07494799,-0.5115958,100.0184
18.92917,233.6424,14.43249,-12.02148,-0.0686911,-0.4695097,100.0434
19.0625,234.9801,14.42976,-11.98435,-0.0627772,-0.4296572,100.0026
19.19583,236.32,14.42677,-11.94105,-0.056376,-0.3863574,100.0003
19.32916,237.6578,14.42402,-11.90284,-0.05044888,-0.3461922,99.98985
19.4625,238.9972,14.421,-11.86098,-0.0442508,-0.304032,100.0205
19.59583,240.3351,14.41812,-11.83606,-0.03950366,-0.2717467,99.96168
19.72916,241.6764,14.4147,-11.80392,-0.03416898,-0.2353348,100.0266
19.8625,243.0062,14.4121,-11.77374,-0.02904341,-0.2002765,100.0263
19.99583,244.3512,14.40902,-11.74572,-0.02408719,-0.1663008,100.0146
20.12917,245.6877,14.40581,-11.72372,-0.01966046,-0.135902,100.0093
20.2625,247.022,14.40263,-11.70292,-0.01534834,-0.1062227,100.0466
20.39584,248.3611,14.39931,-11.69033,-0.01170916,-0.0811345,100.0008
20.52917,249.6934,14.39624,-11.68053,-8.31E-03,-0.05766709,99.99551
20.6625,251.0291,14.39303,-11.67685,-5.41E-03,-0.03757358,100.0229
20.79584,252.3634,14.3895,-11.68172,-3.20E-03,-0.02223458,99.95566
20.92917,253.7008,14.38636,-11.68859,-1.13E-03,-7.90E-03,99.97072
21.0625,255.0333,14.38287,-11.70194,4.09E-04,0.002854278,99.96438
21.19583,256.3668,14.37958,-11.72074,0.001530129,0.01067948,99.99519
21.32916,257.698,14.37611,-11.74681,0.002082684,0.01455303,99.95781
21.4625,259.0228,14.37234,-11.78024,0.002059685,0.01440914,99.98382
21.59583,260.3589,14.36885,-11.81195,0.002211323,0.01548705,100.0374
21.72916,261.6902,14.36534,-11.85561,0.001431362,0.0100354,100.0173
21.8625,263.0208,14.36179,-11.90567,1.75E-04,0.001225552,100.0203
21.99583,264.3502,14.35804,-11.95671,-1.13E-03,-7.95E-03,99.99469
22.12917,265.6828,14.35415,-12.01243,-2.77E-03,-0.01951536,99.99131
22.2625,267.0108,14.35051,-12.07624,-5.02E-03,-0.03538056,99.97228
22.39584,268.3406,14.34675,-12.13676,-6.98E-03,-0.04921572,99.97156
22.52917,269.6721,14.3427,-12.20902,-9.82E-03,-0.06927839,100.0176
22.6625,271.0013,14.33865,-12.2757,-0.01218823,-0.08611454,100.0008
22.79584,272.3283,14.33472,-12.3468,-0.01486982,-0.105176,100.001
22.92917,273.66,14.33052,-12.42473,-0.01803998,-0.1277386,100.0104
23.0625,274.9876,14.32638,-12.49825,-0.02084184,-0.1477394,100.0044
23.19583,276.3173,14.32249,-12.57409,-0.02378856,-0.1688114,100.0178
23.32916,277.6465,14.31827,-12.64576,-0.02638209,-0.1874204,99.99188
23.4625,278.977,14.31394,-12.72289,-0.02935878,-0.2087948,100.0004
23.59583,280.3025,14.30938,-12.79726,-0.03210168,-0.2285436,100.0054
23.72916,281.6296,14.30518,-12.87159,-0.03481082,-0.2480815,100.0547
23.8625,282.9592,14.30068,-12.94425,-0.03736339,-0.266541,99.99048
23.99583,284.2908,14.29633,-13.01649,-0.03985232,-0.2845839,100.0103
24.12917,285.6175,14.29159,-13.09346,-0.04267709,-0.305063,99.96571
24.2625,286.949,14.28684,-13.16384,-0.04496784,-0.321763,100.0617
24.39584,288.2809,14.28196,-13.23445,-0.04725198,-0.3384485,99.97856
24.52917,289.6018,14.27731,-13.30098,-0.04921546,-0.3528674,99.96139
24.6625,290.934,14.27236,-13.3691,-0.05126236,-0.3679152,99.98442
24.79584,292.265,14.26746,-13.43628,-0.05322086,-0.3823566,100.0208
24.92917,293.5924,14.26214,-13.50249,-0.05508406,-0.3961421,99.98574
25.0625,294.9244,14.257,-13.57165,-0.05714493,-0.4113774,100.0043
25.19583,296.252,14.25166,-13.63194,-0.05852344,-0.4217266,99.99992
25.32916,297.5816,14.2463,-13.70209,-0.06061921,-0.437269,100.0295
25.4625,298.9089,14.24076,-13.76614,-0.0622376,-0.4493963,100.0211
25.59583,300.2404,14.23509,-13.82884,-0.06373652,-0.460684,100.0382
25.72916,301.5693,14.22966,-13.88906,-0.0650335,-0.4705119,99.99969
25.8625,302.9004,14.22387,-13.94659,-0.06612022,-0.4788252,99.98864
25.99583,304.232,14.21811,-14.01003,-0.06762376,-0.490176,100.007
26.12917,305.5559,14.21192,-14.06956,-0.06882378,-0.4993454,100.0193
26.2625,306.894,14.20576,-14.12164,-0.06945306,-0.5043878,99.97484
26.39584,308.2217,14.19946,-14.18009,-0.07054062,-0.5127705,100.0592
26.52917,309.5542,14.19309,-14.24344,-0.07197356,-0.5236816,100.0107
26.6625,310.882,14.18649,-14.29306,-0.0723861,-0.5271817,99.99681
26.79584,312.2184,14.17985,-14.34844,-0.07320218,-0.5336301,100.0028
26.92916,313.5468,14.17315,-14.40419,-0.07403715,-0.540228,99.98842
27.0625,314.8787,14.16616,-14.45554,-0.0745387,-0.544403,99.99472
27.19584,316.2112,14.15911,-14.50991,-0.07524118,-0.5500561,100.0237
27.32916,317.5404,14.15192,-14.55606,-0.0753459,-0.5513433,99.9765
27.4625,318.8696,14.14452,-14.60633,-0.07573468,-0.5547144,100.0074
27.59583,320.2052,14.13708,-14.65562,-0.07604084,-0.557486,100.0064
27.72916,321.5368,14.12958,-14.7058,-0.07640378,-0.5606682,99.97676
27.8625,322.868,14.12212,-14.72722,-0.07467798,-0.5484887,99.97968
27.99583,324.2034,14.11444,-14.76912,-0.0744253,-0.5471172,100.0259
28.12917,325.5272,14.10633,-14.80875,-0.07401181,-0.5445592,99.97906
28.2625,326.8632,14.09813,-14.84594,-0.07340585,-0.5405798,100.017
28.39584,328.1979,14.08976,-14.88409,-0.07286813,-0.5370958,99.9642
28.52917,329.5276,14.08168,-14.92342,-0.07240738,-0.5341738,99.97528
28.6625,330.8575,14.07429,-14.96154,-0.07185571,-0.5305744,99.98324
28.79584,332.1858,14.06602,-14.9986,-0.07122545,-0.5263874,99.99238
28.92916,333.5162,14.057,-15.03072,-0.07022806,-0.5194786,100.0283
29.0625,334.8467,14.04825,-15.06747,-0.06955832,-0.5149834,99.98656
29.19584,336.1757,14.03927,-15.10342,-0.06882888,-0.5100374,100.0164
29.32916,337.5134,14.03,-15.142,-0.06827593,-0.5063922,99.97871
29.4625,338.8466,14.02082,-15.17376,-0.06723075,-0.4990864,100.0185
29.59583,340.1769,14.01134,-15.20513,-0.066156,-0.4915477,99.99068
29.72916,341.5066,14.00177,-15.23442,-0.064927,-0.482843,100.0122
29.8625,342.8368,13.99188,-15.26862,-0.06405006,-0.4767264,99.97304
29.99583,344.17,13.98215,-15.30339,-0.06320934,-0.4708692,100.0308
30.12917,345.4988,13.97197,-15.33885,-0.0624136,-0.4653378,99.97376
30.2625,346.8288,13.96171,-15.37367,-0.06156347,-0.4593916,100.0138
30.39584,348.1637,13.9511,-15.40644,-0.06056819,-0.4523508,99.95624
30.52917,349.4914,13.94066,-15.43967,-0.0595985,-0.44549,99.97249
30.6625,350.8234,13.92966,-15.48464,-0.05945918,-0.4448296,99.99516
30.79584,352.1511,13.91892,-15.52661,-0.0590989,-0.4425139,99.97394
30.92916,353.486,13.90772,-15.56813,-0.05870309,-0.4399278,100.0205
31.0625,354.811,13.89621,-15.62073,-0.05908409,-0.4431646,99.91242
31.19584,356.141,13.88458,-15.67495,-0.05957205,-0.4472096,100.0387
31.32916,357.4705,13.87252,-15.73698,-0.060602,-0.4553347,99.9828
31.4625,358.7954,13.86011,-15.805,-0.06204409,-0.4665732,99.97219
31.59583,360.1216,13.84766,-15.8748,-0.0636077,-0.478745,100.007
31.72916,361.4522,13.83461,-15.95152,-0.06564178,-0.4944669,100.0139
31.8625,362.7797,13.82146,-16.04452,-0.06880475,-0.5187188,99.98803
31.99583,364.107,13.80755,-16.13779,-0.07197356,-0.5430545,99.99791
32.12916,365.4335,13.79343,-16.24359,-0.07600024,-0.5739088,100.0252
32.2625,366.7584,13.77866,-16.36164,-0.08087139,-0.6111957,100.0624
32.39583,368.0891,13.76358,-16.4869,-0.08621769,-0.6521391,99.96766
32.52917,369.4131,13.74747,-16.62264,-0.09227347,-0.6985216,99.98258
32.6625,370.7381,13.73094,-16.7695,-0.09908059,-0.7506736,100.0679
32.79584,372.0648,13.71381,-16.93218,-0.106963,-0.8110639,99.96232
32.92916,373.387,13.69587,-17.09639,-0.1149201,-0.8721226,99.98009
33.0625,374.715,13.67731,-17.26178,-0.1229213,-0.9336189,100.0268
33.19584,376.04,13.65763,-17.43395,-0.1313713,-0.9986259,100.0205
33.32916,377.3652,13.63734,-17.61874,-0.1406524,-1.070066,99.98072
33.4625,378.6898,13.6163,-17.80111,-0.1497314,-1.140086,100.0183
33.59583,380.0127,13.59432,-17.99334,-0.1594626,-1.215161,99.98605
33.72917,381.3383,13.57161,-18.17836,-0.1686528,-1.286212,100.0012
33.8625,382.6594,13.54818,-18.36658,-0.1780331,-1.358824,100.0226
33.99584,383.9835,13.52402,-18.5457,-0.186746,-1.426453,99.98625
34.12916,385.3134,13.49879,-18.7178,-0.1949342,-1.49018,99.98084
34.2625,386.6356,13.47275,-18.87776,-0.202266,-1.547455,99.97019
34.39583,387.9662,13.4458,-19.03415,-0.2093074,-1.6026,100.0189
34.52917,389.2954,13.41819,-19.16432,-0.2145364,-1.643943,100.0678
34.6625,390.6232,13.38938,-19.28686,-0.2192163,-1.681142,100.0187
34.79584,391.954,13.35798,-19.40224,-0.2233825,-1.714459,99.99149
34.92916,393.2869,13.3264,-19.50885,-0.2269222,-1.743016,99.97278
35.0625,394.62,13.29108,-19.60039,-0.2294237,-1.763638,99.97709
35.19584,395.9526,13.24797,-19.70539,-0.232812,-1.791114,99.97736
35.32916,397.2832,13.2106,-19.80558,-0.2358575,-1.81599,100.022
35.4625,398.6194,13.17386,-19.86758,-0.236316,-1.820926,99.96949
35.59583,399.9552,13.13716,-19.90154,-0.234893,-1.811343,100.0054
35.72917,401.294,13.10026,-19.91617,-0.2321702,-1.791717,100.0112
35.8625,402.6332,13.06089,-19.91026,-0.228083,-1.761522,99.99338
35.99584,403.9757,13.01389,-19.93895,-0.2262972,-1.749068,99.998
36.12916,405.3154,12.97227,-19.95799,-0.2238784,-1.731695,100.0251
36.2625,406.6572,12.93193,-19.95494,-0.2199978,-1.702981,99.99989
36.39583,407.9997,12.89305,-19.93764,-0.2151893,-1.667033,100.0055
36.52917,409.345,12.85476,-19.91044,-0.2097438,-1.626089,100.0028
36.6625,410.6886,12.81646,-19.87332,-0.2036709,-1.580214,99.98165
36.79584,412.0365,12.77903,-19.83364,-0.1974475,-1.533099,100.0049
36.92916,413.381,12.74116,-19.79646,-0.1914238,-1.48746,100.0065
37.0625,414.7258,12.70367,-19.75031,-0.1848434,-1.43742,100.0206
37.19584,416.0714,12.66691,-19.71114,-0.1787454,-1.39105,100.0005
37.32916,417.417,12.63066,-19.67578,-0.1729307,-1.34679,100.0171
37.4625,418.761,12.59501,-19.64428,-0.1673956,-1.304644,100.0299
37.59583,420.106,12.5601,-19.60676,-0.1615035,-1.259647,100.0142
37.72917,421.452,12.52762,-19.56964,-0.1556674,-1.215019,99.99942
37.8625,422.792,12.49417,-19.5439,-0.1506042,-1.176361,100.0311
37.99584,424.1361,12.46122,-19.51076,-0.1450908,-1.134123,99.96718
38.12916,425.4812,12.42879,-19.48462,-0.140054,-1.09555,99.99418
38.2625,426.8226,12.39755,-19.45906,-0.1350923,-1.057506,100.0031
38.39583,428.1631,12.3664,-19.43998,-0.1305733,-1.022872,99.95597
38.52917,429.5028,12.3362,-19.41763,-0.1258789,-0.9868118,99.96251
38.6625,430.8446,12.3068,-19.39791,-0.1213768,-0.9522045,100.0138
38.79584,432.1805,12.2776,-19.38538,-0.1173671,-0.9214108,99.97975
38.92916,433.5228,12.24873,-19.36538,-0.1129049,-0.8870176,99.9985
39.0625,434.8625,12.2208,-19.35971,-0.1093725,-0.85987,100.0056
39.19584,436.201,12.19274,-19.34769,-0.1054755,-0.8298035,100.0135
39.32916,437.5384,12.16558,-19.33894,-0.1018118,-0.8015301,100.0144
39.4625,438.8766,12.1383,-19.33034,-0.09818194,-0.7734842,99.92544
39.59583,440.2153,12.11146,-19.32254,-0.09462735,-0.7459918,100.0452
39.72917,441.5537,12.08463,-19.32021,-0.09143572,-0.7213231,99.98392
39.8625,442.8922,12.05777,-19.31982,-0.08838782,-0.6977545,99.98215
39.99584,444.2272,12.03128,-19.32779,-0.08588153,-0.6784308,100
40.12916,445.5647,12.00461,-19.33534,-0.08336574,-0.6590049,100.0272
40.2625,446.9019,11.97799,-19.33442,-0.0803591,-0.6356684,100.0093
40.39583,448.2383,11.95136,-19.34106,-0.07783479,-0.6161172,99.96613
40.52917,449.575,11.92452,-19.34807,-0.07535568,-0.5968965,99.98663
40.6625,450.9138,11.8975,-19.35926,-0.0731445,-0.5797729,100.0189
40.79584,452.2491,11.87022,-19.37575,-0.07127764,-0.5653559,100.0334
40.92916,453.5852,11.84298,-19.38849,-0.06920543,-0.5492822,100.0147
41.0625,454.9194,11.81506,-19.40628,-0.06745776,-0.5357598,100.0005
41.19584,456.2578,11.78715,-19.42211,-0.06560282,-0.5213657,99.99028
41.32916,457.5892,11.7585,-19.44514,-0.06420657,-0.5106002,100.0365
41.4625,458.9234,11.72946,-19.47565,-0.06325985,-0.5033974,100.03
41.59583,460.2604,11.69995,-19.49587,-0.06171817,-0.4914475,100.0097
41.72917,461.5931,11.66974,-19.525,-0.06072224,-0.4838291,100.001
41.8625,462.9276,11.63876,-19.55264,-0.05964856,-0.47558,99.94634
41.99584,464.2629,11.60748,-19.58728,-0.05899414,-0.4706652,100.0074
42.12916,465.5976,11.57537,-19.62262,-0.05839276,-0.4661664,100.0064
42.2625,466.9253,11.54254,-19.66611,-0.05828765,-0.4656254,99.99431
42.39583,468.2605,11.50892,-19.70862,-0.05811646,-0.4645548,99.99472
42.52917,469.5968,11.47454,-19.75872,-0.05838535,-0.4670023,100.0325
42.6625,470.9278,11.43968,-19.8103,-0.0587566,-0.4702719,100.0123
42.79584,472.2585,11.40404,-19.86606,-0.05936944,-0.475478,100.0037
42.92916,473.5899,11.3676,-19.92043,-0.0599052,-0.4800705,100.0224
43.0625,474.9226,11.33052,-19.98144,-0.06081581,-0.4876742,100.0107
43.19584,476.2556,11.29298,-20.05217,-0.06227392,-0.4996798,100.0167
43.32916,477.5884,11.25502,-20.12414,-0.06379802,-0.5122296,100.0293
43.4625,478.9216,11.21692,-20.19875,-0.06546545,-0.5259462,99.96834
43.59583,480.2509,11.17856,-20.27445,-0.06719654,-0.5401901,99.97879
43.72917,481.58,11.13971,-20.35582,-0.06923856,-0.556953,99.99419
43.8625,482.9111,11.10105,-20.44007,-0.07142639,-0.574909,100.0059
43.99584,484.2444,11.06233,-20.52969,-0.07389682,-0.5951624,100.0507
44.12916,485.576,11.02379,-20.61665,-0.07621434,-0.6142088,99.99405
44.2625,486.9042,10.98533,-20.70888,-0.07881712,-0.6355771,100.017
44.39583,488.235,10.94678,-20.78849,-0.08071437,-0.651279,99.95914
44.52917,489.5668,10.9088,-20.86847,-0.08262244,-0.6670874,100.0086
44.6625,490.8942,10.871,-20.96383,-0.08536562,-0.6896594,99.99614
44.79584,492.2289,10.83349,-21.0533,-0.08776216,-0.7094543,99.95171
44.92916,493.5606,10.79615,-21.14128,-0.09007416,-0.7285875,100.0188
45.0625,494.892,10.75948,-21.22886,-0.09235324,-0.7474761,99.98864
45.19584,496.223,10.72314,-21.3303,-0.09536401,-0.7723129,99.98758
45.32916,497.5539,10.68734,-21.42294,-0.09789171,-0.7932644,100.0201
45.4625,498.8838,10.65192,-21.5256,-0.1009388,-0.818451,100.0181
45.59583,500.2156,10.61669,-21.61904,-0.1034775,-0.8395422,100.0074
45.72917,501.5446,10.58224,-21.71945,-0.1063773,-0.8635895,99.9757
45.8625,502.8732,10.54855,-21.81668,-0.1090957,-0.8861915,100.0241
45.99584,504.2047,10.51489,-21.9183,-0.1120238,-0.9105246,100.0062
46.12916,505.5347,10.48196,-22.02293,-0.1150969,-0.9360648,100.0135
46.2625,506.866,10.44935,-22.13114,-0.1183376,-0.9629982,100.0238
46.39583,508.1944,10.4175,-22.2408,-0.1216427,-0.9904872,100.0003
46.52917,509.5236,10.386,-22.34395,-0.1245928,-1.015117,100.0132
46.6625,510.8606,10.3551,-22.45148,-0.127736,-1.041341,100.0401
46.79584,512.1854,10.32465,-22.56728,-0.1313182,-1.07117,100.029
46.92916,513.5134,10.29452,-22.68438,-0.1349408,-1.101361,100.0188
47.0625,514.8463,10.2652,-22.80554,-0.1387418,-1.133044,100.0072
47.19584,516.1698,10.23642,-22.92951,-0.1426874,-1.165943,100.0194
47.32916,517.4998,10.20804,-23.05035,-0.1464408,-1.197309,99.99291
47.4625,518.8329,10.18018,-23.17594,-0.150408,-1.230459,100.0226
47.59583,520.1582,10.15287,-23.30923,-0.1547614,-1.266806,100.0383
47.72917,521.4874,10.12621,-23.43566,-0.1587397,-1.300122,99.99074
47.8625,522.814,10.10001,-23.57539,-0.163372,-1.338834,99.99139
47.99584,524.1454,10.07439,-23.71562,-0.1679948,-1.377512,100.014
48.12916,525.4707,10.04866,-23.85995,-0.1728125,-1.417832,100.0209
48.2625,526.7988,10.02364,-23.99136,-0.1769604,-1.452699,100.0415
48.39583,528.13,9.999305,-24.11022,-0.1804606,-1.482285,100.0052
48.52917,529.4562,9.975356,-24.23384,-0.1841931,-1.513813,99.97944
48.6625,530.785,9.952446,-24.36447,-0.1882481,-1.548019,99.99969
48.79584,532.1161,9.929961,-24.50568,-0.1927992,-1.586343,100.009
48.92916,533.445,9.907869,-24.63942,-0.1969698,-1.621576,99.97394
49.0625,534.7757,9.886459,-24.79667,-0.2022638,-1.666102,99.99238
49.19584,536.1007,9.86533,-24.95658,-0.2076751,-1.711643,99.98518
49.32916,537.4298,9.844722,-25.13153,-0.2137786,-1.76294,100.0308
49.4625,538.755,9.824584,-25.31331,-0.220192,-1.816851,100.0409
49.59583,540.083,9.804803,-25.49941,-0.2267762,-1.87223,99.98218
49.72917,541.4111,9.785492,-25.69014,-0.23355,-1.929235,100.0285
49.8625,542.7359,9.76668,-25.8935,-0.2409033,-1.991091,99.96391
49.99584,544.0606,9.74829,-26.09798,-0.2482754,-2.053172,100.0135
50.12916,545.383,9.730356,-26.30797,-0.2558767,-2.117212,100.026
50.2625,546.7043,9.712745,-26.52762,-0.2639023,-2.184834,99.98304
50.39583,548.032,9.695632,-26.7487,-0.271943,-2.252657,100.013
50.52917,549.3552,9.67904,-26.98326,-0.280591,-2.325584,100.0079
50.6625,550.6758,9.662576,-27.22088,-0.2893494,-2.399483,100.0311
50.79584,551.9996,9.64675,-27.46613,-0.2984167,-2.47602,100.0147
50.92916,553.3215,9.63103,-27.71048,-0.3074033,-2.551964,100.0088
51.0625,554.6425,9.616059,-27.95438,-0.316329,-2.627485,99.95929
51.19584,555.9709,9.601245,-28.21257,-0.3258581,-2.708098,100.0351
51.32917,557.2888,9.586838,-28.46686,-0.3351876,-2.787138,99.99169
51.4625,558.6142,9.572844,-28.71614,-0.3442252,-2.86383,99.98986
51.59583,559.9385,9.559147,-28.96702,-0.3532983,-2.940902,99.97259
51.72917,561.2624,9.545581,-29.22482,-0.362649,-3.020366,99.98809
51.8625,562.5859,9.532465,-29.47992,-0.3718344,-3.098535,100.0018
51.99584,563.9088,9.520086,-29.74976,-0.3816524,-3.182055,99.99342
52.12916,565.2313,9.507628,-30.02518,-0.3916811,-3.267423,100.0153
52.2625,566.5502,9.495561,-30.3107,-0.4021305,-3.356388,100.0116
52.39583,567.8718,9.48367,-30.5928,-0.4123738,-3.443728,99.99319
52.52918,569.193,9.472188,-30.8776,-0.4226925,-3.531784,100.0246
52.6625,570.5176,9.460956,-31.166,-0.4331228,-3.620848,99.99004
52.79582,571.8381,9.44992,-31.45691,-0.4436303,-3.710644,100.0326
52.92916,573.159,9.439322,-31.74992,-0.4541858,-3.800936,100.0184
53.0625,574.4799,9.428653,-32.0348,-0.4643329,-3.8879,99.97824
53.19584,575.8033,9.418453,-32.32916,-0.4748534,-3.97808,99.9788
53.32918,577.125,9.40847,-32.6138,-0.4849036,-4.064411,99.99944
53.4625,578.4478,9.39865,-32.8956,-0.4947842,-4.149406,100.0043
53.59582,579.7701,9.38903,-33.18422,-0.504926,-4.23668,100.0364
53.72918,581.093,9.379634,-33.47258,-0.5150144,-4.323592,99.98813
53.8625,582.4151,9.370381,-33.75112,-0.5246344,-4.40666,100.056
53.99584,583.7358,9.361249,-34.0368,-0.5345342,-4.492163,100.0143
54.12916,585.0615,9.352496,-34.31291,-0.5439649,-4.573806,100.0456
54.2625,586.3862,9.343672,-34.58322,-0.5531106,-4.653137,100.0105
54.39582,587.7104,9.335151,-34.84574,-0.5618868,-4.729434,99.97043
54.52918,589.0346,9.32675,-35.10031,-0.5702877,-4.80265,100.0288
54.6625,590.359,9.318439,-35.35612,-0.5787217,-4.876148,99.97749
54.79582,591.6832,9.310532,-35.59795,-0.5865307,-4.944403,99.97719
54.92916,593.0048,9.302359,-35.83464,-0.5941016,-5.010715,99.96437
55.0625,594.3337,9.294274,-36.06454,-0.6013416,-5.074297,99.97911
55.19584,595.6588,9.286461,-36.28581,-0.608202,-5.134736,99.95218
55.32918,596.9812,9.278708,-36.51574,-0.6154192,-5.198246,99.96469
55.4625,598.3066,9.271255,-36.73333,-0.622086,-5.257162,100.0053
55.59582,599.6344,9.263798,-36.94945,-0.6286676,-5.315414,99.97401
55.72918,600.963,9.256351,-37.16161,-0.6350655,-5.37217,99.99744
55.8625,602.292,9.249084,-37.36194,-0.6409488,-5.424624,100.0219
55.99584,603.6187,9.241903,-37.56852,-0.6470887,-5.479296,99.96454
56.12916,604.9448,9.234684,-37.77912,-0.6533862,-5.535356,100.0076
56.2625,606.2701,9.227686,-37.98134,-0.6593212,-5.588389,99.99512
56.39582,607.5996,9.220759,-38.18948,-0.6654818,-5.643387,100.0255
56.52918,608.9258,9.213853,-38.38578,-0.6711457,-5.694224,99.96268
56.6625,610.252,9.206874,-38.57969,-0.6766648,-5.744168,100.0416
56.79582,611.5824,9.200301,-38.76642,-0.6818054,-5.79148,99.98326
56.92916,612.9099,9.193522,-38.95359,-0.6869634,-5.839,99.91806
57.0625,614.2382,9.186775,-39.13252,-0.6917715,-5.883594,100.0006
57.19584,615.5654,9.180438,-39.30978,-0.696507,-5.927621,100.018
57.32918,616.8935,9.174484,-39.5,-0.7017658,-5.976155,99.96866
57.4625,618.2235,9.167925,-39.68606,-0.7068406,-6.023172,99.99238
57.59582,619.5521,9.161454,-39.86491,-0.7116195,-6.067729,100.0001
57.72918,620.8797,9.155338,-40.054,-0.7168098,-6.115836,99.97785
57.8625,622.2082,9.148719,-40.24032,-0.7218795,-6.162974,100.0387
57.99584,623.5331,9.142451,-40.42939,-0.7270611,-6.211116,99.9248
58.12916,624.863,9.136036,-40.61875,-0.7322363,-6.25926,100.0214
58.2625,626.1912,9.129972,-40.80137,-0.737137,-6.305112,99.98476
58.39582,627.5168,9.123578,-40.98672,-0.7421474,-6.351949,99.96944
58.52918,628.8438,9.117481,-41.16262,-0.7467694,-6.395507,99.99686
58.6625,630.1716,9.111202,-41.35248,-0.7519505,-6.443866,100.0092
58.79582,631.4989,9.105051,-41.53659,-0.7569439,-6.490271,99.98429
58.92916,632.8261,9.099054,-41.72076,-0.7619394,-6.53671,99.98691
59.0625,634.1518,9.092988,-41.90068,-0.766765,-6.581738,99.96608
59.19584,635.4834,9.08687,-42.087,-0.7718269,-6.628834,99.99793
59.32918,636.81,9.081494,-42.32067,-0.7787671,-6.69212,99.99659
59.4625,638.1368,9.075538,-42.52586,-0.7845712,-6.745698,99.9462
59.59582,639.4604,9.069755,-42.71152,-0.7896066,-6.792718,99.99331
59.72918,640.79,9.063964,-42.89966,-0.7947247,-6.8405,99.99269
59.8625,642.115,9.058087,-43.0942,-0.8000991,-6.890534,99.9836
59.99584,643.4421,9.052368,-43.29292,-0.8056261,-6.94193,99.99157
60.12916,644.7666,9.046594,-43.487,-0.810973,-6.991826,100.0125
60.2625,646.0982,9.040801,-43.67833,-0.8161945,-7.040692,100.0163
60.39582,647.4242,9.03503,-43.86774,-0.8213506,-7.089045,100.0139
60.52918,648.7502,9.029601,-44.06998,-0.8269982,-7.14168,100.0402
60.6625,650.0743,9.02382,-44.2614,-0.8322285,-7.190766,100.0187
60.79582,651.4033,9.018251,-44.45471,-0.8375181,-7.240412,100.0073
60.92916,652.7292,9.012859,-44.6465,-0.842752,-7.289625,100.0411
61.0625,654.0616,9.007528,-44.83998,-0.8480361,-7.339328,100.0244
61.19584,655.3853,9.002132,-45.03464,-0.8533795,-7.389585,100.0173
61.32918,656.711,8.99684,-45.22688,-0.8586238,-7.439032,99.99416
61.4625,658.0385,8.991466,-45.41128,-0.8635639,-7.485899,99.99472
61.59582,659.3671,8.986101,-45.59858,-0.8686116,-7.533741,99.9795
61.72918,660.6936,8.980838,-45.7882,-0.8737507,-7.582421,99.99856
61.8625,662.021,8.975766,-45.97286,-0.8786978,-7.62948,100.0007
61.99584,663.35,8.970441,-46.16222,-0.8838202,-7.678113,100.0039
62.12916,664.679,8.965326,-46.34037,-0.8885178,-7.723094,100.0241
62.2625,666.007,8.960371,-46.53158,-0.8937121,-7.772446,100.0244
62.39582,667.3321,8.95535,-46.71582,-0.8986481,-7.81959,99.97488
62.52918,668.6597,8.950282,-46.90372,-0.9037174,-7.867945,100.0145
62.6625,669.99,8.94553,-47.10488,-0.9092751,-7.920594,99.94806
62.79582,671.3144,8.940571,-47.29068,-0.9142725,-7.968418,100.02
62.92916,672.6443,8.93572,-47.47352,-0.9191481,-8.015222,99.97082
63.0625,673.9734,8.930985,-47.64555,-0.9236261,-8.058606,99.96819
63.19584,675.2998,8.926543,-47.82053,-0.9282208,-8.103047,99.98731
63.32918,676.627,8.921736,-47.99711,-0.9328762,-8.14806,99.99285
63.4625,677.9518,8.917309,-48.16058,-0.9370556,-8.18896,99.99045
63.59582,679.2826,8.912792,-48.32678,-0.9413278,-8.2307,100.029
63.72918,680.6087,8.90827,-48.49597,-0.9457241,-8.273572,99.98634
63.8625,681.9382,8.903754,-48.65944,-0.9499084,-8.314629,99.98022
63.99584,683.2664,8.899174,-48.83188,-0.9544288,-8.358668,100.0126
64.12916,684.5912,8.895035,-48.988,-0.9583629,-8.397608,100.0227
64.2625,685.9208,8.890749,-49.13403,-0.9619272,-8.433344,100.0142
64.39584,687.2516,8.886207,-49.29387,-0.9659992,-8.473571,99.97739
64.52918,688.5822,8.882105,-49.4528,-0.9700461,-8.513618,100.0101
64.6625,689.9106,8.877858,-49.60493,-0.9738582,-8.551641,99.99392
64.79582,691.2395,8.873749,-49.7606,-0.9778031,-8.590859,100.0097
64.92918,692.5678,8.869644,-49.91211,-0.9816126,-8.628866,99.99262
65.0625,693.8988,8.865601,-50.05877,-0.9852553,-8.665406,99.97041
65.19582,695.2261,8.861412,-50.20424,-0.9888687,-8.701715,99.99578
65.32918,696.5572,8.857459,-50.35159,-0.9925522,-8.738681,100.0199
65.4625,697.8869,8.853431,-50.50046,-0.9963038,-8.776282,100.0016
65.59582,699.2145,8.84947,-50.63998,-0.9997313,-8.811059,100.0256
65.72916,700.5445,8.845519,-50.77192,-1.002893,-8.843512,100.041
65.8625,701.8742,8.841766,-50.89994,-1.005927,-8.874875,100.0107
65.99584,703.2046,8.837922,-51.0296,-1.00903,-8.906879,99.98004
66.12916,704.5387,8.834184,-51.16653,-1.012395,-8.941226,99.9975
66.2625,705.868,8.830542,-51.2944,-1.015454,-8.972895,100.0298
66.39584,707.1978,8.82675,-51.42422,-1.01859,-9.005281,100.0379
66.52918,708.5262,8.823129,-51.56164,-1.022005,-9.040158,99.98009
66.6625,709.8554,8.819662,-51.69466,-1.025269,-9.073719,100.0006
66.79582,711.1876,8.816094,-51.8219,-1.02833,-9.105516,99.97249
66.92918,712.5176,8.812662,-51.93578,-1.030933,-9.13329,99.97384
67.0625,713.8435,8.809242,-52.08106,-1.034649,-9.170941,100.0113
67.19582,715.173,8.805792,-52.2032,-1.037552,-9.201416,100.0289
67.32918,716.5015,8.802486,-52.32222,-1.040353,-9.231016,100.0542
67.4625,717.8328,8.799256,-52.43035,-1.042774,-9.257269,100.0664
67.59582,719.1634,8.795838,-52.54118,-1.045294,-9.284422,99.9384
67.72916,720.4889,8.792843,-52.6534,-1.047876,-9.312148,99.98289
67.8625,721.8204,8.789848,-52.7646,-1.050416,-9.339522,100.0153
67.99584,723.15,8.786744,-52.87605,-1.052971,-9.367051,100.0384
68.12916,724.4782,8.783756,-52.97649,-1.05515,-9.391269,100.0146
68.2625,725.8103,8.780829,-53.08505,-1.057606,-9.417958,100.0012
68.39584,727.1413,8.778034,-53.18609,-1.059805,-9.442391,100.012
68.52918,728.47,8.775171,-53.27037,-1.061434,-9.461765,99.99563
68.6625,729.8006,8.772384,-53.3638,-1.063377,-9.483938,100.0131
68.79582,731.1338,8.769784,-53.44995,-1.065067,-9.503884,99.99363
68.92918,732.4619,8.767455,-53.5352,-1.066737,-9.523672,99.98469
69.0625,733.7915,8.764953,-53.60535,-1.06789,-9.538848,99.98999
69.19582,735.1232,8.762525,-53.6723,-1.068932,-9.553049,99.97852
69.32918,736.4584,8.760194,-53.73386,-1.069788,-9.565588,100.0064
69.4625,737.7894,8.7579,-53.79041,-1.070482,-9.576694,99.978
69.59582,739.1204,8.755742,-53.85009,-1.071284,-9.588778,99.97555
69.72916,740.4541,8.753601,-53.90774,-1.072014,-9.600211,100.0046
69.8625,741.7856,8.751671,-53.96425,-1.07271,-9.611352,100.0359
69.99584,743.1162,8.749586,-54.00253,-1.072792,-9.617001,99.95472
70.12916,744.4525,8.747755,-54.04213,-1.072911,-9.622982,99.95101
70.2625,745.7826,8.745942,-54.07461,-1.072802,-9.62691,99.97172
70.39584,747.1145,8.74408,-54.11109,-1.072825,-9.632026,99.96997
70.52918,748.4472,8.7421,-54.1314,-1.072307,-9.632284,100.0008
70.6625,749.7788,8.740649,-54.15134,-1.071778,-9.632436,100.0181
70.79582,751.111,8.739068,-54.16813,-1.071145,-9.631647,100.0181
70.92918,752.4453,8.73755,-54.17419,-1.070152,-9.627618,99.93866
71.0625,753.7784,8.736011,-54.17718,-1.069061,-9.622696,99.96974
71.19582,755.1108,8.7344,-54.1853,-1.06815,-9.619353,100.0205
71.32918,756.4438,8.73295,-54.18582,-1.066984,-9.613681,99.981
71.4625,757.7809,8.731416,-54.16985,-1.06527,-9.603074,99.99806
71.59582,759.1155,8.730132,-54.18103,-1.064458,-9.600572,100.0006
71.72916,760.4489,8.728559,-54.17133,-1.062957,-9.591855,99.99047
71.8625,761.7828,8.727324,-54.16894,-1.061699,-9.585312,99.96684
71.99584,763.1162,8.725994,-54.15321,-1.060003,-9.574811,99.98031
72.12916,764.4501,8.72467,-54.14281,-1.05848,-9.565848,99.98828
72.2625,765.7847,8.723438,-54.132,-1.056943,-9.55675,99.9673
72.39584,767.1184,8.722138,-54.11804,-1.055302,-9.546688,100.0465
72.52918,768.4503,8.720709,-54.11026,-1.053867,-9.5385,100.0291
72.6625,769.7844,8.719618,-54.10516,-1.052511,-9.530988,99.98462
72.79582,771.1192,8.71828,-54.09163,-1.050878,-9.520962,100.0088
72.92918,772.4512,8.717113,-54.0785,-1.049262,-9.511072,100.008
73.0625,773.784,8.715916,-54.07459,-1.047939,-9.503832,99.96891
73.19582,775.1196,8.714531,-54.05514,-1.046109,-9.491968,99.95149
73.32918,776.4535,8.713341,-54.0493,-1.04472,-9.484039,99.99849
73.4625,777.7866,8.712176,-54.04104,-1.04325,-9.475371,100.0068
73.59582,779.1199,8.710922,-54.02444,-1.041509,-9.464228,99.95368
73.72916,780.4558,8.70983,-54.01631,-1.04003,-9.45546,99.99335
73.8625,781.7888,8.708591,-54.0007,-1.038312,-9.444495,100.0033
73.99584,783.1226,8.707571,-53.9957,-1.036927,-9.436547,100.0061
74.12916,784.4566,8.706259,-53.99222,-1.035582,-9.428956,100.0165
74.2625,785.789,8.705152,-53.9923,-1.034348,-9.422358,99.98847
74.39584,787.1228,8.703999,-53.97403,-1.032524,-9.410379,99.98414
74.52918,788.4547,8.702768,-53.97131,-1.031187,-9.402812,99.95744
74.6625,789.789,8.701749,-53.95718,-1.029481,-9.39187,99.98706
74.79582,791.125,8.700572,-53.96377,-1.028416,-9.38677,99.99579
74.92918,792.4559,8.699342,-53.94748,-1.026633,-9.375109,100.0119
75.0625,793.7866,8.698282,-53.9498,-1.025428,-9.368699,99.99406
75.19582,795.1189,8.697314,-53.9525,-1.024221,-9.362265,100.0148
75.32918,796.456,8.695988,-53.95562,-1.023012,-9.355762,100.0159
75.4625,797.7891,8.695086,-53.93989,-1.021221,-9.343926,99.98266
75.59582,799.1239,8.693816,-53.94192,-1.01997,-9.337012,100.0394
75.72916,800.4606,8.692816,-53.95352,-1.018999,-9.332647,100.0162
75.8625,801.7937,8.691772,-53.95386,-1.017677,-9.325064,99.98531
75.99584,803.1275,8.69068,-53.9495,-1.0162,-9.31604,100.0111
76.12916,804.4612,8.689401,-53.9668,-1.015381,-9.313048,99.99486
76.2625,805.7934,8.688399,-53.9778,-1.014365,-9.308241,99.98736
76.39584,807.1288,8.687326,-53.98079,-1.013084,-9.300988,99.98861
76.52918,808.4626,8.686241,-53.97512,-1.011535,-9.291261,100.0269
76.6625,809.7964,8.68511,-53.99468,-1.01075,-9.288543,99.94676
76.79582,811.1297,8.684128,-54.01331,-1.009928,-9.285481,100.0024
76.92918,812.4657,8.682949,-54.0256,-1.0089,-9.280509,99.93149
77.0625,813.7958,8.681855,-54.03914,-1.007914,-9.275921,100.0314
77.19582,815.132,8.680756,-54.07284,-1.007515,-9.276728,99.99408
77.32918,816.4628,8.679499,-54.0837,-1.00643,-9.271207,100.0119
77.4625,817.8004,8.678515,-54.10469,-1.005632,-9.268334,99.98134
77.59582,819.1308,8.677298,-54.13403,-1.005091,-9.267813,99.99738
77.72916,820.4611,8.6764,-54.1666,-1.004638,-9.268098,99.99931
77.8625,821.7938,8.674962,-54.18611,-1.003784,-9.264687,99.96191
77.99584,823.1309,8.674124,-54.21843,-1.003293,-9.264609,100.043
78.12916,824.4629,8.672961,-54.23657,-1.00239,-9.260736,99.99682
78.2625,825.7947,8.671942,-54.27896,-1.002198,-9.263419,99.95869
78.39584,827.1281,8.670836,-54.3135,-1.001763,-9.263851,100.0314
78.52918,828.4578,8.669835,-54.34426,-1.00122,-9.263289,100.0125
78.6625,829.789,8.668719,-54.39263,-1.001183,-9.267397,99.96792
78.79582,831.1264,8.667516,-54.43731,-1.001014,-9.270293,100.0487
78.92918,832.4534,8.66646,-54.471,-1.000546,-9.270399,100.0241
79.0625,833.7874,8.665461,-54.51822,-1.000445,-9.273915,100.0246
79.19582,835.121,8.664191,-54.55301,-0.9999859,-9.27412,100.018
79.32918,836.4553,8.662938,-54.5915,-0.9996243,-9.275219,99.99297
79.4625,837.7863,8.662072,-54.63213,-0.9993324,-9.27693,99.97003
79.59582,839.1215,8.660772,-54.68252,-0.9993066,-9.281095,100.011
79.72916,840.4525,8.65959,-54.73613,-0.9993768,-9.286149,100.0381
79.8625,841.782,8.658618,-54.7988,-0.9997035,-9.293588,99.99794
79.99584,843.1156,8.657449,-54.85158,-0.9997303,-9.298241,100.0016
80.12916,844.4482,8.656332,-54.91363,-1.00002,-9.305347,99.99962
80.2625,845.7811,8.655353,-54.97614,-1.000313,-9.312476,100.0077
80.39584,847.1109,8.654278,-55.05574,-1.001092,-9.324145,100.016
80.52918,848.439,8.653053,-55.12562,-1.001591,-9.333209,100.0341
80.6625,849.7699,8.652056,-55.21055,-1.0025,-9.3461,99.99231
80.79582,851.1025,8.650891,-55.28555,-1.003116,-9.356261,99.97901
80.92918,852.4316,8.649753,-55.37045,-1.004009,-9.369012,100.012
81.0625,853.7609,8.648656,-55.45281,-1.004826,-9.381066,100.0079
81.19582,855.0925,8.647372,-55.54155,-1.005804,-9.394634,99.99813
81.32918,856.4236,8.646341,-55.63738,-1.006975,-9.410012,100.02
81.4625,857.7572,8.645342,-55.72195,-1.007818,-9.422344,100.0208
81.59582,859.0888,8.644014,-55.82222,-1.00909,-9.438689,100.0013
81.72916,860.4191,8.642858,-55.92569,-1.010444,-9.455819,100.0246
81.8625,861.7489,8.641855,-56.03217,-1.011875,-9.473672,99.98016
81.99584,863.0786,8.640628,-56.13365,-1.013156,-9.490144,100.0151
82.12916,864.407,8.639531,-56.24991,-1.014835,-9.510353,100.0217
82.2625,865.7381,8.638299,-56.36826,-1.016549,-9.530902,100.0312
82.39584,867.0656,8.637103,-56.49072,-1.018375,-9.55252,100.0063
82.52918,868.3965,8.63584,-56.60562,-1.019978,-9.572064,99.97039
82.6625,869.7274,8.634816,-56.73285,-1.021899,-9.594611,100.0066
82.79582,871.057,8.633582,-56.86147,-1.023852,-9.617469,100.0281
82.92918,872.3876,8.632178,-56.9868,-1.025702,-9.639387,99.97407
83.0625,873.7169,8.631082,-57.11157,-1.027529,-9.661102,100.0139
83.19582,875.0438,8.629706,-57.2418,-1.029498,-9.684176,100.0348
83.32918,876.3759,8.628712,-57.37969,-1.031641,-9.708897,99.99681
83.4625,877.7056,8.627349,-57.52032,-1.033852,-9.734282,100.0167
83.59582,879.0336,8.626109,-57.68445,-1.036678,-9.76539,99.97541
83.72916,880.3637,8.624907,-57.84338,-1.039351,-9.795074,100.0246
83.8625,881.6944,8.62366,-58.00566,-1.042095,-9.825454,100.0151
83.99584,883.0238,8.622351,-58.16314,-1.044702,-9.854564,99.98542
84.12916,884.3547,8.621094,-58.33373,-1.047633,-9.886751,100.0245
84.2625,885.6806,8.619628,-58.49856,-1.050408,-9.917499,100.0027
84.39584,887.0094,8.618506,-58.67314,-1.053412,-9.950431,99.99556
84.52918,888.3412,8.617106,-58.83885,-1.056166,-9.98103,100.0024
84.6625,889.6688,8.615859,-59.02419,-1.05942,-10.01637,99.98491
84.79582,890.9995,8.614478,-59.20274,-1.062472,-10.04984,100.0085
84.92918,892.3272,8.613301,-59.38765,-1.065677,-10.08479,99.98781
85.0625,893.6591,8.612043,-59.5708,-1.068808,-10.11906,99.96999
85.19582,894.9853,8.610603,-59.75603,-1.071993,-10.15387,99.97178
85.32918,896.3139,8.609282,-59.93551,-1.075011,-10.18713,100.0045
85.4625,897.6462,8.608072,-60.12911,-1.078355,-10.22351,99.97749
85.59582,898.9701,8.606594,-60.3104,-1.081392,-10.25702,100.0095
85.72916,900.3094,8.605374,-60.48115,-1.084116,-10.28765,99.93972
85.8625,901.6319,8.603906,-60.66078,-1.08708,-10.32054,100.0426
85.99584,902.9644,8.602628,-60.84574,-1.090146,-10.35447,100.0229
86.12916,904.2926,8.601226,-61.03535,-1.093314,-10.38937,99.96799
86.2625,905.6246,8.599872,-61.21656,-1.096251,-10.42211,99.99139
86.39584,906.9541,8.598481,-61.38829,-1.098948,-10.4526,100.1136
86.52918,908.2843,8.597126,-61.55816,-1.101582,-10.48252,99.97438
86.6625,909.6136,8.595626,-61.74798,-1.104694,-10.517,100.0079
86.79582,910.94,8.594201,-61.93556,-1.107743,-10.55091,99.9832
86.92918,912.2715,8.592675,-62.114,-1.110541,-10.58246,99.97274
87.0625,913.6019,8.591371,-62.28843,-1.113229,-10.613,100.016
87.19582,914.9336,8.589889,-62.46376,-1.115926,-10.64364,99.97751
87.32918,916.2637,8.588398,-62.65059,-1.11889,-10.67686,99.98251
87.4625,917.591,8.586999,-62.8196,-1.121417,-10.70593,99.98131
87.59582,918.9188,8.585629,-62.99562,-1.124101,-10.7365,100.0075
87.72916,920.2522,8.584022,-63.1758,-1.126862,-10.76776,99.96118
87.8625,921.5814,8.582574,-63.33345,-1.129095,-10.79399,99.98275
87.99584,922.911,8.581043,-63.49521,-1.131412,-10.82106,99.94611
88.12916,924.2422,8.579519,-63.65218,-1.1336,-10.8469,99.9957
88.2625,925.5736,8.578032,-63.82312,-1.136105,-10.87578,99.98751
88.39584,926.9005,8.576647,-63.9665,-1.137969,-10.89857,99.98594
88.52918,928.2303,8.575102,-64.13616,-1.140426,-10.92704,99.98621
88.6625,929.5571,8.573508,-64.27998,-1.14228,-10.94976,99.99707
88.79582,930.8871,8.571984,-64.4357,-1.144394,-10.97499,99.94519
88.92918,932.2175,8.57043,-64.58204,-1.146282,-10.99808,99.97755
89.0625,933.5481,8.568791,-64.73552,-1.148328,-11.0227,100.0196
89.19582,934.879,8.567468,-64.89322,-1.150462,-11.04819,99.98142
89.32918,936.2094,8.566009,-65.05156,-1.152601,-11.07374,100.0256
89.4625,937.5387,8.56441,-65.21407,-1.154832,-11.10021,100.0157
89.59582,938.8686,8.562957,-65.37612,-1.157039,-11.12646,100.014
89.72916,940.1997,8.561595,-65.5216,-1.158858,-11.149,99.97153
89.8625,941.5264,8.560039,-65.6759,-1.160884,-11.17355,100.0234
89.99584,942.8562,8.558593,-65.83154,-1.162921,-11.19822,100.0448
90.12916,944.1863,8.557016,-65.97408,-1.164656,-11.22001,99.96335
90.2625,945.5137,8.55553,-66.11098,-1.166266,-11.24061,99.99142
90.39584,946.8449,8.5541,-66.25241,-1.16796,-11.26204,99.98794
90.52918,948.1745,8.552599,-66.37434,-1.169226,-11.27936,99.96578
90.6625,949.505,8.551124,-66.52388,-1.171092,-11.30247,99.9983
90.79582,950.8358,8.549501,-66.66212,-1.172705,-11.32318,100.0154
90.92918,952.1653,8.54793,-66.80953,-1.174516,-11.3458,99.99394
91.0625,953.4968,8.546591,-66.93682,-1.175876,-11.36408,99.99272
91.19582,954.8246,8.545122,-67.08132,-1.177617,-11.38607,100.0198
91.32918,956.1545,8.543547,-67.2253,-1.179334,-11.40784,99.99476
91.4625,957.4839,8.541991,-67.37769,-1.18123,-11.43135,100.0182
91.59582,958.815,8.540497,-67.51501,-1.182791,-11.45164,99.98925
91.72916,960.142,8.539087,-67.64418,-1.184186,-11.4703,99.96447
91.8625,961.4742,8.537497,-67.78661,-1.185848,-11.49154,100.011
91.99584,962.8032,8.535988,-67.90978,-1.187103,-11.50886,100.0036
92.12916,964.132,8.534598,-68.03026,-1.188301,-11.52564,99.99054
92.2625,965.4657,8.533032,-68.15581,-1.189591,-11.54332,100.0312
92.39584,966.7942,8.531606,-68.28149,-1.1909,-11.5612,100.0359
92.52918,968.1254,8.530176,-68.42776,-1.192637,-11.58325,100.0682
92.6625,969.4576,8.528547,-68.56188,-1.194109,-11.60274,100.0062
92.79582,970.7891,8.52707,-68.70587,-1.195787,-11.62424,100.0106
92.92918,972.1219,8.525481,-68.84648,-1.19739,-11.64503,100.0123
93.0625,973.4496,8.524106,-68.98589,-1.198978,-11.66568,99.95907
93.19582,974.7794,8.522574,-69.09928,-1.200014,-11.68098,100.0136
93.32918,976.1126,8.521053,-69.22478,-1.201296,-11.69869,100.0048
93.4625,977.4434,8.519518,-69.3532,-1.202642,-11.71702,99.97106
93.59582,978.7728,8.518036,-69.4829,-1.204017,-11.73565,100.0176
93.72916,980.1054,8.516391,-69.57325,-1.20458,-11.74638,100.0176
93.8625,981.4381,8.514996,-69.68014,-1.205484,-11.76044,99.99501
93.99584,982.7694,8.513452,-69.78639,-1.206376,-11.7744,99.99059
94.12916,984.1009,8.511929,-69.92843,-1.207999,-11.79548,100.018
94.2625,985.4297,8.510424,-70.0509,-1.209228,-11.81274,99.97515
94.39584,986.7608,8.508954,-70.18388,-1.210664,-11.83203,99.99621
94.52918,988.0901,8.507425,-70.29424,-1.212381,-11.85407,99.98382
94.6625,989.4209,8.50589,-70.47426,-1.213521,-11.8705,99.99922
94.79582,990.7543,8.504297,-70.66163,-1.214803,-11.88833,100.0168
94.92918,992.0835,8.502755,-70.84968,-1.216104,-11.90634,99.9836
95.00416,992.8329,8.502,-70.94908,-1.216707,-11.91522,100.0007