File: examples/pyrolysis/single_element/1D/gold/experiment_comp/20degpermin_run3.csv
Time (min),Temperature (degC),Weight (mg),Heat Flow (mW),Temperature Difference (degC),Temperature Difference (muV),Sample Purge Flow (mL/min)
0.001555556,50.43435,11.48318,-8.543484,-0.19202,-0.9294053,199.6064
0.0625,50.32391,11.48144,-8.537176,-0.1915928,-0.9269788,100.0154
0.1291666,50.23482,11.47984,-8.529181,-0.1909022,-0.9233108,99.985
0.1958334,50.1662,11.47996,-8.509015,-0.1885046,-0.9114528,99.98934
0.2625,50.1402,11.48049,-8.47148,-0.1836587,-0.8878594,99.96732
0.3291667,50.1714,11.48066,-8.421272,-0.1769342,-0.8553334,99.98349
0.3958334,50.2525,11.48126,-8.355575,-0.1679305,-0.8119415,99.99595
0.4625,50.41951,11.48148,-8.285309,-0.1580681,-0.7645625,99.97026
0.5291666,50.66508,11.48192,-8.208881,-0.1470974,-0.7119805,100.0039
0.5958334,50.99792,11.48239,-8.1323,-0.135827,-0.6580626,100.0227
0.6625,51.43133,11.48268,-8.055001,-0.1241579,-0.6022976,99.98445
0.7291668,51.94915,11.48313,-7.979382,-0.112421,-0.5462325,100.0261
0.7958334,52.57716,11.48341,-7.908712,-0.1010479,-0.4919228,100.0094
0.8625,53.30474,11.48388,-7.844538,-0.09023609,-0.440291,99.96256
0.9291668,54.12713,11.48434,-7.784708,-0.07972108,-0.390003,99.99531
0.9958332,55.04466,11.4845,-7.72859,-0.0694358,-0.340683,100.0074
1.0625,56.05986,11.48504,-7.675085,-0.05923526,-0.291584,99.98376
1.129167,57.16586,11.48519,-7.627551,-0.0495868,-0.2449608,99.99259
1.195833,58.35302,11.48541,-7.58379,-0.04021352,-0.1994216,100.0555
1.2625,59.62166,11.48542,-7.541119,-0.0308033,-0.1533817,99.9984
1.329166,60.96028,11.48579,-7.503934,-0.02193834,-0.1096962,99.99374
1.395834,62.36656,11.4858,-7.466491,-0.01290584,-0.06479335,100.0106
1.4625,63.82966,11.48586,-7.434351,-4.44E-03,-0.02237912,100.0212
1.529167,65.34168,11.486,-7.40485,0.003778594,0.01917198,100.0055
1.595833,66.9003,11.48607,-7.37375,0.01227326,0.06250294,100.0151
1.6625,68.49856,11.48614,-7.344638,0.02056632,0.1052192,100.0143
1.729166,70.11601,11.48596,-7.319349,0.02839528,0.1459624,99.99969
1.795834,71.75866,11.48578,-7.296166,0.03595764,0.1857355,99.96541
1.8625,73.41849,11.48564,-7.27427,0.04335226,0.2250293,100.0069
1.929166,75.08692,11.48535,-7.252659,0.05067902,0.2643624,99.99902
1.995833,76.7637,11.48523,-7.232328,0.05779239,0.3029563,99.99045
2.0625,78.43678,11.48498,-7.21823,0.06408516,0.3376028,100.0133
2.129166,80.10191,11.48488,-7.20463,0.07026421,0.371911,100.0166
2.195834,81.75821,11.4845,-7.200884,0.075181,0.3997036,100.0083
2.2625,83.40579,11.48415,-7.194708,0.0803244,0.4289263,100.0228
2.329166,85.04141,11.48373,-7.196006,0.08448791,0.4531105,99.9747
2.395833,86.65465,11.48334,-7.201506,0.08806718,0.4743291,100.027
2.4625,88.24562,11.48284,-7.211687,0.09100009,0.4921887,100.0016
2.529167,89.81171,11.48233,-7.223422,0.09366626,0.5087024,100.0198
2.595833,91.35632,11.48166,-7.236216,0.09612922,0.5241978,100.0188
2.6625,92.88188,11.47979,-7.243876,0.0991243,0.5426934,99.99594
2.729167,94.38301,11.47912,-7.23161,0.1043961,0.573793,100.0185
2.795834,95.85464,11.47869,-7.228251,0.1085146,0.5987109,100.0008
2.8625,97.30826,11.47791,-7.23827,0.1109744,0.61458,99.97059
2.929166,98.73168,11.47738,-7.257025,0.1123474,0.6243781,99.99926
2.995834,100.1342,11.4766,-7.281132,0.1130439,0.6303052,99.97131
3.0625,101.5148,11.47604,-7.311478,0.1129548,0.6318228,99.98231
3.129166,102.8712,11.47536,-7.346656,0.112252,0.6298632,99.99413
3.195834,104.2137,11.47461,-7.383366,0.1113273,0.626601,100.0284
3.2625,105.5318,11.47395,-7.42323,0.1099938,0.6209688,99.9455
3.329167,106.8334,11.47318,-7.467089,0.1081668,0.6124714,100.0149
3.395833,108.1246,11.47233,-7.51042,0.1063725,0.6040816,99.99598
3.4625,109.398,11.47181,-7.551782,0.1047686,0.5966864,100.01
3.529167,110.6575,11.47086,-7.595315,0.1028963,0.5876934,99.98194
3.595833,111.9131,11.47018,-7.634745,0.1014749,0.5812092,99.99418
3.6625,113.1564,11.46926,-7.66983,0.1005286,0.5773934,99.99889
3.729167,114.3949,11.46847,-7.706811,0.09934991,0.5721951,99.97912
3.795833,115.6304,11.4676,-7.73964,0.09863049,0.569608,99.98329
3.8625,116.863,11.46676,-7.771968,0.09796709,0.5672938,100.0154
3.929166,118.0934,11.46584,-7.800556,0.09772782,0.5673274,100.0024
3.995834,119.3241,11.46506,-7.820995,0.09840172,0.5726454,100.008
4.0625,120.5572,11.46416,-7.840551,0.09916599,0.5785082,99.99351
4.129166,121.7898,11.46325,-7.859506,0.09999574,0.5847758,100.0005
4.195833,123.0238,11.46222,-7.878458,0.1008207,0.5910408,100.0256
4.2625,124.2705,11.46129,-7.891379,0.1023193,0.6012914,100.0042
4.329167,125.5129,11.4603,-7.905124,0.1037334,0.6110944,100.0023
4.395834,126.777,11.45909,-7.915728,0.1054944,0.6229916,99.98231
4.4625,128.0316,11.45825,-7.924065,0.1075096,0.6364521,100.0034
4.529167,129.3046,11.45716,-7.93596,0.1091321,0.6476425,100.0136
4.595833,130.5827,11.45624,-7.94214,0.1113938,0.6626985,99.99726
4.6625,131.8726,11.45527,-7.948028,0.1136897,0.6780297,100.0216
4.729166,133.1679,11.45421,-7.951262,0.11628,0.6952022,99.99281
4.795833,134.4713,11.45319,-7.9516,0.1191837,0.7143321,99.97441
4.8625,135.7862,11.4521,-7.956452,0.1216106,0.730685,99.98524
4.929167,137.112,11.45092,-7.958056,0.1244024,0.7492016,99.97891
4.995834,138.4454,11.44972,-7.958944,0.1272847,0.7683158,100.018
5.0625,139.7867,11.4486,-7.960835,0.1300585,0.7868631,99.98485
5.129166,141.1296,11.44729,-7.960495,0.1330701,0.8069331,99.99941
5.195833,142.4885,11.44617,-7.96114,0.135973,0.8264362,100.0288
5.2625,143.8475,11.44504,-7.960452,0.1390203,0.8469082,100.0198
5.329168,145.2282,11.44374,-7.956726,0.1423884,0.8694328,99.97769
5.395834,146.6048,11.44254,-7.954239,0.1456187,0.8912151,100.041
5.4625,147.9842,11.44124,-7.95339,0.148664,0.9119569,99.99024
5.529168,149.3685,11.44002,-7.951812,0.1517757,0.9331944,100.0088
5.595832,150.7592,11.43852,-7.953254,0.1545585,0.9524969,100.0178
5.6625,152.1551,11.43724,-7.95736,0.1570513,0.970087,99.98105
5.729166,153.5533,11.43578,-7.960253,0.1596628,0.9884884,99.96456
5.795832,154.953,11.4345,-7.9601,0.1625767,1.008832,99.98182
5.8625,156.3501,11.43307,-7.965032,0.1649598,1.025842,99.98488
5.929168,157.7476,11.43154,-7.972053,0.1671217,1.04146,99.97304
5.995834,159.1458,11.43031,-7.978532,0.1693247,1.057381,100.0133
6.0625,160.5402,11.42874,-7.983741,0.171641,1.074064,100.045
6.129166,161.9343,11.42721,-7.992358,0.1735863,1.08847,100.0288
6.195832,163.3259,11.42564,-7.998493,0.175771,1.104426,99.96903
6.2625,164.7138,11.42414,-8.010384,0.1773428,1.11657,100.0342
6.329168,166.0985,11.42266,-8.01973,0.1791539,1.130252,99.99266
6.395834,167.482,11.42106,-8.030801,0.1807734,1.142761,99.94092
6.4625,168.8564,11.4196,-8.044059,0.1821456,1.153732,99.98781
6.529166,170.2301,11.41795,-8.058994,0.183333,1.163556,99.97954
6.595834,171.5981,11.4163,-8.072336,0.1846592,1.174279,99.99358
6.6625,172.9638,11.41468,-8.084915,0.1860463,1.185411,99.99579
6.729166,174.3256,11.41304,-8.101814,0.1869793,1.19367,99.99078
6.795832,175.6787,11.41164,-8.117224,0.188053,1.2028,99.97644
6.8625,177.0272,11.41012,-8.131314,0.1892637,1.212688,100.0292
6.929168,178.3796,11.40834,-8.145272,0.1904747,1.222575,100.0182
6.995834,179.7216,11.40667,-8.159637,0.1916278,1.232105,99.99371
7.0625,181.0626,11.40492,-8.174216,0.1927448,1.24142,99.95718
7.129166,182.3966,11.40324,-8.190268,0.1936983,1.249698,100.0134
7.195832,183.7287,11.40148,-8.203639,0.1949082,1.259642,99.96545
7.2625,185.0587,11.39975,-8.215524,0.1962516,1.27047,100.0292
7.329168,186.3801,11.39791,-8.223711,0.1979534,1.283644,99.93871
7.395834,187.7077,11.39629,-8.23452,0.1993814,1.295071,99.9713
7.4625,189.0293,11.39466,-8.244508,0.2008769,1.30696,99.98622
7.529166,190.3495,11.39274,-8.253309,0.202481,1.319586,99.93886
7.595834,191.6666,11.3909,-8.260138,0.2042682,1.333433,100.0133
7.6625,192.9854,11.389,-8.267016,0.2060366,1.34719,99.98356
7.729166,194.3033,11.3872,-8.271374,0.2080477,1.362573,99.98031
7.795832,195.623,11.38552,-8.27801,0.2098253,1.376456,99.98332
7.8625,196.939,11.38374,-8.280539,0.2120203,1.393016,99.97336
7.929168,198.2616,11.38173,-8.278036,0.2147121,1.412819,99.99957
7.995834,199.5796,11.37995,-8.272242,0.217716,1.434728,100.0157
8.0625,200.8986,11.37803,-8.287149,0.2206476,1.456221,99.95472
8.129166,202.222,11.37634,-8.277245,0.2235359,1.477486,99.95122
8.195832,203.5444,11.37446,-8.254684,0.2268488,1.501614,100.0094
8.2625,204.8676,11.37244,-8.235548,0.2297833,1.523304,99.99043
8.329166,206.1906,11.3706,-8.209382,0.2333519,1.54926,99.96381
8.395832,207.5153,11.36878,-8.183847,0.236822,1.574631,99.99259
8.4625,208.8497,11.36684,-8.154107,0.24067,1.602593,100.0128
8.529166,210.1823,11.36492,-8.120706,0.244812,1.632591,100.0025
8.595834,211.5174,11.36294,-8.089084,0.2487514,1.661322,99.98316
8.6625,212.8578,11.36096,-8.054284,0.2529644,1.691959,99.98316
8.729168,214.1959,11.35903,-8.017549,0.2573049,1.723541,99.97103
8.795834,215.5383,11.35712,-7.970205,0.262593,1.761563,99.99969
8.8625,216.8767,11.35512,-7.927374,0.2674182,1.796557,99.98689
8.929168,218.2196,11.35306,-7.880389,0.272619,1.834026,100.0071
8.995834,219.566,11.3512,-7.831212,0.2779887,1.872701,100.0288
9.0625,220.9105,11.34918,-7.780309,0.2834783,1.912278,100.0116
9.129166,222.2594,11.34709,-7.727102,0.2891477,1.953172,100.0205
9.195832,223.602,11.345,-7.67005,0.2951096,1.996154,99.98416
9.2625,224.9548,11.34281,-7.612422,0.3011131,2.03952,100.0281
9.329166,226.3044,11.34074,-7.55117,0.3073928,2.084879,100.0237
9.395832,227.6527,11.3385,-7.488297,0.3137832,2.131102,99.99868
9.4625,229.0067,11.33639,-7.421545,0.3204897,2.179592,99.97828
9.529166,230.353,11.33408,-7.35228,0.327371,2.229396,99.97442
9.595834,231.7038,11.33208,-7.284511,0.3341042,2.278311,99.99482
9.6625,233.0595,11.32984,-7.213995,0.3410524,2.328823,100.0133
9.729168,234.4099,11.32762,-7.145884,0.3477636,2.377838,100.0247
9.795834,235.7604,11.32529,-7.069929,0.3551187,2.431383,99.95444
9.8625,237.1067,11.32303,-6.994652,0.3623883,2.48447,100.0151
9.929168,238.4549,11.3207,-6.915359,0.3699894,2.53987,100.0519
9.995834,239.8047,11.31837,-6.838105,0.3774234,2.594094,99.97814
10.0625,241.155,11.31605,-6.75879,0.3850126,2.649504,99.96695
10.12917,242.4984,11.31372,-6.676415,0.3928314,2.706616,99.97538
10.19583,243.8406,11.31131,-6.598988,0.4002231,2.760911,99.98329
10.2625,245.1877,11.30882,-6.517986,0.4079014,2.81731,100.0157
10.32917,246.5393,11.3062,-6.439624,0.415354,2.872275,100.0252
10.39583,247.8764,11.30396,-6.363136,0.4226291,2.926136,100.0364
10.4625,249.2223,11.30134,-6.289912,0.4296394,2.978278,100.0204
10.52916,250.5629,11.29888,-6.215332,0.43675,3.031233,100.0006
10.59584,251.9017,11.2963,-6.14381,0.4436078,3.082542,100.0187
10.6625,253.2406,11.29362,-6.074324,0.4503,3.132816,99.99501
10.72917,254.5803,11.29116,-6.011324,0.4564722,3.179583,99.96947
10.79584,255.9203,11.28858,-5.953266,0.4622531,3.223712,100.0206
10.8625,257.2542,11.28605,-5.895468,0.4680174,3.267832,100.0198
10.92917,258.5922,11.28334,-5.844456,0.4732536,3.308345,100.0151
10.99584,259.9254,11.28062,-5.792587,0.47859,3.349481,99.98622
11.0625,261.2607,11.27801,-5.747388,0.4834308,3.387106,99.99247
11.12916,262.5956,11.27538,-5.707253,0.487888,3.422107,100.0322
11.19583,263.9277,11.27258,-5.674586,0.4917754,3.453184,99.94844
11.2625,265.2639,11.2698,-5.641086,0.4957524,3.484946,100.0225
11.32916,266.593,11.26706,-5.617488,0.4989726,3.511444,100.0248
11.39583,267.9255,11.2644,-5.596326,0.50203,3.536841,100.0049
11.4625,269.2551,11.26169,-5.577255,0.5049504,3.561324,100.0016
11.52916,270.5874,11.25886,-5.56414,0.5074367,3.582787,99.97266
11.59584,271.9191,11.25604,-5.551608,0.5099076,3.604182,99.99172
11.6625,273.2481,11.25324,-5.549986,0.5115632,3.619844,99.97253
11.72917,274.5744,11.25036,-5.554955,0.5127422,3.632156,99.99379
11.79584,275.9068,11.24746,-5.560516,0.5139135,3.644435,99.98141
11.8625,277.2396,11.24446,-5.566244,0.515105,3.656872,100.0197
11.92917,278.5632,11.24175,-5.581924,0.5155664,3.664144,100.007
11.99584,279.893,11.23874,-5.596618,0.5161446,3.672238,100.0035
12.0625,281.2205,11.2357,-5.616978,0.5163516,3.67751,100.0142
12.12916,282.549,11.23274,-5.63818,0.516545,3.682608,99.98549
12.19583,283.879,11.22982,-5.660888,0.5166607,3.687156,99.99625
12.2625,285.208,11.22671,-5.69205,0.5161714,3.687384,100.014
12.32916,286.535,11.22378,-5.720506,0.5159246,3.689346,100.0052
12.39583,287.8699,11.2206,-5.751178,0.5155481,3.690375,99.97897
12.4625,289.1934,11.21751,-5.786007,0.514893,3.689409,100.0117
12.52916,290.5232,11.21431,-5.82258,0.5141418,3.687739,99.95639
12.59584,291.8515,11.21116,-5.857566,0.5135467,3.687189,99.99759
12.6625,293.1774,11.20804,-5.890932,0.5131084,3.68776,100.0085
12.72917,294.5078,11.20475,-5.923653,0.5127486,3.688887,99.99303
12.79584,295.8315,11.2013,-5.956711,0.5123993,3.690094,100.0228
12.8625,297.1622,11.19797,-5.994403,0.5117356,3.689031,99.99688
12.92917,298.4944,11.1947,-6.032271,0.5110922,3.68811,99.99008
12.99583,299.8222,11.19138,-6.065085,0.5108572,3.690139,100.0186
13.0625,301.152,11.18783,-6.095422,0.5108383,3.693675,100.0209
13.12917,302.4815,11.18435,-6.129004,0.5106332,3.695706,100.0054
13.19583,303.8076,11.18089,-6.165278,0.510259,3.696483,99.9678
13.2625,305.1368,11.17721,-6.200704,0.5099754,3.697915,99.98501
13.32916,306.4708,11.17355,-6.235093,0.5097985,3.700128,99.97509
13.39583,307.7989,11.1699,-6.270576,0.509563,3.701913,99.96501
13.4625,309.1294,11.16612,-6.309248,0.509114,3.702143,99.99016
13.52916,310.4588,11.16226,-6.343997,0.5089794,3.704662,100.0221
13.59584,311.7912,11.15832,-6.381732,0.5086512,3.70578,99.97772
13.6625,313.1187,11.15425,-6.423868,0.5080162,3.704651,99.99996
13.72917,314.4469,11.15022,-6.465748,0.5074234,3.703832,99.98836
13.79584,315.7804,11.14592,-6.50289,0.5071962,3.705676,100.0227
13.8625,317.1072,11.14184,-6.54008,0.5069839,3.707633,99.99508
13.92917,318.4356,11.1376,-6.573497,0.5070618,3.711714,99.98449
13.99583,319.7629,11.13319,-6.60937,0.5069756,3.714597,99.99981
14.0625,321.0904,11.12854,-6.64489,0.5069344,3.717809,100.0251
14.12917,322.4204,11.12401,-6.683218,0.5067232,3.719632,99.99671
14.19583,323.7508,11.11934,-6.717182,0.5068569,3.7239,100.0213
14.2625,325.0786,11.11458,-6.752747,0.506886,3.727406,99.99848
14.32916,326.4056,11.10972,-6.790782,0.5067452,3.729663,99.99554
14.39583,327.7388,11.10462,-6.822928,0.507043,3.735158,99.99628
14.4625,329.0688,11.09967,-6.850214,0.5077032,3.743335,100.0371
14.52916,330.3945,11.09447,-6.87932,0.508239,3.750609,99.99009
14.59584,331.723,11.0893,-6.90045,0.5093584,3.762209,100.0297
14.6625,333.0545,11.08377,-6.923798,0.5103194,3.77265,99.99759
14.72917,334.38,11.07831,-6.94493,0.5114484,3.784361,99.97968
14.79584,335.7072,11.07263,-6.967207,0.512495,3.795478,99.99239
14.8625,337.038,11.0669,-6.984449,0.5139063,3.809317,100.0175
14.92917,338.3638,11.06112,-6.997663,0.5156097,3.825352,99.98804
14.99583,339.6917,11.05531,-7.012349,0.5172052,3.84061,100.0186
15.0625,341.0203,11.04932,-7.026359,0.5188511,3.85627,99.98628
15.12917,342.3481,11.04313,-7.033325,0.5210126,3.875694,99.96801
15.19583,343.6759,11.03681,-7.037845,0.5233578,3.896445,100.0179
15.2625,345.0002,11.03041,-7.048228,0.5252817,3.914091,99.99171
15.32916,346.3288,11.02393,-7.056416,0.5273574,3.9329,100.007
15.39583,347.6596,11.01726,-7.068018,0.5291873,3.94991,100.0021
15.4625,348.9858,11.01047,-7.080061,0.5309788,3.96666,100.0255
15.52916,350.3119,11.00355,-7.08332,0.5333901,3.988078,100.0001
15.59584,351.6339,10.9966,-7.08897,0.5356225,4.008192,99.98695
15.6625,352.9594,10.98925,-7.097766,0.537624,4.026614,100.0183
15.72917,354.2912,10.98201,-7.10627,0.5396409,4.045185,100.017
15.79584,355.6138,10.97457,-7.117356,0.5414684,4.062372,100.0294
15.8625,356.9398,10.96692,-7.122142,0.5437292,4.082844,99.97949
15.92917,358.2669,10.95907,-7.128247,0.5458876,4.102585,99.99394
15.99583,359.5908,10.95114,-7.135299,0.5479692,4.121785,99.98106
16.0625,360.9225,10.94297,-7.139007,0.5502824,4.142742,100.0014
16.12917,362.2476,10.93505,-7.125478,0.55381,4.172752,100.001
16.19583,363.576,10.92659,-7.131622,0.555943,4.192255,100.0084
16.2625,364.905,10.91794,-7.144981,0.5575664,4.207959,99.98858
16.32916,366.2307,10.90897,-7.157078,0.5592625,4.224239,99.98691
16.39584,367.5569,10.8998,-7.17282,0.5606873,4.238492,100.0242
16.4625,368.8873,10.89048,-7.19033,0.5619762,4.251742,99.99044
16.52917,370.2088,10.88036,-7.221506,0.5622982,4.257696,99.97813
16.59583,371.5342,10.86727,-7.271137,0.5613246,4.25384,99.97882
16.6625,372.862,10.85522,-7.312301,0.560932,4.25439,99.94992
16.72916,374.188,10.84378,-7.359335,0.5601212,4.251772,100.0018
16.79584,375.5142,10.82668,-7.429468,0.557699,4.236896,100.0179
16.8625,376.8396,10.81045,-7.520196,0.5538486,4.211142,99.98719
16.92917,378.168,10.79308,-7.629806,0.5486944,4.175425,100.0139
16.99583,379.4956,10.77713,-7.729331,0.5442398,4.144965,99.98625
17.0625,380.8248,10.76161,-7.828606,0.5398152,4.114566,99.9825
17.12917,382.1562,10.74626,-7.926456,0.5354938,4.084872,100.0471
17.19583,383.4873,10.73057,-8.027058,0.5309812,4.053672,100.0102
17.2625,384.8189,10.71454,-8.127845,0.5264535,4.022308,100.0033
17.32916,386.1492,10.69799,-8.231603,0.5217206,3.989325,99.99063
17.39584,387.4796,10.68098,-8.343303,0.5164404,3.952097,100.0001
17.4625,388.8102,10.66323,-8.465329,0.510459,3.909438,100.0131
17.52917,390.1428,10.64432,-8.590305,0.5042782,3.865182,100.0045
17.59583,391.4742,10.62495,-8.718922,0.4978533,3.818982,99.9983
17.6625,392.8097,10.60478,-8.853524,0.4910291,3.769643,99.99851
17.72916,394.142,10.58326,-8.983934,0.4844906,3.722418,99.97301
17.79584,395.477,10.56065,-9.113105,0.4780414,3.675804,99.97841
17.8625,396.8132,10.53678,-9.244889,0.4714214,3.627802,100.0092
17.92917,398.1476,10.51233,-9.372516,0.4650844,3.581867,99.99924
17.99583,399.482,10.4873,-9.495934,0.4590446,3.538068,99.99819
18.0625,400.82,10.46152,-9.61514,0.4532903,3.496389,99.99247
18.12917,402.1578,10.43521,-9.726332,0.4480709,3.458775,99.99962
18.19583,403.5,10.40848,-9.830866,0.4432932,3.424512,99.98816
18.2625,404.8411,10.38121,-9.928384,0.4389775,3.393767,100.0022
18.32916,406.1832,10.35342,-10.01222,0.435563,3.369948,100.0175
18.39584,407.526,10.32452,-10.07044,0.4338301,3.359111,99.95976
18.4625,408.8723,10.29394,-10.12202,0.4325216,3.351543,100.0294
18.52917,410.2138,10.26345,-10.16703,0.431621,3.347121,99.99712
18.59583,411.5622,10.23263,-10.19716,0.4316809,3.350142,99.98639
18.6625,412.907,10.20162,-10.21662,0.4324094,3.35836,99.99091
18.72916,414.2562,10.16992,-10.21763,0.4343152,3.375736,99.95728
18.79584,415.6048,10.13776,-10.20309,0.4371961,3.40072,100.0189
18.8625,416.9567,10.10491,-10.17896,0.4406668,3.430289,100.0075
18.92917,418.3082,10.07185,-10.14946,0.4444441,3.462256,100.047
18.99583,419.6548,10.0388,-10.11183,0.4486948,3.497956,99.99524
19.0625,421.0139,10.00575,-10.06864,0.4532656,3.5362,100.0285
19.12917,422.369,9.972832,-10.01703,0.4583216,3.578283,100.0072
19.19583,423.7206,9.939966,-9.962202,0.463525,3.621576,100.034
19.2625,425.0744,9.907372,-9.902475,0.4689874,3.66695,99.98882
19.32916,426.429,9.874825,-9.843022,0.4743757,3.711802,99.98515
19.39584,427.7824,9.842609,-9.779548,0.47996,3.758248,99.97291
19.4625,429.1387,9.810644,-9.715091,0.4855512,3.80481,100.0047
19.52917,430.4891,9.778899,-9.651642,0.4910139,3.850424,99.97922
19.59583,431.8413,9.747599,-9.581572,0.4968357,3.898914,100.0406
19.6625,433.1952,9.716559,-9.520691,0.5020236,3.942488,99.96225
19.72916,434.546,9.685981,-9.458739,0.5072203,3.986168,100.0229
19.79584,435.8945,9.655897,-9.397803,0.5123044,4.02894,99.98392
19.8625,437.2443,9.626082,-9.336845,0.5173374,4.07134,99.99391
19.92917,438.5961,9.596686,-9.277001,0.5222475,4.112828,99.98312
19.99583,439.941,9.567568,-9.218516,0.5270112,4.153214,99.98784
20.0625,441.2897,9.539269,-9.164822,0.5314309,4.19093,100.0208
20.12917,442.636,9.511078,-9.111799,0.535755,4.227935,99.99285
20.19583,443.9763,9.483491,-9.063928,0.5397076,4.262046,100.0067
20.2625,445.3196,9.456069,-9.014562,0.5437055,4.296549,99.98992
20.32916,446.6638,9.429053,-8.962574,0.5478139,4.33197,99.99871
20.39584,448.0054,9.402676,-8.911305,0.5518265,4.36667,99.99871
20.4625,449.3465,9.37632,-8.868621,0.5552724,4.396924,100.0066
20.52917,450.6895,9.350508,-8.825268,0.5587152,4.427186,100.0128
20.59583,452.032,9.324969,-8.78096,0.5621695,4.457572,100.0007
20.6625,453.3659,9.299744,-8.734741,0.5656874,4.488471,100.0585
20.72916,454.7089,9.274882,-8.695212,0.5687789,4.51596,99.97982
20.79584,456.0479,9.250009,-8.651837,0.5720525,4.544918,99.98828
20.8625,457.3896,9.225594,-8.614161,0.5749496,4.570912,100.0136
20.92917,458.7304,9.201278,-8.577231,0.5777615,4.596254,99.97775
20.99583,460.0693,9.177132,-8.540575,0.5805157,4.621164,99.96688
21.0625,461.405,9.15318,-8.495369,0.5837282,4.649746,99.99852
21.12917,462.7452,9.129422,-8.452245,0.5867821,4.677094,99.96272
21.19583,464.0797,9.105661,-8.413934,0.5895096,4.70187,100.0141
21.2625,465.4204,9.082056,-8.377725,0.5920844,4.725452,100.0006
21.32916,466.7566,9.058434,-8.340282,0.5946888,4.749291,99.9725
21.39584,468.0967,9.034972,-8.306906,0.597028,4.771033,99.99579
21.4625,469.4343,9.01134,-8.266969,0.5997038,4.795496,100.0066
21.52917,470.771,8.987718,-8.230371,0.6021534,4.818164,99.99386
21.59583,472.1088,8.96395,-8.193131,0.6046064,4.840881,100.0328
21.6625,473.4498,8.940179,-8.153916,0.6071424,4.864265,100.018
21.72916,474.7872,8.916403,-8.116904,0.6095161,4.886368,99.98151
21.79584,476.1243,8.892363,-8.079853,0.6118599,4.908248,100.0226
21.8625,477.4608,8.868228,-8.041368,0.6142514,4.930531,99.99539
21.92917,478.8018,8.844225,-8.005274,0.6164814,4.951541,99.97882
21.99583,480.1364,8.819994,-7.966572,0.6188202,4.973444,99.99937
22.0625,481.4727,8.795642,-7.92872,0.621083,4.994756,100.0157
22.12917,482.8087,8.770819,-7.895855,0.6230396,5.013624,99.97051
22.19583,484.1472,8.745884,-7.860016,0.6251365,5.033634,99.981
22.2625,485.485,8.720838,-7.826264,0.6270894,5.052506,100.0314
22.32916,486.8208,8.695688,-7.786795,0.629327,5.073691,99.99655
22.39584,488.1586,8.670462,-7.750891,0.6313438,5.093116,100.0255
22.4625,489.4922,8.644788,-7.71666,0.633241,5.11159,100.0306
22.52917,490.8281,8.614049,-7.702815,0.6340113,5.120974,99.99601
22.59583,492.1652,8.583718,-7.691318,0.6346422,5.129219,100.0087
22.6625,493.503,8.555366,-7.680806,0.635207,5.136921,99.99058
22.72916,494.836,8.528062,-7.668886,0.6358303,5.1451,100.015
22.79584,496.1709,8.501084,-7.655012,0.6365469,5.154034,100.0422
22.8625,497.5082,8.474574,-7.638208,0.6374079,5.164146,100.0377
22.92917,498.8408,8.448671,-7.616174,0.6385293,5.176376,100.0283
22.99583,500.1769,8.422437,-7.593228,0.639687,5.188906,99.99126
23.0625,501.5111,8.396399,-7.571032,0.6407895,5.200998,100.0371
23.12917,502.8497,8.3705,-7.544624,0.6421039,5.214818,99.99422
23.19583,504.1836,8.344853,-7.529368,0.6428137,5.223736,100.0084
23.2625,505.5205,8.319189,-7.507454,0.643861,5.235408,99.99855
23.32916,506.8546,8.293701,-7.483056,0.6450229,5.248018,99.98961
23.39584,508.1904,8.268276,-7.462744,0.6459604,5.258808,99.97692
23.4625,509.528,8.243098,-7.440728,0.6469726,5.270216,100.0122
23.52917,510.8644,8.217972,-7.417687,0.6480256,5.281949,100.009
23.59583,512.2019,8.19291,-7.396376,0.6489812,5.29285,99.96369
23.6625,513.535,8.167992,-7.381825,0.6495752,5.300801,100.0527
23.72916,514.8716,8.143214,-7.363018,0.6503784,5.310464,99.99438
23.79584,516.2092,8.118787,-7.3482,0.6509669,5.318378,99.97356
23.8625,517.544,8.094425,-7.330937,0.6516662,5.3272,99.97941
23.92917,518.8785,8.07038,-7.322276,0.6519174,5.332361,100.011
23.99583,520.2146,8.046449,-7.312668,0.6522096,5.337857,100.0227
24.0625,521.5474,8.022753,-7.298603,0.6527141,5.34509,99.95849
24.12917,522.8828,7.999187,-7.285131,0.6531788,5.352002,100.0015
24.19583,524.2175,7.975906,-7.272332,0.653598,5.358545,100.0361
24.2625,525.5486,7.952743,-7.26882,0.6535446,5.361206,99.99659
24.32916,526.8843,7.930118,-7.267932,0.653355,5.36275,99.96148
24.39584,528.2196,7.907606,-7.267079,0.6531546,5.364205,99.98856
24.4625,529.5544,7.885352,-7.260638,0.6532242,5.367871,99.99976
24.52917,530.8876,7.863339,-7.259503,0.6530258,5.369312,100.0382
24.59583,532.2213,7.841553,-7.25498,0.6529874,5.372055,99.97325
24.6625,533.5552,7.820108,-7.250088,0.6529596,5.374879,99.9759
24.72916,534.8914,7.799047,-7.245844,0.652893,5.377382,100.0186
24.79584,536.2219,7.778234,-7.246862,0.6525592,5.377679,99.99246
24.8625,537.556,7.757669,-7.247555,0.652238,5.378072,100.0651
24.92917,538.888,7.737478,-7.252199,0.6517172,5.376816,100.008
24.99583,540.2205,7.717506,-7.260645,0.6510082,5.374,100.001
25.0625,541.5508,7.697918,-7.267776,0.6503565,5.371646,99.98394
25.12917,542.885,7.67881,-7.281489,0.6493888,5.36667,99.96754
25.19583,544.2157,7.659919,-7.297436,0.6483074,5.360748,100.0076
25.2625,545.5461,7.641382,-7.315522,0.6471221,5.35395,99.96694
25.32916,546.8794,7.623247,-7.337172,0.645767,5.345738,99.98298
25.39584,548.2129,7.605407,-7.360597,0.644327,5.336807,100.0268
25.4625,549.546,7.587813,-7.386994,0.6427456,5.326688,100.002
25.52917,550.878,7.570788,-7.418715,0.6409201,5.314484,99.99018
25.59583,552.2049,7.553907,-7.449307,0.6391478,5.302682,99.98145
25.6625,553.537,7.537418,-7.485374,0.6371254,5.288782,99.99022
25.72916,554.8678,7.521212,-7.537728,0.634345,5.26857,100.0223
25.79584,556.1962,7.505342,-7.585212,0.6317954,5.25025,100.0216
25.8625,557.5282,7.489918,-7.644061,0.6287292,5.227605,99.98624
25.92916,558.855,7.474829,-7.69853,0.6258686,5.206643,100.0364
25.99583,560.1855,7.460019,-7.759304,0.622727,5.183313,100.0156
26.0625,561.5145,7.445609,-7.82232,0.6194891,5.159156,100.0009
26.12917,562.8432,7.431457,-7.888953,0.6160957,5.133664,100.0072
26.19584,564.1678,7.417788,-7.960826,0.6124694,5.106202,99.98519
26.2625,565.5011,7.404134,-8.032176,0.6088834,5.07904,100.0017
26.32916,566.8307,7.39105,-8.11753,0.604668,5.046596,99.9592
26.39584,568.1556,7.378213,-8.206332,0.6003086,5.012906,99.97584
26.4625,569.4824,7.365506,-8.301416,0.5956817,4.976938,99.98832
26.52917,570.811,7.353241,-8.398585,0.5909793,4.94028,100.0205
26.59583,572.1386,7.341141,-8.504999,0.585879,4.90024,100.0051
26.6625,573.4671,7.32957,-8.612418,0.5807516,4.859926,100.0068
26.72916,574.7964,7.318303,-8.721628,0.5755622,4.819048,99.96709
26.79584,576.12,7.307242,-8.834838,0.5702107,4.77676,100.0063
26.8625,577.4476,7.296436,-8.946219,0.5649602,4.735272,100.0177
26.92916,578.775,7.285891,-9.065098,0.5593956,4.691101,100.0178
26.99583,580.1036,7.275654,-9.192238,0.553486,4.643989,99.98728
27.0625,581.4296,7.265581,-9.328961,0.5471752,4.593451,99.99749
27.12917,582.7566,7.255806,-9.458809,0.5411874,4.545574,99.9963
27.19584,584.083,7.246219,-9.594316,0.5349736,4.49574,100.0101
27.2625,585.4096,7.236864,-9.725111,0.5289888,4.447774,99.96908
27.32916,586.7324,7.227704,-9.864405,0.5226516,4.396789,99.99882
27.39584,588.0554,7.218757,-10.00695,0.5161952,4.344744,100.0364
27.4625,589.3801,7.210053,-10.14153,0.5101078,4.295746,99.98664
27.52917,590.7086,7.201486,-10.27985,0.5038878,4.245523,99.97862
27.59583,592.0344,7.193292,-10.42419,0.4974316,4.193213,100.0031
27.6625,593.3589,7.185119,-10.57301,0.490803,4.139395,100.0147
27.72916,594.6838,7.17717,-10.71467,0.4845036,4.088298,100.0099
27.79584,596.0118,7.16939,-10.84723,0.4786142,4.04061,100.0289
27.8625,597.3359,7.161811,-10.98207,0.4726424,3.992172,99.96587
27.92916,598.6609,7.154251,-11.12288,0.4664346,3.941694,100.0374
27.99583,599.9871,7.146966,-11.26167,0.460334,3.892064,99.99859
28.0625,601.3134,7.139863,-11.40306,0.454141,3.841602,99.98793
28.12917,602.6388,7.132815,-11.5361,0.4483166,3.794208,100.019
28.19584,603.9654,7.126016,-11.66723,0.4425898,3.747591,100.0016
28.2625,605.2906,7.119176,-11.79966,0.4368222,3.70058,100.0278
28.32916,606.6168,7.112418,-11.93356,0.4310094,3.653138,100.0196
28.39584,607.9415,7.10599,-12.06639,0.4252548,3.60614,99.99188
28.4625,609.2686,7.099753,-12.19792,0.4195732,3.559711,99.99197
28.52917,610.5918,7.093408,-12.32148,0.414212,3.51613,99.98322
28.59583,611.9192,7.087268,-12.45,0.4086264,3.470896,100.0134
28.6625,613.248,7.081112,-12.57458,0.4032172,3.42712,100.0065
28.72916,614.576,7.075094,-12.70026,0.3977759,3.383013,100.0093
28.79584,615.9028,7.069134,-12.82795,0.392265,3.338254,99.96431
28.8625,617.2298,7.063366,-12.95514,0.38679,3.293741,100.0187
28.92916,618.5537,7.057602,-13.07892,0.3814661,3.250455,99.97701
28.99583,619.8819,7.052066,-13.20281,0.376153,3.207205,100.0458
29.0625,621.2074,7.04646,-13.32321,0.3709926,3.165198,100.0084
29.12917,622.5362,7.0409,-13.4502,0.3655805,3.120986,100.0431
29.19584,623.8609,7.03543,-13.57215,0.3603811,3.078534,99.98957
29.2625,625.1879,7.0299,-13.7007,0.3549295,3.033869,100.023
29.32916,626.5156,7.024545,-13.82253,0.3497614,2.99157,99.98544
29.39584,627.8451,7.01917,-13.93522,0.3449726,2.952462,100.0072
29.4625,629.1732,7.013955,-14.05026,0.3400985,2.912572,100.0252
29.52917,630.4986,7.008787,-14.16425,0.3352771,2.87305,99.98934
29.59583,631.8279,7.003668,-14.27727,0.3305235,2.833915,100.0113
29.6625,633.1576,6.998514,-14.39688,0.3255199,2.792555,99.98111
29.72916,634.4825,6.993389,-14.51937,0.3204086,2.750222,100.0162
29.79584,635.8109,6.988184,-14.65939,0.3146151,2.70198,99.98084
29.8625,637.1394,6.983303,-14.80532,0.3086016,2.651795,100.016
29.92916,638.4658,6.978432,-14.92349,0.3036924,2.611046,100.0196
29.99583,639.796,6.973437,-15.03989,0.2988656,2.570959,99.98613
30.0625,641.124,6.968599,-15.16019,0.2938916,2.529558,99.99754
30.12917,642.4503,6.963634,-15.28746,0.2886526,2.485827,100.0187
30.19584,643.7766,6.958762,-15.4112,0.2835612,2.443318,99.99822
30.2625,645.1032,6.954059,-15.53428,0.2785039,2.401054,99.97652
30.32916,646.4311,6.949155,-15.65886,0.2733971,2.358317,99.9818
30.39584,647.7606,6.944426,-15.79195,0.2679708,2.312773,99.99184
30.4625,649.0855,6.93968,-15.9114,0.2630782,2.271787,99.98369
30.52917,650.4137,6.934949,-16.04259,0.2577442,2.226938,99.98539
30.59583,651.7371,6.930426,-16.17784,0.2522574,2.180718,99.98243
30.6625,653.0628,6.925772,-16.31853,0.2465734,2.132742,99.99803
30.72916,654.3884,6.921199,-16.45109,0.2412107,2.087492,100.0023
30.79584,655.7164,6.916706,-16.58899,0.2356554,2.040522,99.99788
30.8625,657.041,6.912218,-16.73463,0.2298105,1.990992,100.0221
30.92916,658.372,6.907799,-16.86917,0.2244054,1.945218,100.0217
30.99583,659.6922,6.903384,-17.00736,0.2188616,1.89819,100.0285
31.0625,661.0226,6.898954,-17.15359,0.2130301,1.848613,99.9893
31.12917,662.3441,6.894714,-17.297,0.2073085,1.799935,100.008
31.19584,663.6699,6.890478,-17.44128,0.2015664,1.751025,100.022
31.2625,664.9965,6.886234,-17.58322,0.1959213,1.702906,99.97439
31.32916,666.3222,6.882019,-17.72858,0.1901562,1.653689,99.98085
31.39584,667.648,6.877936,-17.86926,0.1845758,1.606024,100.0107
31.4625,668.9734,6.873806,-18.00747,0.1790951,1.559176,99.99957
31.52917,670.2995,6.86973,-18.15696,0.1732025,1.508687,99.98694
31.59583,671.625,6.865699,-18.30036,0.1675448,1.460191,100.0049
31.6625,672.9547,6.861545,-18.44875,0.1617129,1.410122,99.9972
31.72916,674.2813,6.857719,-18.60378,0.15564,1.357896,99.98355
31.79584,675.6054,6.853631,-18.75925,0.1495586,1.305539,100.0101
31.8625,676.9337,6.849616,-18.91852,0.1433496,1.25201,100.0009
31.92916,678.2588,6.845665,-19.08545,0.1368652,1.196016,99.96699
31.99583,679.5844,6.841786,-19.23847,0.1309052,1.144546,99.97866
32.0625,680.9109,6.837994,-19.4027,0.1245407,1.089482,100.0195
32.12916,682.2336,6.834268,-19.55002,0.1188053,1.039865,100.003
32.19584,683.5616,6.830614,-19.70268,0.1128847,0.9885705,99.97512
32.2625,684.889,6.826734,-19.85624,0.1069383,0.9369966,99.98647
32.32916,686.2124,6.823199,-20.02042,0.1006108,0.8820244,100.0052
32.39583,687.5347,6.819343,-20.18231,0.09437441,0.8277918,100.0222
32.4625,688.8624,6.815862,-20.34334,0.08818175,0.7738858,100.0354
32.52917,690.185,6.812382,-20.49861,0.08220211,0.721792,100.0013
32.59583,691.5144,6.808949,-20.65835,0.07607272,0.6683266,99.99126
32.6625,692.8394,6.805576,-20.82028,0.0698686,0.6141437,100.0259
32.72917,694.1616,6.802216,-20.97687,0.0638648,0.5616621,100.0131
32.79584,695.4869,6.798772,-21.13432,0.05783889,0.5089306,100.0041
32.8625,696.8163,6.795469,-21.28805,0.05195383,0.4573848,99.97754
32.92916,698.1414,6.791826,-21.44263,0.0460406,0.405537,99.99491
32.99584,699.4698,6.788626,-21.59661,0.04015808,0.3539055,100.0264
33.0625,700.7939,6.785597,-21.75092,0.03426509,0.302128,99.99254
33.12916,702.1238,6.782606,-21.91185,0.02814669,0.2483077,100.0236
33.19584,703.45,6.779498,-22.07115,0.02208978,0.1949742,99.95601
33.2625,704.7746,6.776556,-22.23876,0.01574364,0.1390314,99.97931
33.32916,706.103,6.773671,-22.40915,0.009308944,0.08224778,99.9911
33.39583,707.4321,6.770761,-22.57992,0.002869172,0.02536039,100.0083
33.4625,708.7548,6.767887,-22.75113,-3.58E-03,-0.03168552,100.05
33.52917,710.086,6.765246,-22.91854,-9.89E-03,-0.08748918,99.99054
33.59583,711.4106,6.76249,-23.08944,-0.01630883,-0.1444028,99.98336
33.6625,712.7356,6.759722,-23.25892,-0.02267162,-0.200843,100.0149
33.72917,714.0662,6.757113,-23.43822,-0.02936787,-0.2602968,99.99985
33.79584,715.3928,6.754472,-23.62237,-0.0362266,-0.3212522,100.0155
33.8625,716.717,6.751843,-23.79692,-0.04274163,-0.379221,99.95932
33.92916,718.0438,6.74927,-23.97118,-0.04923338,-0.4370424,99.99054
33.99584,719.3703,6.746679,-24.14162,-0.05558479,-0.4936767,99.96402
34.0625,720.6998,6.744108,-24.31759,-0.06211633,-0.5519701,99.99676
34.12916,722.0251,6.74153,-24.49102,-0.06855307,-0.6094795,100.0108
34.19584,723.3522,6.738831,-24.66267,-0.07491688,-0.6663995,100.0104
34.2625,724.6782,6.736197,-24.83446,-0.08127655,-0.7233401,100.04
34.32916,726.005,6.733962,-25.00634,-0.08762796,-0.7802657,100.0061
34.39583,727.3326,6.731756,-25.17586,-0.09388954,-0.836449,99.97792
34.4625,728.6551,6.729522,-25.35002,-0.100302,-0.8940334,99.98189
34.52917,729.9837,6.72742,-25.52182,-0.106618,-0.9508164,100.0102
34.59583,731.31,6.725302,-25.70387,-0.1132778,-1.010725,99.99801
34.6625,732.635,6.723351,-25.89092,-0.1200969,-1.072115,99.9685
34.72917,733.9615,6.721314,-26.07511,-0.1268038,-1.132566,100.0051
34.79584,735.287,6.719239,-26.25482,-0.1333464,-1.19161,100.0123
34.8625,736.615,6.717351,-26.43397,-0.1398544,-1.250404,100.0238
34.92916,737.9376,6.71535,-26.61492,-0.1464161,-1.309737,99.98264
34.99584,739.267,6.713443,-26.80217,-0.1531724,-1.370872,99.97539
35.0625,740.5903,6.71177,-26.99622,-0.1601507,-1.434056,100.0107
35.12916,741.9171,6.710028,-27.18125,-0.1668051,-1.494401,100.0132
35.19584,743.2397,6.708304,-27.36084,-0.1732654,-1.553069,99.97809
35.2625,744.5656,6.706788,-27.54362,-0.179816,-1.612603,99.96626
35.32916,745.8901,6.704874,-27.71832,-0.1860812,-1.669637,100.0266
35.39583,747.2182,6.703438,-27.89788,-0.1924938,-1.728051,100.0123
35.4625,748.5429,6.701853,-28.07454,-0.1987981,-1.785551,99.98766
35.52917,749.869,6.700488,-28.25398,-0.2051781,-1.843788,100.0052
35.59583,751.1949,6.69897,-28.42947,-0.2114122,-1.900772,99.99359
35.6625,752.5212,6.697322,-28.60754,-0.217717,-1.958449,100.0447
35.72917,753.8453,6.695974,-28.79067,-0.2241765,-2.017574,100.0105
35.79584,755.169,6.694728,-28.97024,-0.2305011,-2.075537,99.99382
35.8625,756.4956,6.693191,-29.14932,-0.2367925,-2.133255,100.0098
35.92916,757.8225,6.69174,-29.3273,-0.243032,-2.190561,99.97631
35.99584,759.1497,6.69043,-29.50266,-0.249168,-2.246991,99.99137
36.0625,760.4772,6.6892,-29.67978,-0.2553442,-2.303839,99.96728
36.12916,761.7988,6.68803,-29.8562,-0.2614856,-2.360427,99.98444
36.19584,763.1274,6.68669,-30.04482,-0.2680026,-2.420464,99.99054
36.2625,764.4518,6.6854,-30.23897,-0.274685,-2.482053,100.0179
36.32916,765.7765,6.684258,-30.41097,-0.280624,-2.53698,100.0254
36.39583,767.0997,6.683241,-30.58344,-0.2865626,-2.591959,99.96481
36.4625,768.43,6.682129,-30.75559,-0.2924647,-2.646661,99.99378
36.52917,769.7566,6.681134,-30.92961,-0.2984148,-2.701852,99.99699
36.59583,771.0806,6.680074,-31.10676,-0.3044484,-2.75785,99.98226
36.6625,772.4058,6.679021,-31.27954,-0.310319,-2.812427,99.98499
36.72917,773.7305,6.678075,-31.41722,-0.3150386,-2.85662,99.98126
36.79584,775.059,6.677026,-31.56019,-0.3199104,-2.902237,100.0065
36.8625,776.3831,6.676028,-31.7493,-0.3262555,-2.961256,100.0121
36.92916,777.7078,6.675126,-31.94114,-0.3326647,-3.02091,100.0233
36.99584,779.0326,6.674174,-32.11953,-0.338618,-3.07648,100.0006
37.0625,780.3599,6.673285,-32.30165,-0.3446678,-3.13298,99.99789
37.12916,781.685,6.672451,-32.47592,-0.3504474,-3.187078,99.98048
37.19584,783.0082,6.671518,-32.66442,-0.3566617,-3.245183,99.98366
37.2625,784.3347,6.670574,-32.85239,-0.3628289,-3.302911,99.99666
37.32916,785.6602,6.66977,-33.01898,-0.3682974,-3.354334,99.98382
37.39583,786.9818,6.668906,-33.18646,-0.3737767,-3.405905,99.96506
37.4625,788.3093,6.668062,-33.35064,-0.3791217,-3.4563,99.99447
37.52917,789.6328,6.667376,-33.53074,-0.384952,-3.511167,100.0236
37.59583,790.9605,6.666562,-33.6871,-0.3900074,-3.559018,100.0029
37.6625,792.2868,6.665821,-33.86325,-0.3956645,-3.612408,100.0386
37.72917,793.6132,6.665007,-34.01917,-0.4006619,-3.659819,100.0027
37.79584,794.9406,6.664082,-34.1742,-0.4056084,-3.706812,100.008
37.8625,796.265,6.663462,-34.3281,-0.4105053,-3.75339,100.0213
37.92916,797.5908,6.662826,-34.48366,-0.4154296,-3.80025,99.9782
37.99584,798.9188,6.662016,-34.63554,-0.4202144,-3.845876,99.97405
38.0625,800.2486,6.661355,-34.79094,-0.4250859,-3.892341,100.0182
38.12916,801.5732,6.660735,-34.94305,-0.4298393,-3.937768,100.0236
38.19584,802.9046,6.660062,-35.09683,-0.4346111,-3.983403,100.0182
38.2625,804.2307,6.659305,-35.25518,-0.4395088,-4.030235,100.0115
38.32916,805.5584,6.658614,-35.41454,-0.4444141,-4.077184,99.99511
38.39583,806.8884,6.657918,-35.55871,-0.448826,-4.119644,100.0146
38.4625,808.215,6.657224,-35.71312,-0.4535355,-4.16488,99.97238
38.52917,809.5445,6.656565,-35.87022,-0.4582997,-4.210657,99.99397
38.59583,810.8714,6.655795,-36.0193,-0.4628018,-4.25407,99.99744
38.6625,812.1986,6.655305,-36.16872,-0.4672903,-4.297396,100.0062
38.72917,813.5245,6.654816,-36.32775,-0.4720507,-4.343262,100.026
38.79584,814.8554,6.653985,-36.47484,-0.4764216,-4.385588,99.99374
38.8625,816.1835,6.65348,-36.62547,-0.480883,-4.428787,99.98066
38.92916,817.513,6.652868,-36.78044,-0.4854515,-4.473013,100.0052
38.99584,818.84,6.652288,-36.94955,-0.4904217,-4.52098,99.96032
39.0625,820.166,6.651622,-37.10887,-0.4950765,-4.566079,100.0261
39.12916,821.4945,6.651024,-37.25975,-0.4994546,-4.60867,100.0192
39.19584,822.823,6.650558,-37.40493,-0.5036441,-4.64956,99.99256
39.2625,824.1494,6.649882,-37.55115,-0.5078492,-4.690634,99.99486
39.32916,825.4772,6.64944,-37.69662,-0.5120075,-4.731309,100.0168
39.39583,826.8038,6.648738,-37.84595,-0.516259,-4.77288,99.9892
39.4625,828.1296,6.6482,-37.99592,-0.5205118,-4.814502,100.0156
39.52917,829.4588,6.647555,-38.13812,-0.5245115,-4.853822,99.98368
39.59583,830.7842,6.647044,-38.26938,-0.5281798,-4.89011,99.99907
39.6625,832.1144,6.646482,-38.40448,-0.5319324,-4.92721,100.0093
39.72917,833.441,6.645979,-38.53769,-0.5356228,-4.963771,100.0134
39.79584,834.771,6.645364,-38.67501,-0.5394086,-5.001248,100.0479
39.8625,836.0989,6.644809,-38.80704,-0.543028,-5.037219,100.0075
39.92916,837.4272,6.644188,-38.94835,-0.5468988,-5.075546,99.93822
39.99584,838.757,6.643716,-39.07459,-0.550316,-5.10968,100.0213
40.0625,840.0842,6.643258,-39.20725,-0.5539086,-5.14547,100.0048
40.12916,841.4122,6.642613,-39.32735,-0.5571228,-5.177776,100.0165
40.19584,842.7406,6.642007,-39.43482,-0.5599613,-5.206616,99.96476
40.2625,844.067,6.641485,-39.54058,-0.5627432,-5.234954,99.97382
40.32916,845.3958,6.64086,-39.67125,-0.5662163,-5.269752,100.0098
40.39583,846.7278,6.640306,-39.79045,-0.5693446,-5.301372,99.9865
40.4625,848.0545,6.639891,-39.91458,-0.5726078,-5.334275,99.98626
40.52917,849.382,6.639352,-40.03443,-0.5757343,-5.365932,100.0051
40.59583,850.7101,6.638892,-40.15197,-0.5787826,-5.396889,99.97774
40.6625,852.039,6.638236,-40.27087,-0.5818539,-5.428088,100.0053
40.72917,853.3671,6.637722,-40.36914,-0.5843415,-5.453868,100.032
40.79584,854.6982,6.637189,-40.46189,-0.5866604,-5.478094,100.0217
40.8625,856.0239,6.636694,-40.57015,-0.5894115,-5.50638,99.99549
40.92916,857.3542,6.636106,-40.67328,-0.5920005,-5.533174,99.9865
40.99584,858.685,6.635394,-40.75482,-0.5939853,-5.554342,99.99058
41.0625,860.0081,6.634903,-40.8423,-0.5961432,-5.577149,100.0102
41.12916,861.3374,6.634332,-40.92676,-0.5981987,-5.599015,99.98296
41.19584,862.6653,6.633912,-41.0128,-0.600295,-5.621283,100.0116
41.2625,863.9982,6.633494,-41.08325,-0.601953,-5.639468,99.99695
41.32916,865.3265,6.632982,-41.15424,-0.6036329,-5.657873,100.018
41.39583,866.6566,6.632372,-41.2322,-0.6054898,-5.677949,100.0016
41.4625,867.9856,6.631882,-41.29952,-0.6070599,-5.695352,100.0038
41.52917,869.3164,6.631408,-41.3575,-0.6083724,-5.710355,99.99652
41.59583,870.6449,6.630842,-41.4228,-0.6098865,-5.727261,99.98406
41.6625,871.9743,6.630297,-41.46624,-0.6108132,-5.738664,100.0091
41.72917,873.3049,6.62976,-41.50756,-0.6116837,-5.749549,100.0106
41.79584,874.6359,6.629194,-41.55184,-0.6126344,-5.761196,99.97766
41.8625,875.9655,6.62872,-41.60211,-0.613747,-5.774375,100.0174
41.92916,877.2976,6.6282,-41.63632,-0.6144374,-5.783593,99.96942
41.99584,878.6301,6.627704,-41.66852,-0.6150772,-5.792328,99.97762
42.0625,879.9597,6.6272,-41.70219,-0.6157715,-5.801541,100.0142
42.12916,881.2922,6.626871,-41.74122,-0.6166044,-5.812064,100.0073
42.19584,882.6249,6.626342,-41.76774,-0.6171139,-5.819543,100.0067
42.2625,883.9555,6.625718,-41.77884,-0.6172356,-5.823374,100.0143
42.32916,885.2855,6.62527,-41.80582,-0.6177735,-5.831129,100
42.39583,886.6172,6.6247,-41.81648,-0.6178932,-5.834942,100.0194
42.4625,887.9431,6.624256,-41.84281,-0.6184365,-5.842758,99.98939
42.52917,889.2778,6.6237,-41.85512,-0.6186062,-5.847045,100.0241
42.59583,890.6074,6.623136,-41.86464,-0.6187286,-5.850894,99.99535
42.6625,891.9379,6.62273,-41.87194,-0.6187988,-5.854247,100.0188
42.72917,893.2701,6.622191,-41.87256,-0.6187051,-5.856051,99.99561
42.79584,894.6022,6.621776,-41.8637,-0.6183838,-5.855702,99.99634
42.8625,895.9358,6.621319,-41.85586,-0.6180984,-5.85569,100.0035
42.92916,897.2658,6.620801,-41.851,-0.6179078,-5.856576,99.95255
42.99584,898.5941,6.620376,-41.85095,-0.6178504,-5.858724,100.0073
43.0625,899.93,6.619846,-41.8335,-0.61735,-5.85669,100.008
43.12916,901.258,6.619226,-41.82372,-0.6170787,-5.856842,99.98689
43.19584,902.5934,6.61876,-41.80433,-0.6165534,-5.854568,100.0205
43.2625,903.9236,6.618272,-41.77797,-0.6158915,-5.851005,100.0018
43.32916,905.2559,6.6179,-41.7672,-0.6156228,-5.851171,99.99361
43.39583,906.5889,6.617382,-41.75168,-0.615247,-5.850316,100.0027
43.4625,907.9184,6.616956,-41.73898,-0.6149598,-5.8503,99.99934
43.52917,909.2507,6.616335,-41.70676,-0.614204,-5.845822,100.0227
43.59583,910.5804,6.61584,-41.67941,-0.6135878,-5.84267,99.99781
43.6625,911.9141,6.615494,-41.64506,-0.6128086,-5.83796,99.97644
43.72917,913.2475,6.614942,-41.62107,-0.6122992,-5.835818,99.98915
43.79584,914.5782,6.614331,-41.59125,-0.611668,-5.832507,100.017
43.8625,915.9112,6.613958,-41.54861,-0.6107406,-5.826368,100.0116
43.92916,917.2426,6.6134,-41.51018,-0.6099346,-5.82138,99.95551
43.99584,918.5762,6.612903,-41.46162,-0.608897,-5.814174,99.98812
44.0625,919.9072,6.61246,-41.40533,-0.6077055,-5.80546,100.0118
44.12916,921.2391,6.612003,-41.366,-0.6069376,-5.80076,100.0213
44.19584,922.5715,6.611592,-41.32265,-0.6060894,-5.795281,99.99921
44.2625,923.9056,6.610912,-41.27537,-0.6051621,-5.789041,100.0052
44.32916,925.2353,6.61046,-41.22717,-0.6042414,-5.782859,99.9952
44.39583,926.5692,6.61003,-41.17754,-0.6032952,-5.776421,100.0033
44.4625,927.8978,6.609496,-41.13648,-0.6025813,-5.772206,99.98811
44.52917,929.2292,6.609054,-41.1072,-0.6021484,-5.770675,99.9715
44.59583,930.5629,6.608501,-41.08912,-0.6019888,-5.771764,100.0219
44.6625,931.8899,6.607928,-41.0501,-0.6013703,-5.768448,100.0252
44.72917,933.2231,6.607514,-41.01326,-0.600806,-5.765649,100.0033
44.79584,934.5555,6.606976,-40.99232,-0.6006283,-5.766559,100.0108
44.8625,935.8863,6.606454,-40.96436,-0.6003041,-5.766059,99.97001
44.92916,937.2194,6.60603,-40.94194,-0.6001172,-5.76688,99.95496
44.99584,938.5504,6.605364,-40.94,-0.600415,-5.772359,99.95578
45.0625,939.8803,6.604996,-40.93225,-0.6005926,-5.776682,100.0052
45.12916,941.2106,6.604364,-40.93313,-0.6009757,-5.782988,99.99219
45.19584,942.5436,6.603949,-40.9322,-0.6013232,-5.788956,100.0093
45.2625,943.8719,6.603421,-40.92388,-0.6015259,-5.793531,99.99876
45.32916,945.2026,6.602929,-40.93046,-0.6020653,-5.801354,100.0005
45.39583,946.5316,6.602566,-40.93953,-0.6026763,-5.809873,99.98016
45.4625,947.8594,6.602008,-40.94665,-0.6032535,-5.818074,99.96782
45.52917,949.1911,6.601399,-40.95486,-0.6038559,-5.82652,99.95549
45.59583,950.5231,6.601031,-40.96775,-0.604572,-5.836074,99.98165
45.6625,951.8526,6.600402,-40.98398,-0.6053746,-5.84647,100.0159
45.72917,953.1816,6.599859,-40.9959,-0.6060896,-5.856026,100.01
45.79584,954.5112,6.599356,-41.02605,-0.6072125,-5.869536,99.98087
45.8625,955.8398,6.598842,-41.05852,-0.6083918,-5.883597,100.024
45.92916,957.1707,6.598449,-41.07942,-0.6093209,-5.895251,99.97238
45.99584,958.5006,6.597922,-41.11666,-0.610614,-5.91044,100.0047
46.0625,959.8272,6.597388,-41.14844,-0.6117988,-5.92458,99.99616
46.12916,961.1582,6.596868,-41.16332,-0.6126191,-5.935183,99.99003
46.19584,962.4868,6.596355,-41.19072,-0.6137243,-5.948555,100.0239
46.2625,963.8168,6.595813,-41.22195,-0.6149138,-5.962754,100.0176
46.32916,965.1428,6.595359,-41.25696,-0.6161968,-5.97787,99.97051
46.39583,966.4728,6.594836,-41.28834,-0.6174016,-5.99224,99.99931
46.4625,967.8038,6.59429,-41.3264,-0.6187552,-6.008066,100.0157
46.52917,969.1349,6.593638,-41.36284,-0.62008,-6.023624,99.98504
46.59583,970.4655,6.592947,-41.40402,-0.6215102,-6.040215,100.0105
46.6625,971.7937,6.592657,-41.44524,-0.6229538,-6.056952,100.0054
46.72917,973.1259,6.592084,-41.507,-0.6248214,-6.077825,99.97301
46.79584,974.4551,6.591711,-41.55835,-0.626482,-6.0967,100.0274
46.8625,975.7863,6.59112,-41.61462,-0.6282474,-6.116614,99.97108
46.92916,977.116,6.590669,-41.66333,-0.6298599,-6.135049,100.0113
46.99584,978.4478,6.590126,-41.72295,-0.6316975,-6.155695,99.99171
47.0625,979.7774,6.589484,-41.78337,-0.633559,-6.176586,99.99374
47.12916,981.1055,6.589131,-41.84686,-0.6354868,-6.198144,100.0078
47.19584,982.4366,6.588574,-41.92554,-0.6377202,-6.222696,99.99632
47.2625,983.7672,6.588038,-41.99947,-0.63986,-6.246355,99.99449
47.32916,985.0978,6.587332,-42.06234,-0.641773,-6.267816,99.99941
47.39583,986.4286,6.586982,-42.12246,-0.643636,-6.288808,100.0523
47.4625,987.7561,6.586429,-42.15914,-0.6456994,-6.311775,100.0177
47.49584,988.4208,6.586255,-42.2255,-0.6470082,-6.325974,100.0211