File: examples/pyrolysis/single_element/1D/gold/experiment_comp/20degpermin_run2.csv
Time (min),Temperature (degC),Weight (mg),Heat Flow (mW),Temperature Difference (degC),Temperature Difference (muV),Sample Purge Flow (mL/min)
5.56E-04,49.31304,15.65369,-8.746774,-1.332863,-8.28247,199.9351
0.0625,49.20824,15.65347,-8.752888,-1.334618,-8.290264,100.0166
0.1291666,49.11794,15.65469,-8.764294,-1.337007,-8.302179,100.0419
0.1958334,49.05044,15.65446,-8.769149,-1.338372,-8.308276,99.99031
0.2625,49.01729,15.65416,-8.764924,-1.338303,-8.30627,99.98445
0.3291667,49.03704,15.65348,-8.751444,-1.336632,-8.29559,99.96722
0.3958334,49.117,15.65392,-8.728497,-1.33326,-8.275853,100.0052
0.4625,49.2703,15.65361,-8.698408,-1.328362,-8.248556,99.99938
0.5291666,49.50037,15.65296,-8.668438,-1.322819,-8.219388,99.99109
0.5958334,49.82481,15.65282,-8.634621,-1.316071,-8.18498,100.017
0.6625,50.22922,15.65272,-8.599152,-1.30835,-8.146926,100.0078
0.7291668,50.7425,15.65164,-8.563905,-1.299876,-8.106647,99.98769
0.7958334,51.34476,15.65139,-8.529068,-1.290612,-8.064074,100.0023
0.8625,52.04678,15.65123,-8.496238,-1.280825,-8.020641,99.96984
0.9291668,52.84776,15.65179,-8.463007,-1.270187,-7.97431,99.9953
0.9958332,53.7453,15.65074,-8.436909,-1.259708,-7.931256,99.99781
1.0625,54.73657,15.65156,-8.40916,-1.248264,-7.884337,100.001
1.129167,55.80815,15.65101,-8.384314,-1.236502,-7.837385,100.0173
1.195833,56.97801,15.65067,-8.360656,-1.22422,-7.78902,100.0221
1.2625,58.23056,15.65064,-8.34095,-1.211831,-7.741626,99.98946
1.329166,59.54467,15.65021,-8.32174,-1.198953,-7.692535,100.0089
1.395834,60.93148,15.65039,-8.302306,-1.185765,-7.64146,99.86814
1.4625,62.37888,15.64964,-8.283011,-1.172485,-7.588676,100.0015
1.529167,63.87836,15.64944,-8.265145,-1.159077,-7.535501,100.0022
1.595833,65.42387,15.64906,-8.24825,-1.145524,-7.481762,99.95194
1.6625,67.00758,15.64896,-8.22752,-1.131288,-7.423728,100.0218
1.729166,68.62868,15.64892,-8.209564,-1.117252,-7.366962,100.0218
1.795834,70.26701,15.64854,-8.189276,-1.102829,-7.30745,100.0303
1.8625,71.92403,15.64834,-8.164588,-1.08784,-7.24374,100.0264
1.929166,73.60456,15.64783,-8.141578,-1.073049,-7.180835,99.9678
1.995833,75.29092,15.64712,-8.116531,-1.058068,-7.115931,100.0401
2.0625,76.9757,15.64685,-8.091589,-1.043204,-7.050955,100.0159
2.129166,78.65919,15.64629,-8.06491,-1.028264,-6.9845,100.063
2.195834,80.33494,15.64539,-8.033413,-1.013108,-6.91422,100.0332
2.2625,82.00144,15.64463,-8.00212,-0.9984165,-6.844331,100.0406
2.329166,83.65918,15.64406,-7.969762,-0.9838012,-6.77384,100.006
2.395833,85.29468,15.64352,-7.936404,-0.9692618,-6.702808,99.99918
2.4625,86.91082,15.64192,-7.900225,-0.9546434,-6.630014,99.97022
2.529167,88.50762,15.64112,-7.866165,-0.9405231,-6.559478,100.0325
2.595833,90.08356,15.63982,-7.827729,-0.9261329,-6.485902,100.0012
2.6625,91.63593,15.63923,-7.787218,-0.9117619,-6.411246,100.0269
2.729167,93.15924,15.6382,-7.749308,-0.8979453,-6.339314,100.0128
2.795834,94.66743,15.63681,-7.708034,-0.8839966,-6.265284,100.0042
2.8625,96.14234,15.636,-7.667897,-0.870437,-6.192854,100.0177
2.929166,97.60292,15.63472,-7.629111,-0.8572816,-6.122168,99.9972
2.995834,99.03532,15.63356,-7.585095,-0.8439124,-6.047854,100.0112
3.0625,100.4415,15.63192,-7.541148,-0.8309022,-5.974179,100.0126
3.129166,101.83,15.63058,-7.500679,-0.818518,-5.904038,100.01
3.195834,103.1976,15.62946,-7.45448,-0.8056634,-5.829691,100.0261
3.2625,104.544,15.62848,-7.410968,-0.7933064,-5.758096,99.99735
3.329167,105.8756,15.62721,-7.361939,-0.7805286,-5.682598,100.0073
3.395833,107.1864,15.62535,-7.317496,-0.7684294,-5.611278,100.0046
3.4625,108.4884,15.62359,-7.271753,-0.7563416,-5.539316,99.97332
3.529167,109.7743,15.6225,-7.226432,-0.7444434,-5.46806,100.0289
3.595833,111.0508,15.62042,-7.178455,-0.7323938,-5.395012,99.9767
3.6625,112.3202,15.61922,-7.130955,-0.7205128,-5.322594,99.98288
3.729167,113.5709,15.61739,-7.085356,-0.7089694,-5.252039,99.98156
3.795833,114.8205,15.61572,-7.038125,-0.6973689,-5.180454,100.0123
3.8625,116.0676,15.61411,-6.99131,-0.685905,-5.109346,99.97462
3.929166,117.3084,15.61385,-6.941938,-0.6742919,-5.036244,99.94776
3.995834,118.5516,15.61242,-6.893168,-0.6629269,-4.963756,100.0612
4.0625,119.7866,15.60992,-6.856368,-0.6529389,-4.901085,99.95901
4.129166,121.0284,15.60811,-6.821048,-0.6431586,-4.839609,100.0287
4.195833,122.2716,15.6055,-6.790444,-0.6339352,-4.78197,100.0118
4.2625,123.5177,15.60401,-6.762674,-0.6250597,-4.726622,99.95099
4.329167,124.7635,15.60244,-6.734959,-0.6162202,-4.671244,99.97382
4.395834,126.0224,15.59974,-6.707322,-0.6074132,-4.61582,100.016
4.4625,127.284,15.59846,-6.678234,-0.5984688,-4.559074,99.98982
4.529167,128.5578,15.59646,-6.65504,-0.5901775,-4.507012,100.03
4.595833,129.8284,15.5949,-6.634284,-0.5821632,-4.456803,100.0029
4.6625,131.1169,15.59282,-6.612295,-0.5740205,-4.405375,100.0339
4.729166,132.405,15.59083,-6.589135,-0.5657642,-4.35282,99.99884
4.795833,133.7091,15.58879,-6.56917,-0.5578622,-4.302726,100.0063
4.8625,135.0168,15.58714,-6.54879,-0.5499234,-4.252105,100.0021
4.929167,136.3364,15.58505,-6.5309,-0.5422804,-4.203274,100.04
4.995834,137.662,15.5831,-6.509093,-0.5343181,-4.151122,100.0077
5.0625,139.0006,15.58074,-6.492217,-0.5268844,-4.102794,100.0103
5.129166,140.3445,15.57933,-6.474682,-0.5193932,-4.053787,99.98812
5.195833,141.6937,15.57695,-6.45827,-0.5120282,-4.00554,100.0093
5.2625,143.0525,15.57496,-6.443182,-0.504813,-3.958234,99.96793
5.329168,144.4238,15.57293,-6.426352,-0.4974244,-3.90935,99.95453
5.395834,145.795,15.5711,-6.409834,-0.490072,-3.860528,99.99341
5.4625,147.1791,15.56921,-6.392168,-0.4826268,-3.810718,99.99915
5.529168,148.5591,15.56676,-6.376446,-0.475398,-3.762376,100.0082
5.595832,149.9505,15.56526,-6.359566,-0.4680824,-3.713082,100.0139
5.6625,151.3448,15.56296,-6.344475,-0.4609712,-3.665165,100.0406
5.729166,152.7378,15.56062,-6.330093,-0.4539632,-3.61781,99.99168
5.795832,154.1427,15.55842,-6.316992,-0.4471086,-3.571436,100.036
5.8625,155.5489,15.55647,-6.300182,-0.4399234,-3.522047,99.9725
5.929168,156.9474,15.5543,-6.28668,-0.4331742,-3.475433,99.99199
5.995834,158.3498,15.5514,-6.271256,-0.4262778,-3.427302,99.99409
6.0625,159.7503,15.54918,-6.256463,-0.4194912,-3.379801,99.95955
6.129166,161.1567,15.54708,-6.243101,-0.4128842,-3.333511,99.97442
6.195832,162.5519,15.54475,-6.228512,-0.406191,-3.286289,100.0206
6.2625,163.9504,15.54222,-6.212382,-0.3993842,-3.237904,99.99776
6.329168,165.3459,15.54001,-6.199171,-0.3929313,-3.192126,100.0184
6.395834,166.7355,15.53729,-6.18728,-0.3866399,-3.147439,99.97246
6.4625,168.1209,15.5351,-6.172534,-0.3801159,-3.100615,99.99828
6.529166,169.5075,15.53286,-6.159374,-0.373804,-3.055276,99.95569
6.595834,170.8907,15.52978,-6.142428,-0.3671528,-3.006935,99.98884
6.6625,172.2634,15.52744,-6.127949,-0.3608053,-2.960829,99.95836
6.729166,173.6336,15.52512,-6.11078,-0.3542315,-2.91264,100.0103
6.795832,174.998,15.52226,-6.094765,-0.3478279,-2.865581,99.97194
6.8625,176.3625,15.52027,-6.080795,-0.3417114,-2.82037,100.0289
6.929168,177.7152,15.51783,-6.066448,-0.3356205,-2.77501,99.99952
6.995834,179.0712,15.51507,-6.04862,-0.3292285,-2.726958,99.97301
7.0625,180.4178,15.51253,-6.032172,-0.3230139,-2.680173,99.9909
7.129166,181.7631,15.50911,-6.018354,-0.3170996,-2.635682,99.98759
7.195832,183.1046,15.5074,-6.00058,-0.3108378,-2.588106,100.0049
7.2625,184.4442,15.5044,-5.981826,-0.3045178,-2.539852,99.96036
7.329168,185.7744,15.50193,-5.969034,-0.2988213,-2.496605,100.0343
7.395834,187.1085,15.49939,-5.952582,-0.2928027,-2.450484,99.99469
7.4625,188.4403,15.49707,-5.93005,-0.2862287,-2.399525,100.024
7.529166,189.7618,15.49461,-5.914278,-0.2803459,-2.35417,100.076
7.595834,191.0883,15.49191,-5.897982,-0.2744482,-2.308508,99.98639
7.6625,192.4137,15.48884,-5.879041,-0.2683166,-2.26071,99.97716
7.729166,193.732,15.48632,-5.861931,-0.2623956,-2.214504,99.94424
7.795832,195.0547,15.48342,-5.847521,-0.2567589,-2.170529,99.9947
7.8625,196.3754,15.48126,-5.82818,-0.2506859,-2.122557,99.97791
7.929168,197.6982,15.47831,-5.810369,-0.244807,-2.07593,99.97164
7.995834,199.0194,15.4758,-5.794498,-0.2391319,-2.030881,99.9932
8.0625,200.3425,15.47293,-5.77959,-0.2330912,-1.982577,100.0346
8.129166,201.6696,15.47005,-5.781729,-0.2268396,-1.932317,99.99419
8.195832,202.99,15.4683,-5.785894,-0.2210098,-1.885496,99.98634
8.2625,204.3171,15.46551,-5.783787,-0.214684,-1.834286,99.92111
8.329166,205.6459,15.46299,-5.78232,-0.2085198,-1.784301,100.0187
8.395832,206.9739,15.45981,-5.779757,-0.2023656,-1.734238,99.99813
8.4625,208.3079,15.45765,-5.77712,-0.1962931,-1.684725,100.0071
8.529166,209.6427,15.45504,-5.770295,-0.1899393,-1.632637,99.99722
8.595834,210.9785,15.45225,-5.761452,-0.1835032,-1.579679,100.018
8.6625,212.3154,15.44967,-5.750828,-0.1770102,-1.526065,99.97469
8.729168,213.6545,15.44672,-5.73962,-0.1705638,-1.472688,99.96278
8.795834,214.9978,15.44448,-5.726946,-0.1640838,-1.418854,99.97272
8.8625,216.3382,15.44154,-5.711972,-0.157507,-1.363994,100.0066
8.929168,217.6806,15.43934,-5.693009,-0.1506912,-1.30679,99.97944
8.995834,219.0328,15.4364,-5.675551,-0.1440908,-1.251273,100.0249
9.0625,220.3756,15.43368,-5.653787,-0.1372281,-1.193318,99.98049
9.129166,221.7242,15.43118,-5.63052,-0.1303331,-1.134915,100.0204
9.195832,223.0746,15.42856,-5.603,-0.1231606,-1.073931,99.99791
9.2625,224.4228,15.42546,-5.572637,-0.1158496,-1.011565,100.0009
9.329166,225.7764,15.42283,-5.539368,-0.1083894,-0.9477188,100.0011
9.395832,227.1291,15.42009,-5.503163,-0.1007815,-0.8824014,100.0189
9.4625,228.4804,15.41753,-5.461015,-0.09276793,-0.813346,99.97342
9.529166,229.8342,15.41481,-5.419353,-0.0849048,-0.74542,100.0374
9.595834,231.1844,15.41206,-5.374905,-0.07691079,-0.676154,99.9879
9.6625,232.5366,15.40899,-5.324444,-0.06851578,-0.603166,100.0104
9.729168,233.8928,15.40653,-5.272711,-0.06011272,-0.5299086,100.0246
9.795834,235.2448,15.40431,-5.221594,-0.05187459,-0.4579042,99.98369
9.8625,236.5957,15.40078,-5.162802,-0.04310594,-0.3810128,100.0039
9.929168,237.9452,15.39844,-5.104574,-0.03448987,-0.3052484,99.98413
9.995834,239.2948,15.39524,-5.042838,-0.02568822,-0.2276294,100.0022
10.0625,240.6445,15.39248,-4.979281,-0.01683964,-0.1494004,99.95703
10.12917,241.9922,15.38971,-4.917702,-8.26E-03,-0.07337368,99.99574
10.19583,243.3435,15.38657,-4.85478,3.34E-04,0.002982235,100.0034
10.2625,244.692,15.38362,-4.785774,0.009326407,0.08306915,99.98876
10.32917,246.043,15.38042,-4.722168,0.01778368,0.1585807,100.0773
10.39583,247.387,15.37789,-4.657142,0.02625894,0.2344376,100.0018
10.4625,248.7295,15.37447,-4.594492,0.03444207,0.3078665,100.0148
10.52916,250.0736,15.37157,-4.530683,0.04263205,0.3815369,99.97559
10.59584,251.4198,15.36859,-4.463953,0.05097269,0.4567354,99.97208
10.6625,252.7632,15.36511,-4.404772,0.05861992,0.5258934,100.0105
10.72917,254.0993,15.362,-4.351202,0.0657309,0.5904008,100.012
10.79584,255.4394,15.35896,-4.300956,0.07250074,0.6519941,99.99903
10.8625,256.7753,15.35556,-4.255482,0.07881578,0.7096388,100.0118
10.92917,258.1124,15.3526,-4.209789,0.08508137,0.7669662,99.99336
10.99584,259.4478,15.34931,-4.168267,0.09095186,0.8208124,99.99848
11.0625,260.786,15.34507,-4.128848,0.09659559,0.8727132,99.98906
11.12916,262.1251,15.33327,-4.083318,0.1026595,0.9285324,100.0338
11.19583,263.4572,15.32781,-4.027102,0.1094942,0.9914504,99.97734
11.2625,264.7947,15.32497,-3.988758,0.114867,1.04125,99.99019
11.32916,266.1252,15.32099,-3.958153,0.1195796,1.085166,99.95586
11.39583,267.4485,15.31785,-3.947696,0.1226722,1.114456,100.0072
11.4625,268.7849,15.31351,-3.945498,0.1250894,1.137667,100.0423
11.52916,270.1154,15.31057,-3.952063,0.1267892,1.154394,99.99571
11.59584,271.4406,15.3073,-3.96852,0.1276913,1.163884,100.0092
11.6625,272.7712,15.3034,-3.990122,0.1281688,1.169516,99.9912
11.72917,274.099,15.29995,-4.017372,0.1281857,1.170951,100.0023
11.79584,275.4238,15.2961,-4.050972,0.1276905,1.167703,99.97001
11.8625,276.7534,15.29283,-4.086502,0.1270287,1.162921,99.98749
11.92917,278.0795,15.28892,-4.127659,0.1259151,1.153984,100.0119
11.99584,279.4066,15.28491,-4.170554,0.1246518,1.14363,100.0442
12.0625,280.7368,15.28092,-4.21423,0.123321,1.132573,100.0313
12.12916,282.0602,15.27731,-4.25939,0.1218585,1.120272,99.96371
12.19583,283.3926,15.2733,-4.309574,0.1200023,1.104322,99.97621
12.2625,284.7188,15.26911,-4.363294,0.1178657,1.085757,99.98766
12.32916,286.0463,15.26478,-4.415256,0.1158446,1.068216,99.98159
12.39583,287.3738,15.26079,-4.463326,0.1140981,1.053172,99.93895
12.4625,288.7038,15.25666,-4.518916,0.1117757,1.032774,100.0167
12.52916,290.0314,15.2529,-4.572269,0.1096057,1.013745,99.97241
12.59584,291.36,15.24831,-4.624008,0.1075433,0.9956722,99.9565
12.6625,292.6896,15.24373,-4.674444,0.1055626,0.9783188,100.0246
12.72917,294.0175,15.23939,-4.721387,0.1038249,0.963183,99.9923
12.79584,295.3491,15.23457,-4.7713,0.101855,0.9458589,99.98219
12.8625,296.6832,15.23025,-4.82551,0.09955591,0.9254403,99.99968
12.92917,298.0117,15.22555,-4.878171,0.09735418,0.9058843,100.0165
12.99583,299.3389,15.22089,-4.922162,0.09577616,0.8920978,100.037
13.0625,300.6672,15.21621,-4.96577,0.09421406,0.8784036,100.0026
13.12917,302.0002,15.21099,-5.010918,0.09252785,0.8634931,100.0374
13.19583,303.3303,15.20614,-5.057354,0.09073478,0.8475566,100.0207
13.2625,304.6568,15.20097,-5.094832,0.08957756,0.8375326,100.0066
13.32916,305.9902,15.19612,-5.131836,0.08844008,0.827673,100.0542
13.39583,307.3192,15.19019,-5.173874,0.08692278,0.8142376,99.99632
13.4625,308.6525,15.18536,-5.210881,0.08575756,0.8040772,100.007
13.52916,309.9826,15.17977,-5.24832,0.08454609,0.7934624,99.99836
13.59584,311.3133,15.17417,-5.286155,0.08329218,0.7824287,99.98218
13.6625,312.642,15.16826,-5.323272,0.0820739,0.7717072,99.99634
13.72917,313.972,15.16263,-5.358194,0.08100196,0.7623428,99.98984
13.79584,315.2984,15.15677,-5.391474,0.0800345,0.753944,99.98058
13.8625,316.6356,15.15096,-5.424426,0.07908066,0.745658,99.99032
13.92917,317.9628,15.14417,-5.455946,0.07821679,0.7382058,99.98384
13.99583,319.2952,15.13781,-5.485316,0.07749278,0.7320587,100.0608
14.0625,320.6266,15.13094,-5.515426,0.0767046,0.7252876,99.96965
14.12917,321.9559,15.12439,-5.548056,0.07573014,0.7167092,100.0236
14.19583,323.2854,15.11802,-5.575618,0.07510464,0.7114101,99.9962
14.2625,324.6102,15.11069,-5.598032,0.07483181,0.7094444,100.0233
14.32916,325.9462,15.10369,-5.621564,0.07447095,0.7066391,99.98329
14.39583,327.2762,15.0959,-5.648307,0.07387195,0.7015682,100.0154
14.4625,328.6053,15.08918,-5.670754,0.0735665,0.6992776,99.93253
14.52916,329.9372,15.0816,-5.691708,0.07335715,0.697898,99.94826
14.59584,331.2661,15.07416,-5.712666,0.07313788,0.6964201,100.0137
14.6625,332.5981,15.06638,-5.732964,0.07295447,0.6952813,99.99784
14.72917,333.9278,15.05823,-5.752241,0.07283474,0.6947476,100.0137
14.79584,335.2563,15.04995,-5.763504,0.07326889,0.6995009,99.9832
14.8625,336.5843,15.04184,-5.7735,0.0737822,0.705018,100.006
14.92917,337.9148,15.03404,-5.786658,0.07406508,0.7083403,99.99372
14.99583,339.2422,15.02554,-5.796462,0.07457466,0.713839,99.97249
15.0625,340.5763,15.01679,-5.801448,0.07541374,0.722503,99.98191
15.12917,341.907,15.00778,-5.808403,0.07610888,0.7297825,100.0209
15.19583,343.2326,14.99927,-5.815356,0.07679594,0.7369821,99.97631
15.2625,344.5644,14.99026,-5.818608,0.07773507,0.7466153,100.0095
15.32916,345.889,14.981,-5.819259,0.07884537,0.7579087,99.99848
15.39583,347.2164,14.97194,-5.826752,0.07947576,0.7646042,99.97225
15.4625,348.5476,14.9625,-5.828709,0.0804843,0.7749518,100.0141
15.52916,349.8762,14.95256,-5.831425,0.08143579,0.7847674,100.0323
15.59584,351.2047,14.94279,-5.830943,0.08260187,0.7966687,100.0004
15.6625,352.5335,14.93292,-5.829007,0.08386345,0.8095118,100.0593
15.72917,353.8625,14.92274,-5.827374,0.08510009,0.822135,100.0098
15.79584,355.1905,14.91234,-5.825396,0.08635584,0.834965,100.0195
15.8625,356.5179,14.90194,-5.82121,0.08775855,0.849237,99.9629
15.92917,357.845,14.89142,-5.821401,0.08885734,0.860589,99.98762
15.99583,359.1748,14.88004,-5.82215,0.08991719,0.8715844,100.0328
16.0625,360.4998,14.86901,-5.824982,0.09083238,0.881192,100.0014
16.12917,361.8297,14.85752,-5.828136,0.091728,0.890603,99.98756
16.19583,363.1576,14.84594,-5.831791,0.09259147,0.8996996,100.0034
16.2625,364.4833,14.83425,-5.83728,0.09333007,0.9075972,99.98712
16.32916,365.8139,14.82224,-5.843693,0.09400714,0.9149078,99.97816
16.39584,367.1433,14.8102,-5.852182,0.09454572,0.9208819,100.0158
16.4625,368.4726,14.7974,-5.865402,0.09476749,0.9237781,99.99389
16.52917,369.799,14.78735,-5.88421,0.09461506,0.9230276,100.004
16.59583,371.1296,14.76929,-5.915262,0.09364314,0.9142749,99.98101
16.6625,372.4559,14.73701,-5.960568,0.09171894,0.8962019,99.99024
16.72916,373.779,14.71738,-6.030218,0.08816918,0.8622003,99.9961
16.79584,375.1044,14.69908,-6.127648,0.08277528,0.8100988,99.95224
16.8625,376.4366,14.681,-6.223139,0.07753898,0.7594592,99.98047
16.92917,377.7625,14.66326,-6.316365,0.07247702,0.7104465,100.0022
16.99583,379.0887,14.64553,-6.409193,0.0674666,0.6618608,100.0679
17.0625,380.42,14.62703,-6.506455,0.06218964,0.6105771,100.0481
17.12917,381.7459,14.60826,-6.602759,0.05700324,0.5600864,99.97609
17.19583,383.074,14.5893,-6.706874,0.05132732,0.5046998,99.9935
17.2625,384.4037,14.5694,-6.814265,0.0454649,0.4473946,99.9592
17.32916,385.7304,14.54948,-6.922774,0.03955881,0.3895713,100.0236
17.39584,387.0618,14.52836,-7.041398,0.03302014,0.3254251,100.0238
17.4625,388.392,14.50714,-7.159624,0.02654328,0.2617916,100.0156
17.52917,389.72,14.48546,-7.285361,0.01960855,0.1935406,100.0186
17.59583,391.0511,14.4625,-7.412756,0.01260563,0.1245127,99.98086
17.6625,392.3774,14.43956,-7.54673,0.005210152,0.05149805,99.99164
17.72916,393.7082,14.41548,-7.682187,-2.24E-03,-0.02214247,99.99579
17.79584,395.0413,14.39108,-7.810189,-9.15E-03,-0.09062278,99.94796
17.8625,396.3705,14.36554,-7.937313,-0.01596953,-0.1582363,99.98141
17.92917,397.7016,14.33896,-8.062079,-0.0225877,-0.2239814,99.98976
17.99583,399.0369,14.31288,-8.182595,-0.02888435,-0.286635,99.96803
18.0625,400.3712,14.28591,-8.294324,-0.03456989,-0.343309,99.98622
18.12917,401.7029,14.25852,-8.399436,-0.03979002,-0.3954356,100.0015
18.19583,403.041,14.23063,-8.490671,-0.0440739,-0.4383275,100.0183
18.2625,404.3796,14.20182,-8.570139,-0.04756462,-0.4733878,100.0006
18.32916,405.7168,14.17182,-8.639738,-0.05039239,-0.5018974,100.0105
18.39584,407.0588,14.14086,-8.701031,-0.0526575,-0.5248383,100.0049
18.4625,408.397,14.10971,-8.743696,-0.05371194,-0.5357384,99.98494
18.52917,409.74,14.0782,-8.76983,-0.0536922,-0.5359307,100.0137
18.59583,411.0834,14.04729,-8.775734,-0.05237292,-0.5231434,100.0431
18.6625,412.4273,14.01625,-8.758241,-0.04956686,-0.4954731,100.0439
18.72916,413.7717,13.98675,-8.725351,-0.04578689,-0.4580228,99.98289
18.79584,415.1198,13.95762,-8.666266,-0.04036181,-0.4040456,99.97984
18.8625,416.4652,13.92908,-8.599918,-0.03449725,-0.3455898,100.0083
18.92917,417.8165,13.90118,-8.510957,-0.02723043,-0.2729878,99.99813
18.99583,419.1648,13.87437,-8.409819,-0.01923184,-0.1929386,100.0104
19.0625,420.5179,13.8471,-8.311781,-0.0114533,-0.1149789,99.96038
19.12917,421.8711,13.82124,-8.173012,-1.17E-03,-0.0117878,100.0072
19.19583,423.2269,13.79574,-8.026616,0.009534702,0.09587216,100.0069
19.2625,424.5758,13.77074,-7.882743,0.02003456,0.201578,100.0179
19.32916,425.9314,13.74566,-7.74806,0.02992477,0.301299,100.0115
19.39584,427.2881,13.72208,-7.58782,0.04134146,0.4165388,99.96504
19.4625,428.6385,13.69839,-7.4242,0.05290546,0.5334262,100.0446
19.52917,429.9896,13.67498,-7.258638,0.06453256,0.6511123,100.0113
19.59583,431.3414,13.65221,-7.109314,0.07511282,0.7583955,100.0016
19.6625,432.6965,13.62923,-6.945916,0.08649861,0.8739668,100.0085
19.72916,434.045,13.60649,-6.800966,0.09670486,0.9777722,100.0456
19.79584,435.3992,13.58423,-6.639464,0.1078626,1.09135,100.0416
19.8625,436.7436,13.56308,-6.484874,0.1185392,1.200212,99.98446
19.92917,438.1002,13.54193,-6.356142,0.1276166,1.293009,99.998
19.99583,439.4432,13.52119,-6.232902,0.1363113,1.38203,99.98986
20.0625,440.7925,13.50014,-6.119744,0.1443628,1.464638,99.97202
20.12917,442.1376,13.47874,-6.00897,0.1522288,1.545474,99.96099
20.19583,443.4838,13.45729,-5.909726,0.1593698,1.619047,100.0114
20.2625,444.8282,13.43561,-5.82351,0.1657013,1.684488,100.0151
20.32916,446.1674,13.41276,-5.740925,0.1717827,1.747466,99.98901
20.39584,447.5078,13.3884,-5.675552,0.1768198,1.799896,99.96853
20.4625,448.8478,13.36417,-5.611364,0.1817619,1.851424,100.0018
20.52917,450.1874,13.3398,-5.558499,0.1860163,1.896008,100.0021
20.59583,451.5272,13.31561,-5.513287,0.1898029,1.935877,100.0325
20.6625,452.8648,13.28851,-5.488981,0.1923544,1.963189,100.0358
20.72916,454.2083,13.2625,-5.438895,0.1963909,2.005706,99.96508
20.79584,455.5444,13.23648,-5.385418,0.2005988,2.050022,100.0443
20.8625,456.8829,13.211,-5.341941,0.2042099,2.088287,100.0306
20.92917,458.218,13.17957,-5.318042,0.2066798,2.114892,100.0041
20.99583,459.5508,13.13948,-5.328411,0.2071752,2.121302,100.0153
21.0625,460.8877,13.10553,-5.33935,0.2076404,2.127408,100.0427
21.12917,462.2243,13.0721,-5.349674,0.2081412,2.133886,100.0068
21.19583,463.5612,13.04036,-5.360711,0.2086018,2.139956,99.98847
21.2625,464.8939,13.00772,-5.37054,0.2091282,2.146708,99.96709
21.32916,466.23,12.97446,-5.363203,0.210624,2.163424,100.0316
21.39584,467.5672,12.94199,-5.349484,0.2124734,2.183792,99.97518
21.4625,468.8996,12.88877,-5.34542,0.2137712,2.19851,99.99009
21.52917,470.2296,12.8274,-5.392802,0.2121877,2.183588,100.0192
21.59583,471.5608,12.78225,-5.445507,0.2103203,2.165722,99.9863
21.6625,472.8978,12.74136,-5.486424,0.2091258,2.154768,100.006
21.72916,474.2317,12.70206,-5.515151,0.2086145,2.150845,99.97626
21.79584,475.5688,12.66344,-5.532018,0.2087659,2.15375,100.0457
21.8625,476.9016,12.62622,-5.542281,0.2092804,2.1604,99.97478
21.92917,478.2368,12.58986,-5.541645,0.2103942,2.173238,100.031
21.99583,479.5762,12.5535,-5.539334,0.2115989,2.18703,99.97009
22.0625,480.9087,12.51704,-5.52871,0.2132478,2.20543,99.9962
22.12917,482.2452,12.48199,-5.529886,0.2142502,2.217158,99.98843
22.19583,483.5778,12.44617,-5.533239,0.2151289,2.227618,99.99319
22.2625,484.9112,12.40323,-5.547629,0.2154095,2.23189,99.98121
22.32916,486.2466,12.34338,-5.619829,0.2125788,2.203909,99.99366
22.39584,487.578,12.29697,-5.669465,0.2109767,2.188638,99.97595
22.4625,488.914,12.25553,-5.702771,0.2102635,2.182572,99.97297
22.52917,490.2438,12.21601,-5.715213,0.2106674,2.1881,100.0041
22.59583,491.5792,12.17744,-5.717072,0.211638,2.199523,100.0318
22.6625,492.914,12.13954,-5.715366,0.212794,2.212886,100.0046
22.72916,494.2502,12.10211,-5.708503,0.214219,2.229062,99.99413
22.79584,495.585,12.06518,-5.704463,0.2154886,2.243638,99.99601
22.8625,496.9207,12.02775,-5.696,0.2169871,2.260604,99.99852
22.92917,498.2544,11.98057,-5.697839,0.2179387,2.271883,100.013
22.99583,499.585,11.9092,-5.726895,0.2174627,2.268279,99.99547
23.0625,500.918,11.86016,-5.784291,0.2155173,2.249332,100.0056
23.12917,502.2488,11.81887,-5.844776,0.2134241,2.228816,100.0061
23.19583,503.579,11.7795,-5.899757,0.2116306,2.211406,100.0038
23.2625,504.9136,11.74171,-5.944628,0.2103746,2.199596,100.0086
23.32916,506.247,11.70529,-5.976375,0.2098037,2.194935,99.99276
23.39584,507.5809,11.66951,-6.002695,0.2095177,2.193254,100.0449
23.4625,508.9139,11.63396,-6.02648,0.2093644,2.192954,99.99532
23.52917,510.2487,11.5989,-6.0465,0.2094073,2.194708,99.96925
23.59583,511.5848,11.56452,-6.059344,0.2098184,2.200327,99.99098
23.6625,512.9197,11.53044,-6.072802,0.210198,2.205619,100.0124
23.72916,514.2526,11.49647,-6.082334,0.2107739,2.212976,100.0287
23.79584,515.5896,11.46312,-6.088535,0.211519,2.222112,100.0512
23.8625,516.9239,11.42899,-6.096916,0.2121532,2.230074,99.99736
23.92917,518.261,11.3965,-6.104087,0.2128478,2.238676,99.99901
23.99583,519.5965,11.36391,-6.115002,0.213352,2.24528,99.99871
24.0625,520.9296,11.33163,-6.119863,0.2141554,2.25504,99.99899
24.12917,522.2657,11.29957,-6.131474,0.2146217,2.261258,100.0032
24.19583,523.602,11.26802,-6.139541,0.2152625,2.26932,99.98475
24.2625,524.9358,11.23669,-6.152068,0.2156795,2.275029,100.0288
24.32916,526.2703,11.20554,-6.160515,0.2162968,2.282857,99.97222
24.39584,527.6037,11.17486,-6.172085,0.2167578,2.289039,100.0525
24.4625,528.939,11.1447,-6.187734,0.2170187,2.293115,99.97082
24.52917,530.2789,11.13487,-6.200135,0.2174407,2.298898,99.97828
24.59583,531.6172,10.47846,-6.20548,0.218205,2.308308,99.97831
24.6625,532.9518,10.20019,-6.277511,0.2157254,2.28339,100.0048
24.72916,534.2895,10.17292,-6.353461,0.213072,2.2566,100.0001
24.79584,535.6234,10.14644,-6.416193,0.211071,2.236685,99.98895
24.8625,536.961,10.11997,-6.469943,0.2095177,2.221486,100.0512
24.92917,538.2906,10.09438,-6.517816,0.2082512,2.209305,100.0425
24.99583,539.6234,10.06856,-6.56695,0.2069338,2.196568,99.99366
25.0625,540.958,10.04398,-6.612993,0.2057729,2.18548,99.99731
25.12917,542.2875,10.01909,-6.655884,0.2047661,2.176012,99.98178
25.19583,543.6156,9.994906,-6.703574,0.2035366,2.164162,100.0106
25.2625,544.9485,9.971191,-6.75478,0.2021507,2.150633,100.0144
25.32916,546.2766,9.947766,-6.806206,0.2007598,2.137036,100.0248
25.39584,547.6074,9.924951,-6.856955,0.19941,2.123856,100.0028
25.4625,548.9384,9.905945,-6.90622,0.1981381,2.111494,100.0478
25.52917,550.265,9.888116,-6.948695,0.1971882,2.102546,100.0154
25.59583,551.5946,9.866205,-6.993855,0.1961203,2.092329,100.0352
25.6625,552.9248,9.844629,-7.037414,0.1951329,2.082956,99.98072
25.72916,554.2524,9.823478,-7.086969,0.1938713,2.070644,99.97728
25.79584,555.5824,9.802676,-7.142982,0.1923196,2.055205,99.98322
25.8625,556.9089,9.782697,-7.198844,0.190783,2.039896,100.0054
25.92916,558.2428,9.762955,-7.25626,0.1891874,2.023937,99.98018
25.99583,559.569,9.743609,-7.31655,0.1874643,2.006596,100.0074
26.0625,560.8995,9.72461,-7.383359,0.1854541,1.986158,100.0068
26.12917,562.2292,9.705688,-7.454851,0.1832405,1.963517,99.99336
26.19584,563.5602,9.687993,-7.528911,0.1809225,1.939731,100.0358
26.2625,564.8896,9.669663,-7.610236,0.178286,1.912501,99.96625
26.32916,566.2194,9.652266,-7.695995,0.1754636,1.883246,100.0219
26.39584,567.5518,9.635285,-7.784194,0.1725469,1.852944,100.0112
26.4625,568.8795,9.61875,-7.868707,0.1698088,1.824528,100.0228
26.52917,570.209,9.602516,-7.959278,0.1668144,1.793324,100.034
26.59583,571.537,9.586079,-8.057862,0.1634754,1.758376,99.99199
26.6625,572.8663,9.570716,-8.158776,0.1600512,1.722474,99.98598
26.72916,574.2019,9.555486,-8.262424,0.1565272,1.685458,100.0017
26.79584,575.5271,9.540207,-8.370151,0.1528347,1.646581,100.0124
26.8625,576.8574,9.525728,-8.489694,0.1486418,1.602259,100.0326
26.92916,578.1829,9.511369,-8.619034,0.1440353,1.55343,99.98887
26.99583,579.5128,9.497782,-8.748134,0.1394663,1.504952,99.98258
27.0625,580.8418,9.484241,-8.873003,0.1351066,1.458681,99.99516
27.12917,582.168,9.471099,-9.001376,0.1306145,1.41093,99.99926
27.19584,583.497,9.458035,-9.133441,0.1259867,1.36166,100.0258
27.2625,584.8216,9.445262,-9.272625,0.12107,1.309213,99.9945
27.32916,586.1524,9.4327,-9.413655,0.116103,1.256166,100.0173
27.39584,587.48,9.420749,-9.559747,0.1109409,1.200949,100.0182
27.4625,588.8079,9.409001,-9.709519,0.1056472,1.144248,99.95738
27.52917,590.1349,9.397749,-9.857906,0.10044,1.088424,100.0235
27.59583,591.4613,9.386222,-10.00032,0.09551612,1.035612,99.89032
27.6625,592.791,9.375174,-10.14602,0.09047939,0.9815181,99.99384
27.72916,594.1156,9.364441,-10.30023,0.08510225,0.9236724,99.99347
27.79584,595.4408,9.35428,-10.46116,0.0794678,0.8629634,99.98268
27.8625,596.7696,9.343674,-10.62044,0.07393613,0.8032965,99.99488
27.92916,598.0966,9.333469,-10.78656,0.06814328,0.7407299,100.0072
27.99583,599.4208,9.32402,-10.95287,0.06236972,0.6783099,100.0276
28.0625,600.7508,9.314241,-11.12167,0.05652588,0.6150614,99.96059
28.12917,602.0758,9.305113,-11.30476,0.05010817,0.545502,99.99822
28.19584,603.398,9.295524,-11.48911,0.04366941,0.4756438,99.99391
28.2625,604.7262,9.286556,-11.67203,0.03732817,0.4067777,99.99486
28.32916,606.051,9.277704,-11.85884,0.0308551,0.3364053,100.002
28.39584,607.3824,9.268884,-12.04272,0.02454342,0.2677236,100.012
28.4625,608.705,9.260352,-12.22522,0.01831368,0.1998672,100.0007
28.52917,610.0328,9.251969,-12.40263,0.01233096,0.1346401,99.98637
28.59583,611.3601,9.243995,-12.57853,0.006441116,0.07036289,99.99413
28.6625,612.6847,9.235684,-12.75331,6.25E-04,0.006827712,99.98634
28.72916,614.0126,9.227887,-12.9275,-5.13E-03,-0.05615101,100.0069
28.79584,615.3388,9.219741,-13.10778,-0.01111373,-0.1216054,100.0074
28.8625,616.6664,9.21228,-13.27843,-0.01666689,-0.1824798,99.99381
28.92916,617.9946,9.204718,-13.44238,-0.02191745,-0.2401184,99.98095
28.99583,619.3224,9.19698,-13.60841,-0.02722472,-0.2984526,100.0512
29.0625,620.6508,9.189522,-13.77062,-0.03234897,-0.3548531,100.073
29.12917,621.9788,9.182324,-13.92186,-0.03700533,-0.4061896,99.99256
29.19584,623.3058,9.175048,-14.07247,-0.04161253,-0.4570522,100.022
29.2625,624.6324,9.168006,-14.21748,-0.04597234,-0.5052596,99.99804
29.32916,625.961,9.160491,-14.35721,-0.05009746,-0.5509475,99.98605
29.39584,627.2888,9.154051,-14.4928,-0.05403746,-0.5946555,100.0403
29.4625,628.6195,9.14743,-14.61823,-0.05755161,-0.6337304,99.99296
29.52917,629.9487,9.140166,-14.74046,-0.06092317,-0.6712834,100.0088
29.59583,631.278,9.133682,-14.86088,-0.06420738,-0.7079206,99.99666
29.6625,632.6054,9.127349,-14.97812,-0.06735226,-0.7430668,99.98341
29.72916,633.9384,9.121044,-15.08688,-0.07014468,-0.7743651,99.98701
29.79584,635.2687,9.1155,-15.18318,-0.07244078,-0.8002082,99.98859
29.8625,636.5999,9.109801,-15.27304,-0.07447895,-0.823191,100.0017
29.92916,637.9291,9.103282,-15.36821,-0.07671832,-0.8484168,99.98985
29.99583,639.2581,9.096803,-15.4558,-0.0786552,-0.8703231,99.99951
30.0625,640.5919,9.090712,-15.54251,-0.08054611,-0.8917446,99.99547
30.12917,641.9207,9.084061,-15.62445,-0.08225116,-0.9111309,99.99695
30.19584,643.253,9.078384,-15.70516,-0.08390015,-0.9299159,99.96545
30.2625,644.5807,9.071944,-15.78534,-0.0855284,-0.9484915,100.009
30.32916,645.9106,9.065939,-15.86007,-0.08694055,-0.9646895,100.0162
30.39584,647.245,9.059816,-15.92966,-0.08814845,-0.978637,99.99325
30.4625,648.578,9.053952,-16.0006,-0.08940697,-0.9931626,100.039
30.52917,649.904,9.047638,-16.063,-0.09034564,-1.004148,100.0319
30.59583,651.2373,9.041649,-16.1292,-0.09142009,-1.016655,100.0094
30.6625,652.568,9.033782,-16.20946,-0.09302578,-1.035087,99.98898
30.72916,653.9,9.026171,-16.28201,-0.09433674,-1.050256,100.0205
30.79584,655.2312,9.020074,-16.33609,-0.09495188,-1.057691,99.99816
30.8625,656.561,9.01425,-16.38542,-0.09539238,-1.063188,99.97374
30.92916,657.895,9.007926,-16.44626,-0.09626036,-1.073457,99.98974
30.99583,659.2244,9.001499,-16.50958,-0.09722525,-1.084818,99.98462
31.0625,660.557,8.995853,-16.5812,-0.09849524,-1.099596,100.0598
31.12917,661.8856,8.990132,-16.6482,-0.09959553,-1.112496,99.96246
31.19584,663.221,8.984137,-16.72155,-0.1009236,-1.127953,99.96601
31.2625,664.549,8.977694,-16.80104,-0.102483,-1.146014,99.99384
31.32916,665.8798,8.972356,-16.87692,-0.1039037,-1.162542,99.98032
31.39584,667.2109,8.966231,-16.94965,-0.1052069,-1.177772,99.954
31.4625,668.5399,8.960301,-17.02096,-0.1064586,-1.192441,99.98938
31.52917,669.872,8.954749,-17.09503,-0.1078066,-1.208204,99.97558
31.59583,671.205,8.949246,-17.17198,-0.109257,-1.225134,99.98741
31.6625,672.5337,8.943696,-17.25062,-0.1107706,-1.24279,99.99856
31.72916,673.8644,8.937988,-17.32473,-0.1121168,-1.258584,100.0141
31.79584,675.1938,8.932879,-17.39849,-0.11345,-1.274249,100.0076
31.8625,676.5237,8.927715,-17.48143,-0.1151123,-1.29363,100.0191
31.92916,677.8522,8.922111,-17.56087,-0.1166475,-1.311601,99.98812
31.99583,679.185,8.916687,-17.64379,-0.1183015,-1.330927,100.0198
32.0625,680.515,8.911841,-17.72903,-0.120039,-1.351214,100.0023
32.12916,681.8437,8.906446,-17.81383,-0.1217592,-1.371327,100.0078
32.19584,683.1747,8.901718,-17.89297,-0.1232735,-1.389141,99.98845
32.2625,684.5032,8.896625,-17.97612,-0.1249312,-1.40859,100.0137
32.32916,685.8288,8.891766,-18.05217,-0.1263383,-1.425231,99.99964
32.39583,687.1605,8.887389,-18.1345,-0.127961,-1.444324,100.0003
32.4625,688.4903,8.882476,-18.2236,-0.1298224,-1.466135,100.0008
32.52917,689.8238,8.878201,-18.3133,-0.1316991,-1.488139,99.99164
32.59583,691.152,8.873719,-18.40427,-0.1336226,-1.510696,100.0208
32.6625,692.4825,8.869109,-18.49194,-0.1354259,-1.531916,100.0005
32.72917,693.8106,8.864758,-18.5882,-0.1375296,-1.556559,99.9972
32.79584,695.141,8.860712,-18.6785,-0.1394204,-1.578816,99.95125
32.8625,696.4722,8.85607,-18.76462,-0.1411642,-1.599423,100.0187
32.92916,697.8044,8.851874,-18.85268,-0.142974,-1.620792,100.023
32.99584,699.1366,8.84828,-18.94033,-0.1447681,-1.642003,100.0179
33.0625,700.466,8.844086,-19.02748,-0.1465463,-1.663054,100.0114
33.12916,701.7995,8.84059,-19.12317,-0.1486139,-1.687415,100.0018
33.19584,703.1321,8.836426,-19.22565,-0.1509131,-1.714432,100.0126
33.2625,704.4636,8.83347,-19.32643,-0.1531514,-1.740782,100.0496
33.32916,705.7929,8.829701,-19.42659,-0.1553664,-1.766896,100.0055
33.39583,707.1247,8.826172,-19.52719,-0.1575914,-1.793148,100.0256
33.4625,708.4541,8.822624,-19.63412,-0.1600301,-1.821862,100.002
33.52917,709.7863,8.819219,-19.74218,-0.1624997,-1.850956,100.0218
33.59583,711.1188,8.816008,-19.84148,-0.1646676,-1.876641,100.0097
33.6625,712.4514,8.812942,-19.94332,-0.1669176,-1.903289,99.99484
33.72917,713.7837,8.809976,-20.05488,-0.1694914,-1.933658,99.96304
33.79584,715.1141,8.806746,-20.15881,-0.1718039,-1.961076,99.98321
33.8625,716.4422,8.803944,-20.27559,-0.1745458,-1.993423,99.95499
33.92916,717.7736,8.800868,-20.39006,-0.1772006,-2.024811,100.0068
33.99584,719.103,8.798066,-20.49856,-0.1796508,-2.053889,100.0217
34.0625,720.4337,8.795351,-20.61214,-0.1822636,-2.084856,99.96441
34.12916,721.7657,8.792486,-20.7238,-0.1848052,-2.115041,99.97422
34.19584,723.0922,8.790025,-20.83757,-0.1874144,-2.14603,100.0447
34.2625,724.4261,8.787266,-20.95354,-0.1900842,-2.177744,99.99918
34.32916,725.7525,8.784751,-21.06385,-0.1925652,-2.207325,100.0213
34.39583,727.0844,8.782211,-21.18345,-0.1953422,-2.240332,100.0043
34.4625,728.413,8.779929,-21.29801,-0.1979475,-2.271402,99.97731
34.52917,729.743,8.77742,-21.41728,-0.2006991,-2.304183,99.99211
34.59583,731.0742,8.775262,-21.53482,-0.2033849,-2.336241,99.97648
34.6625,732.4014,8.772874,-21.66442,-0.2064613,-2.37282,100.0308
34.72917,733.7343,8.770679,-21.78574,-0.2092522,-2.406153,99.98781
34.79584,735.0676,8.768114,-21.90978,-0.2121227,-2.440436,100.0361
34.8625,736.3953,8.766465,-22.02635,-0.2147447,-2.471892,100.0332
34.92916,737.721,8.763988,-22.14275,-0.2173542,-2.503235,100.0064
34.99584,739.054,8.762157,-22.26666,-0.2201931,-2.537254,100.0082
35.0625,740.3839,8.760243,-22.39723,-0.2232403,-2.573708,99.9646
35.12916,741.7145,8.757981,-22.51178,-0.2257579,-2.60409,100.0284
35.19584,743.0436,8.755663,-22.63752,-0.228629,-2.638583,100.027
35.2625,744.3765,8.753809,-22.77381,-0.2318263,-2.676877,99.95092
35.32916,745.7045,8.751814,-22.90641,-0.2348973,-2.713748,99.99995
35.39583,747.0308,8.749872,-23.03468,-0.2378188,-2.748926,99.99024
35.4625,748.3651,8.748361,-23.16236,-0.2407036,-2.783716,100.0374
35.52917,749.6918,8.746515,-23.28848,-0.2435332,-2.817905,100.0273
35.59583,751.0192,8.744082,-23.41385,-0.2463264,-2.851703,100.0307
35.6625,752.3484,8.74247,-23.54268,-0.2492174,-2.886667,99.98822
35.72917,753.6775,8.741106,-23.66166,-0.2517828,-2.917895,100.0006
35.79584,755.0056,8.738982,-23.78815,-0.2545765,-2.9518,100.0085
35.8625,756.3375,8.737609,-23.92224,-0.2575952,-2.988348,100.0071
35.92916,757.6671,8.735401,-24.05094,-0.2604336,-3.022828,99.94494
35.99584,758.9956,8.734113,-24.17618,-0.2631512,-3.055936,100.0065
36.0625,760.3247,8.73272,-24.31631,-0.2663242,-3.094366,100.0049
36.12916,761.65,8.731,-24.44872,-0.2692438,-3.129884,100.0286
36.19584,762.9804,8.729138,-24.58085,-0.272136,-3.165123,100.0744
36.2625,764.3125,8.727426,-24.71098,-0.27495,-3.199485,100.0111
36.32916,765.639,8.726293,-24.83762,-0.277646,-3.232508,100.0153
36.39583,766.9694,8.724605,-24.97338,-0.2806096,-3.268676,100.0084
36.4625,768.2978,8.723087,-25.10373,-0.2833914,-3.302763,100.0042
36.52917,769.6275,8.721539,-25.23863,-0.2862984,-3.338344,100.016
36.59583,770.9541,8.7201,-25.37385,-0.2892026,-3.373926,100.0616
36.6625,772.2868,8.718856,-25.51012,-0.2921186,-3.40968,99.99288
36.72917,773.6157,8.717368,-25.64632,-0.2950196,-3.445295,100.0121
36.79584,774.9466,8.716082,-25.78918,-0.2981078,-3.48313,99.97672
36.8625,776.2753,8.71447,-25.92757,-0.3010434,-3.519218,100.0358
36.92916,777.6022,8.712921,-26.06714,-0.3040009,-3.55559,100.0433
36.99584,778.931,8.711757,-26.20771,-0.3069709,-3.59213,100.0208
37.0625,780.2582,8.710406,-26.36122,-0.31032,-3.633144,99.99962
37.12916,781.5874,8.709008,-26.50818,-0.3134483,-3.67161,99.97795
37.19584,782.9138,8.707531,-26.64303,-0.316192,-3.705606,99.96868
37.2625,784.2468,8.706254,-26.78448,-0.3191123,-3.741706,99.98664
37.32916,785.5715,8.70495,-26.92253,-0.3219191,-3.776508,99.99108
37.39583,786.9004,8.703889,-27.05772,-0.3246174,-3.810069,100.0176
37.4625,788.2308,8.702785,-27.20415,-0.3276345,-3.847406,100.0023
37.52917,789.56,8.701447,-27.35651,-0.3308116,-3.88666,99.9877
37.59583,790.8888,8.699764,-27.4988,-0.3336658,-3.922153,99.98722
37.6625,792.2137,8.698829,-27.64698,-0.3366813,-3.959578,99.97855
37.72917,793.543,8.697641,-27.79203,-0.3395776,-3.995632,100.0068
37.79584,794.8718,8.696363,-27.93282,-0.3423269,-4.029993,99.98278
37.8625,796.2012,8.694989,-28.07102,-0.344978,-4.063232,100.0112
37.92916,797.5332,8.694061,-28.21599,-0.3478078,-4.098604,100.0315
37.99584,798.8634,8.692762,-28.35926,-0.3505694,-4.133191,99.98363
38.0625,800.1934,8.69155,-28.50182,-0.3532892,-4.167314,100.0013
38.12916,801.5224,8.690361,-28.64703,-0.3560668,-4.202152,99.95543
38.19584,802.8559,8.688445,-28.79259,-0.3588286,-4.236833,100.0067
38.2625,804.186,8.687781,-28.94035,-0.361637,-4.2721,99.98092
38.32916,805.5155,8.686876,-29.08203,-0.3642462,-4.305044,99.99611
38.39583,806.8444,8.685608,-29.2258,-0.3668967,-4.338506,100.0418
38.4625,808.1754,8.684797,-29.38302,-0.3699155,-4.376358,99.99955
38.52917,809.507,8.683759,-29.53457,-0.3727455,-4.41201,100.0225
38.59583,810.8366,8.682601,-29.6842,-0.3755006,-4.446808,99.99782
38.6625,812.1676,8.681225,-29.83953,-0.3783968,-4.483308,99.96249
38.72917,813.496,8.680382,-29.98739,-3.81E-01,-4.52E+00,100.0238
38.79584,814.8224,8.679212,-30.1324,-3.84E-01,-4.549635,99.99018
38.8625,816.1554,8.678136,-30.27705,-3.86E-01,-4.581776,100.024
38.92916,817.4868,8.676859,-30.42019,-0.3885972,-4.613217,99.98579
38.99584,818.8176,8.675888,-30.56812,-0.3911728,-4.646072,99.97
39.0625,820.1478,8.674576,-30.72588,-0.394008,-4.682041,100.0105
39.12916,821.4784,8.673715,-30.87839,-0.3966712,-4.716,100.039
39.19584,822.8082,8.67257,-31.03062,-0.3993054,-4.749644,100.0145
39.2625,824.135,8.671638,-31.18115,-0.401874,-4.782536,100.0068
39.32916,825.4644,8.670762,-31.34404,-0.4047667,-4.819317,99.98953
39.39583,826.7944,8.669608,-31.502,-0.407497,-4.854196,99.994
39.4625,828.124,8.668538,-31.64856,-0.4098848,-4.885028,99.99311
39.52917,829.4538,8.667388,-31.8019,-0.4124422,-4.917908,99.97742
39.59583,830.782,8.666656,-31.94242,-0.4146216,-4.94631,100.0129
39.6625,832.1139,8.665644,-32.09054,-0.4169882,-4.976974,100.0096
39.72917,833.4428,8.664559,-32.23865,-0.4193384,-5.00747,100.0314
39.79584,834.7728,8.663249,-32.39142,-0.4217957,-5.039273,100.0092
39.8625,836.1032,8.662441,-32.54264,-0.4241886,-5.070334,100.009
39.92916,837.4359,8.661351,-32.68545,-0.4263256,-5.098362,99.99411
39.99584,838.7665,8.660255,-32.83087,-0.4285187,-5.127078,100.0241
40.0625,840.0942,8.65961,-32.97279,-0.430601,-5.154472,100.0264
40.12916,841.4261,8.658478,-33.11494,-0.432665,-5.181674,99.97595
40.19584,842.7541,8.657324,-33.24776,-0.4344601,-5.20568,100.0325
40.2625,844.0856,8.656181,-33.38641,-0.4363914,-5.231338,100.0584
40.32916,845.4152,8.655411,-33.53019,-0.4384465,-5.258504,100.0059
40.39583,846.7432,8.654658,-33.67507,-0.4405146,-5.28585,99.96176
40.4625,848.0764,8.653699,-33.81134,-0.4423233,-5.310105,99.95709
40.52917,849.4039,8.652235,-33.94963,-0.4441768,-5.334919,99.98944
40.59583,850.7328,8.651486,-34.08423,-0.4459112,-5.358325,100.0191
40.6625,852.0678,8.650545,-34.21738,-0.44758,-5.380962,100.0313
40.72917,853.3972,8.649672,-34.34696,-0.4491446,-5.402369,100.0047
40.79584,854.7249,8.648644,-34.47538,-0.4506641,-5.423244,99.99962
40.8625,856.0578,8.647149,-34.59986,-0.4520546,-5.442588,99.98718
40.92916,857.3886,8.646278,-34.72167,-0.4533618,-5.460946,99.97078
40.99584,858.7195,8.645216,-34.85564,-0.4549756,-5.483015,100.0496
41.0625,860.0514,8.644388,-34.97899,-0.4562906,-5.501498,100.0133
41.12916,861.3786,8.643486,-35.09578,-0.4574248,-5.517815,99.99005
41.19584,862.7108,8.64265,-35.20847,-0.458429,-5.532575,99.99887
41.2625,864.0392,8.641705,-35.31078,-0.4591534,-5.543972,100.014
41.32916,865.3686,8.640539,-35.41643,-0.4599516,-5.55627,99.98764
41.39583,866.7001,8.639009,-35.51962,-0.4606701,-5.567611,99.9957
41.4625,868.0334,8.638207,-35.61469,-0.4611626,-5.576232,100.0257
41.52917,869.3611,8.637434,-35.7015,-0.4614382,-5.582234,100.0077
41.59583,870.6924,8.636325,-35.79316,-0.4618244,-5.589575,100.0101
41.6625,872.0219,8.635642,-35.88495,-0.4622062,-5.596868,99.97306
41.72917,873.3539,8.634251,-35.9741,-0.462506,-5.603174,99.99647
41.79584,874.6868,8.633686,-36.0412,-0.4622293,-5.602497,100.046
41.8625,876.0178,8.632749,-36.12389,-0.462347,-5.606604,99.96241
41.92916,877.3495,8.631503,-36.20474,-0.4624084,-5.610024,99.96884
41.99584,878.6819,8.63037,-36.2772,-0.462247,-5.610734,100.0332
42.0625,880.0114,8.629519,-36.34766,-0.462035,-5.61079,100.0129
42.12916,881.3449,8.628426,-36.42962,-0.4621025,-5.614224,99.96425
42.19584,882.6749,8.627532,-36.49262,-0.4616874,-5.611799,99.99251
42.2625,884.0034,8.626506,-36.55981,-0.4613739,-5.610601,100.0377
42.32916,885.3381,8.625766,-36.62663,-0.4610356,-5.609101,100.0469
42.39583,886.6703,8.624764,-36.68213,-0.4604109,-5.604111,99.99132
42.4625,888.0018,8.623703,-36.74153,-0.4598796,-5.600254,100.043
42.52917,889.3314,8.622689,-36.80502,-0.4594474,-5.597598,100.026
42.59583,890.6648,8.62163,-36.87003,-0.4590421,-5.595262,100.004
42.6625,891.9958,8.620801,-36.92354,-0.4583485,-5.589409,100.0021
42.72917,893.3268,8.619728,-36.9818,-0.457768,-5.584928,99.96269
42.79584,894.6576,8.618384,-37.03518,-0.4570623,-5.57891,100.0256
42.8625,895.9906,8.617406,-37.08539,-0.4562708,-5.571839,99.98124
42.92916,897.3212,8.616524,-37.12974,-0.4553346,-5.562993,99.95619
42.99584,898.6519,8.615342,-37.17865,-0.4545063,-5.555457,99.97332
43.0625,899.9894,8.614418,-37.2265,-0.4536367,-5.547425,99.97858
43.12916,901.3142,8.613394,-37.27588,-0.4528183,-5.540022,99.97399
43.19584,902.6496,8.61259,-37.32636,-0.4520074,-5.532693,100.0178
43.2625,903.9811,8.611332,-37.37746,-0.4512131,-5.525566,99.99928
43.32916,905.3176,8.610068,-37.42722,-0.4503742,-5.517884,99.98536
43.39583,906.6453,8.609122,-37.48738,-0.4497947,-5.51337,99.96912
43.4625,907.9775,8.607992,-37.55072,-0.4492797,-5.50964,99.99991
43.52917,909.3118,8.606934,-37.59944,-0.4484058,-5.5015,99.97215
43.59583,910.6437,8.60616,-37.6415,-0.447372,-5.491392,99.96121
43.6625,911.9749,8.604981,-37.7025,-0.4467874,-5.486789,100.0202
43.72917,913.3042,8.603941,-37.77667,-0.4465134,-5.485988,100.0031
43.79584,914.6382,8.602416,-37.8557,-0.4463406,-5.486436,99.99336
43.8625,915.9686,8.601728,-37.92876,-0.4460241,-5.485111,100.0236
43.92916,917.3001,8.60054,-38.00542,-0.4457844,-5.484726,99.98547
43.99584,918.6311,8.599525,-38.0732,-0.445329,-5.481684,100.0407
44.0625,919.9638,8.598141,-38.14736,-0.4450172,-5.48037,100.0095
44.12916,921.2921,8.597168,-38.22643,-0.4448213,-5.480461,100.082
44.19584,922.6228,8.596105,-38.30042,-0.4444958,-5.478955,99.97004
44.2625,923.9532,8.595382,-38.38333,-0.4443714,-5.479921,99.98874
44.32916,925.2866,8.593902,-38.45891,-0.4440648,-5.478641,100.0159
44.39583,926.6181,8.592922,-38.53956,-0.4438703,-5.478744,100.0202
44.4625,927.9485,8.591553,-38.6111,-0.4434594,-5.47617,100.0522
44.52917,929.278,8.590406,-38.68799,-0.4431665,-5.475051,100.0521
44.59583,930.6103,8.589581,-38.78015,-0.4432134,-5.47813,99.96515
44.6625,931.9391,8.588514,-38.86282,-0.4430388,-5.478466,100.0094
44.72917,933.2676,8.58714,-38.93969,-0.4427236,-5.477064,100.0368
44.79584,934.6022,8.585968,-39.02636,-0.4426164,-5.478235,100.0316
44.8625,935.9321,8.584736,-39.11875,-0.442637,-5.480988,99.99699
44.92916,937.2657,8.583368,-39.20506,-0.4425058,-5.48186,99.9963
44.99584,938.5964,8.582406,-39.29087,-0.442359,-5.482538,100.0107
45.0625,939.9301,8.581439,-39.37142,-0.4420802,-5.481582,99.99366
45.12916,941.2578,8.57998,-39.45911,-0.4419634,-5.482628,100.0113
45.19584,942.5886,8.578922,-39.55686,-0.44206,-5.486324,99.99764
45.2625,943.9199,8.577272,-39.66498,-0.4423796,-5.492789,99.98897
45.32916,945.2501,8.576376,-39.76774,-0.4425696,-5.497646,99.97697
45.39583,946.5801,8.575209,-39.8648,-0.4426224,-5.500801,99.98429
45.4625,947.9087,8.573978,-39.97222,-0.4428989,-5.506739,99.97626
45.52917,949.2398,8.57291,-40.07205,-0.4429924,-5.510406,99.96249
45.59583,950.5741,8.571549,-40.18812,-0.4434319,-5.518379,100.0084
45.6625,951.9009,8.570184,-40.30344,-0.4438533,-5.526134,100.0022
45.72917,953.2314,8.569022,-40.41362,-0.4441454,-5.532281,100.0124
45.79584,954.5624,8.567728,-40.51978,-0.4443373,-5.537185,100.0118
45.8625,955.8929,8.566249,-40.62496,-0.4444978,-5.5417,99.99179
45.92916,957.2199,8.565201,-40.7443,-0.4449635,-5.550022,99.97362
45.99584,958.5506,8.564024,-40.87072,-0.4455672,-5.560071,99.99501
46.0625,959.8824,8.562914,-40.98137,-0.4458142,-5.565663,99.98884
46.12916,961.2134,8.561388,-41.08764,-0.445957,-5.569942,100.0204
46.19584,962.5422,8.560431,-41.20648,-0.4463653,-5.577545,100.014
46.2625,963.8734,8.558898,-41.33432,-0.4469538,-5.587402,100.0081
46.32916,965.2048,8.557661,-41.45569,-0.4473907,-5.595371,99.95731
46.39583,966.5362,8.556256,-41.59804,-0.4482687,-5.608863,100.0234
46.4625,967.8669,8.55479,-41.74347,-0.4492006,-5.623043,99.98336
46.52917,969.1978,8.553879,-41.88191,-0.4499691,-5.635184,99.99158
46.59583,970.5293,8.552528,-42.03276,-0.4509902,-5.650497,100.0105
46.6625,971.859,8.551101,-42.19324,-0.4522053,-5.668255,100.0341
46.72917,973.1884,8.549535,-42.35516,-0.4534372,-5.686235,100.0031
46.79584,974.5184,8.548262,-42.5315,-0.4549602,-5.707881,99.99501
46.8625,975.8476,8.547149,-42.69413,-0.4561772,-5.725703,99.99332
46.92916,977.1788,8.546005,-42.86074,-0.4574614,-5.744382,99.9838
46.99584,978.5063,8.54425,-43.04272,-0.4590601,-5.767026,99.98024
47.0625,979.8344,8.542968,-43.23031,-0.4607598,-5.790958,100.0155
47.12916,981.1649,8.541724,-43.42684,-0.4626272,-5.81702,100.0352
47.19584,982.4924,8.540269,-43.6104,-0.4642092,-5.839509,99.99586
47.2625,983.8249,8.539038,-43.80461,-0.4659916,-5.864538,99.99824
47.32916,985.1512,8.537535,-44.00985,-0.4679942,-5.892361,99.96769
47.39583,986.4816,8.536038,-44.21866,-0.4700489,-5.920861,100.0487
47.4625,987.8112,8.534826,-44.43403,-0.4722226,-5.950884,99.99978
47.49584,988.4749,8.534171,-44.54031,-0.473274,-5.96546,99.97691