File: examples/pyrolysis/single_element/1D/gold/experiment_comp/20degpermin_run1.csv
Time (min),Temperature (degC),Weight (mg),Heat Flow (mW),Temperature Difference (degC),Temperature Difference (muV),Sample Purge Flow (mL/min)
6.11E-04,50.72294,8.116201,-11.28152,0.0756052,0.4785191,100.021
0.07916666,50.5923,8.115999,-11.28628,0.07477344,0.4730334,100.0133
0.1625,50.47674,8.115958,-11.27993,0.07525119,0.4758493,99.96738
0.2458334,50.41363,8.115569,-11.25342,0.07813926,0.4939566,100.0201
0.3291667,50.42184,8.11516,-11.20316,0.08391051,0.5303852,99.94664
0.4125,50.52778,8.114734,-11.12676,0.09288985,0.5872608,100.0118
0.4958334,50.74864,8.114375,-11.02287,0.1052588,0.6658332,100.0292
0.5791666,51.10117,8.114075,-10.89534,0.12059,0.7635694,99.97724
0.6625,51.59216,8.11376,-10.75077,0.1381193,0.8758501,100.0128
0.7458334,52.23898,8.113394,-10.58881,0.1578606,1.002999,99.96436
0.8291666,53.04015,8.113197,-10.41677,0.1789508,1.139839,100.0012
0.9125,53.99338,8.112884,-10.23028,0.2018463,1.289558,99.96344
0.9958332,55.09468,8.112605,-10.03274,0.2261062,1.449667,100.0043
1.079166,56.34926,8.112438,-9.822186,0.251891,1.621501,99.98215
1.1625,57.74872,8.112021,-9.603118,0.278635,1.801778,100.0188
1.245833,59.27418,8.111694,-9.375162,0.3063148,1.990622,100.0183
1.329166,60.92,8.111608,-9.141296,0.3345803,2.185703,99.98195
1.4125,62.66703,8.111545,-8.904187,0.363165,2.384819,100.0248
1.495833,64.52495,8.111366,-8.659399,0.3924247,2.591116,100.0106
1.579166,66.44619,8.111213,-8.413791,0.4215474,2.799394,99.98468
1.6625,68.44039,8.11091,-8.164134,0.450845,3.01169,100.0429
1.745833,70.48449,8.110749,-7.913222,0.4799872,3.225855,99.94858
1.829166,72.56819,8.110384,-7.65775,0.5093062,3.444064,99.9758
1.9125,74.68366,8.110168,-7.405478,0.5379446,3.660486,100.0206
1.995833,76.80412,8.109859,-7.158868,0.5656342,3.87307,100.007
2.079166,78.93186,8.109549,-6.926282,0.5914956,4.075515,99.9985
2.1625,81.05731,8.109262,-6.700066,0.6165784,4.273288,100.0329
2.245834,83.16866,8.108728,-6.487995,0.6400046,4.460616,99.96253
2.329166,85.26059,8.1084,-6.281426,0.6625876,4.643654,99.99609
2.4125,87.3197,8.107891,-6.08431,0.6839306,4.819404,100.0254
2.495834,89.35312,8.107309,-5.894004,0.7043296,4.989748,100.0262
2.579166,91.34816,8.106925,-5.7209,0.7227337,5.146959,99.98866
2.6625,93.30418,8.106324,-5.564031,0.7392761,5.291729,99.98507
2.745834,95.22009,8.105576,-5.415142,0.7548304,5.43005,100.0339
2.829166,97.10478,8.104989,-5.280798,0.7687512,5.557114,99.97191
2.9125,98.94235,8.104106,-5.153758,0.7819186,5.678242,100.0028
2.995834,100.7465,8.103422,-5.041244,0.7937134,5.788091,100.023
3.079166,102.5063,8.102489,-4.930413,0.805238,5.896144,100.002
3.1625,104.235,8.101606,-4.832476,0.8153756,5.994164,100.0195
3.245834,105.9265,8.100707,-4.742795,0.8246063,6.085584,100.0088
3.329167,107.5863,8.099855,-4.6653,0.832555,6.16759,100.0199
3.4125,109.2272,8.098743,-4.594592,0.8397699,6.24416,100.0052
3.495834,110.8355,8.097539,-4.52493,0.8468258,6.319564,100.0027
3.579167,112.4282,8.096611,-4.458668,0.8534954,6.39213,100.0156
3.6625,113.9988,8.095468,-4.399811,0.8593934,6.458953,100.0025
3.745834,115.5575,8.094326,-4.34148,0.8651976,6.525118,100.0491
3.829167,117.107,8.093124,-4.291168,0.8702276,6.58523,99.97486
3.9125,118.6453,8.091906,-4.244372,0.8750726,6.642572,100.0004
3.995834,120.1823,8.090584,-4.19618,0.8800437,6.700842,99.98134
4.079167,121.7124,8.089118,-4.151812,0.8846161,6.756244,99.98856
4.1625,123.2546,8.0879,-4.110281,0.8888882,6.809512,100.0113
4.245834,124.7919,8.086554,-4.068162,0.8931915,6.863268,99.9936
4.329167,126.3378,8.084974,-4.030369,0.8970575,6.913891,100.0279
4.4125,127.8929,8.083794,-3.98789,0.9013458,6.96803,99.97805
4.495834,129.4615,8.082185,-3.951695,0.9050147,7.017689,100.0049
4.579167,131.0388,8.080774,-3.909875,0.9091931,7.071598,99.98204
4.6625,132.6309,8.079153,-3.870781,0.9130914,7.123662,100.0488
4.745834,134.2339,8.077313,-3.825559,0.9175419,7.180376,100.0377
4.829167,135.8526,8.075899,-3.782811,0.9217541,7.235462,99.99522
4.9125,137.4863,8.07424,-3.74142,0.9260005,7.289715,100.0209
4.995834,139.1357,8.07261,-3.69983,0.9302912,7.344278,100.0033
5.079167,140.7947,8.070952,-3.662066,0.9342064,7.396204,99.97882
5.1625,142.4707,8.069248,-3.621204,0.9383878,7.450562,99.96496
5.245834,144.1636,8.067457,-3.579031,0.9426691,7.506045,99.98741
5.329168,145.865,8.065681,-3.538411,0.9467853,7.560546,99.95126
5.4125,147.5812,8.063821,-3.499931,0.9506836,7.613571,99.99715
5.495834,149.3004,8.062119,-3.465388,0.9542016,7.663828,100.0094
5.579168,151.0294,8.0602,-3.426216,0.9581212,7.717506,99.97859
5.6625,152.7684,8.05841,-3.39227,0.9615451,7.767436,99.99982
5.745834,154.5169,8.056549,-3.359308,0.9648609,7.816686,99.95556
5.829168,156.2668,8.054628,-3.330618,0.967871,7.862792,100.0133
5.9125,158.0139,8.052634,-3.29988,0.9711751,7.91041,100.0094
5.995834,159.7636,8.05069,-3.274722,0.9739601,7.953868,99.97681
6.079168,161.511,8.0486,-3.250416,0.9766535,7.996656,100.0087
6.1625,163.2609,8.046568,-3.22901,0.9790722,8.03725,100.0026
6.245834,165.0094,8.044395,-3.207825,0.9814571,8.07759,99.99238
6.329168,166.7519,8.042222,-3.189309,0.9835906,8.115869,100.0118
6.4125,168.4891,8.040051,-3.172588,0.9855516,8.152718,100.0125
6.495834,170.2154,8.037622,-3.161165,0.9870316,8.185544,100.0291
6.579168,171.9412,8.0355,-3.147644,0.9886868,8.21977,99.96602
6.6625,173.6582,8.033294,-3.137023,0.9900758,8.25173,99.97962
6.745834,175.3709,8.031072,-3.131469,0.991036,8.279835,99.96503
6.829168,177.0721,8.028834,-3.123366,0.9923647,8.309649,99.99656
6.9125,178.767,8.026435,-3.11879,0.9934018,8.336743,99.98657
6.995834,180.4515,8.024201,-3.115417,0.9943244,8.362772,99.99306
7.079168,182.1387,8.021986,-3.112212,0.9952262,8.388599,99.99522
7.1625,183.8077,8.019594,-3.11077,0.9959659,8.412939,99.95282
7.245834,185.4747,8.017408,-3.107436,0.9968647,8.438594,99.99758
7.329168,187.1367,8.01479,-3.104425,0.9977275,8.463859,100.005
7.4125,188.8032,8.012687,-3.103806,0.9983794,8.487324,100.004
7.495834,190.4527,8.010309,-3.104544,0.9989078,8.509658,99.99424
7.579168,192.1036,8.007891,-3.103808,0.999559,8.533003,99.96922
7.6625,193.7545,8.005556,-3.104453,1.000087,8.555255,100.0155
7.745834,195.4032,8.003188,-3.102028,1.000883,8.579711,99.98056
7.829168,197.0447,8.000728,-3.09832,1.001903,8.60507,99.98093
7.9125,198.69,7.998316,-3.098,1.002664,8.627859,100.0092
7.995834,200.3387,7.996056,-3.097578,1.003692,8.65298,99.98863
8.079166,201.9821,7.993457,-3.093466,1.004997,8.680511,100.0064
8.1625,203.6258,7.991199,-3.074432,1.006304,8.70808,99.98405
8.245834,205.2754,7.988718,-3.052658,1.00776,8.736988,99.97772
8.329166,206.9264,7.986239,-3.030569,1.009159,8.765449,100.0175
8.4125,208.5789,7.98383,-3.004064,1.010835,8.796371,100.0297
8.495834,210.2384,7.981355,-2.975553,1.012594,8.828087,100.0004
8.579166,211.8987,7.9789,-2.946294,1.014323,8.859644,100.0136
8.6625,213.559,7.976437,-2.907914,1.016694,8.896837,100.0102
8.745834,215.2262,7.97398,-2.871504,1.018824,8.932031,100.0131
8.829166,216.8944,7.971449,-2.827299,1.021522,8.971859,99.9857
8.9125,218.5669,7.969034,-2.785196,1.024061,9.009594,100.0026
8.995834,220.2393,7.966619,-2.739852,1.026763,9.04884,100.0254
9.079166,221.9213,7.964045,-2.690102,1.029721,9.090431,99.98258
9.1625,223.5975,7.961554,-2.634692,1.033014,9.135056,100.0082
9.245834,225.2825,7.959118,-2.576252,1.036448,9.181044,99.97797
9.329166,226.9645,7.956582,-2.515764,1.039938,9.227661,100.0277
9.4125,228.6496,7.953976,-2.448542,1.043837,9.278,100.0126
9.495834,230.3359,7.951391,-2.381111,1.047661,9.327791,100.0227
9.579166,232.0216,7.948856,-2.315416,1.051272,9.375809,100.0108
9.6625,233.7065,7.946352,-2.24573,1.055086,9.425744,100.0013
9.745834,235.3917,7.943769,-2.17112,1.059168,9.478181,99.95895
9.829166,237.0746,7.94116,-2.096426,1.063185,9.530041,100.0183
9.9125,238.7609,7.938476,-2.020281,1.06733,9.582226,99.98764
9.995834,240.4417,7.93592,-1.940881,1.071646,9.635835,100.0037
10.07917,242.124,7.933345,-1.863796,1.075729,9.687445,99.98006
10.1625,243.8035,7.930778,-1.782254,1.080042,9.741251,99.99316
10.24583,245.4875,7.9281,-1.705222,1.083984,9.791775,100.004
10.32917,247.1606,7.925394,-1.63098,1.087668,9.840076,100.0043
10.4125,248.8385,7.92292,-1.557799,1.091223,9.887297,100.0051
10.49584,250.5137,7.920187,-1.481821,1.094907,9.935778,99.99599
10.57916,252.1869,7.91754,-1.409334,1.098308,9.981738,100.0444
10.6625,253.8557,7.914847,-1.342901,1.101258,10.02368,99.97091
10.74584,255.524,7.912175,-1.280198,1.103919,10.06308,100.028
10.82916,257.1928,7.909485,-1.221126,1.106308,10.10002,99.99496
10.9125,258.8615,7.906708,-1.160445,1.108816,10.13765,100.04
10.99584,260.5258,7.90421,-1.1076,1.110854,10.1704,100.0308
11.07916,262.1902,7.901506,-1.061532,1.112436,10.19898,100.0223
11.1625,263.854,7.898806,-1.022584,1.11354,10.22324,99.9915
11.24584,265.5172,7.896174,-0.9886311,1.114315,10.24447,100.0401
11.32916,267.1706,7.893592,-0.9563934,1.11497,10.2646,100.016
11.4125,268.8352,7.890651,-0.9323025,1.115109,10.27998,100.0049
11.49584,270.4941,7.888049,-0.9142374,1.114864,10.29184,100.0039
11.57916,272.1548,7.885222,-0.9019624,1.114262,10.3004,99.98525
11.6625,273.8147,7.882697,-0.8904709,1.113616,10.30852,99.94882
11.74584,275.475,7.880026,-0.8838256,1.112678,10.31393,99.94735
11.82916,277.1336,7.877228,-0.8829276,1.111396,10.31613,99.97018
11.9125,278.7963,7.874371,-0.8861469,1.109878,10.31609,100.0085
11.99584,280.4564,7.871728,-0.8919097,1.108299,10.31471,100.0048
12.07916,282.1154,7.868908,-0.904993,1.106322,10.30933,99.96274
12.1625,283.7768,7.866165,-0.9168625,1.104436,10.30477,99.99434
12.24584,285.4358,7.863335,-0.9359601,1.102138,10.2963,100.0008
12.32916,287.0987,7.860584,-0.9526074,1.100007,10.28936,100.0159
12.4125,288.7582,7.857737,-0.9736047,1.097639,10.28016,99.99965
12.49584,290.4209,7.854688,-0.9992364,1.095021,10.26856,100.0212
12.57916,292.0819,7.85196,-1.015057,1.093002,10.26252,99.9641
12.6625,293.7442,7.849032,-1.029714,1.091068,10.25727,100.0136
12.74584,295.4031,7.846036,-1.050933,1.088773,10.24857,100.0067
12.82916,297.064,7.843116,-1.077954,1.086164,10.23687,99.97999
12.9125,298.7294,7.840064,-1.104893,1.083584,10.2254,100.0069
12.99583,300.3904,7.837076,-1.141863,1.080474,10.20867,100.0264
13.07916,302.0535,7.833874,-1.172556,1.077814,10.19554,99.9672
13.1625,303.7141,7.83069,-1.19493,1.075657,10.18707,100.0157
13.24583,305.3796,7.827574,-1.203452,1.074305,10.18621,100.0024
13.32916,307.0442,7.82429,-1.210986,1.073022,10.18601,99.98732
13.4125,308.7072,7.820947,-1.207272,1.072386,10.19193,100.0243
13.49583,310.3743,7.817663,-1.170714,1.073599,10.21545,100.0176
13.57916,312.0405,7.814131,-1.164827,1.073097,10.22267,99.98612
13.6625,313.6981,7.810468,-1.260837,1.066944,10.17596,100.0002
13.74583,315.3602,7.806965,-1.32623,1.062536,10.1458,100.0108
13.82916,317.0248,7.803129,-1.357363,1.060058,10.134,99.99959
13.9125,318.6833,7.799411,-1.38653,1.057711,10.12341,100.0112
13.99583,320.3472,7.79558,-1.402866,1.056093,10.11976,100.0526
14.07916,322.0086,7.791419,-1.414981,1.054784,10.11846,100.0021
14.1625,323.6713,7.787378,-1.439219,1.052855,10.11097,99.97782
14.24583,325.3292,7.783252,-1.462218,1.051014,10.1043,99.99653
14.32916,326.9925,7.77881,-1.48595,1.049156,10.09742,100.0036
14.4125,328.6522,7.77459,-1.50684,1.04747,10.0922,99.98934
14.49583,330.3102,7.770032,-1.530862,1.045637,10.08551,99.99936
14.57916,331.9709,7.765347,-1.551045,1.04403,10.08099,99.99782
14.6625,333.6318,7.760631,-1.571254,1.042441,10.07663,99.99931
14.74583,335.2885,7.75586,-1.593589,1.040758,10.07135,99.98884
14.82916,336.946,7.750976,-1.60745,1.039544,10.07058,100.0201
14.9125,338.607,7.74571,-1.631274,1.037822,10.06489,100.0445
14.99583,340.2639,7.740645,-1.647822,1.036503,10.0631,100.0201
15.07916,341.929,7.735357,-1.659261,1.035501,10.06408,100.0336
15.1625,343.5869,7.729919,-1.671525,1.034501,10.06479,99.95363
15.24583,345.2441,7.724197,-1.68048,1.03369,10.06733,99.99306
15.32916,346.9037,7.718434,-1.692558,1.032733,10.06846,100.0137
15.4125,348.5585,7.712793,-1.700205,1.032022,10.07199,99.99722
15.49583,350.2219,7.706794,-1.709526,1.03124,10.07484,100.006
15.57916,351.8796,7.700768,-1.72889,1.029961,10.07281,99.99256
15.6625,353.5384,7.694598,-1.740303,1.029107,10.07495,100.002
15.74583,355.1946,7.688103,-1.75302,1.028204,10.07661,99.99397
15.82916,356.852,7.681539,-1.765822,1.027314,10.0784,100.0045
15.9125,358.5118,7.674939,-1.781781,1.026283,10.07881,99.9961
15.99583,360.1669,7.667944,-1.795693,1.025374,10.08042,99.97501
16.07916,361.8248,7.660774,-1.815851,1.024199,10.07913,99.99726
16.1625,363.4834,7.653647,-1.834321,1.02316,10.07888,99.97324
16.24583,365.1413,7.64614,-1.863489,1.021607,10.07356,99.96593
16.32916,366.8012,7.638566,-1.887583,1.02033,10.07097,100.0085
16.4125,368.4571,7.630584,-1.92275,1.018527,10.06315,99.97968
16.49583,370.1174,7.622502,-1.969741,1.016167,10.04982,99.98538
16.57916,371.7844,7.611372,-2.040786,1.012655,10.02509,100.0134
16.6625,373.4407,7.595376,-2.143736,1.007619,9.9852,100.0217
16.74583,375.1011,7.552558,-2.305898,0.9997469,9.917076,99.983
16.82916,376.7511,7.533813,-2.500912,0.9903476,9.833621,100.007
16.9125,378.4108,7.51892,-2.658022,0.9828686,9.769084,100.0162
16.99583,380.0637,7.504743,-2.797544,0.9763074,9.713534,100.0322
17.07916,381.7258,7.490332,-2.91053,0.9711211,9.671234,100.0336
17.1625,383.385,7.47608,-3.014685,0.9664234,9.633605,99.99944
17.24583,385.0495,7.461418,-3.127298,0.9613746,9.592399,100.0291
17.32916,386.7145,7.446409,-3.24855,0.9559699,9.547553,100.0255
17.4125,388.3765,7.430966,-3.378802,0.9501964,9.498941,100.0154
17.49583,390.0383,7.414941,-3.51875,0.9440269,9.446259,100.0341
17.57916,391.7019,7.398413,-3.67081,0.9373544,9.388426,100.0331
17.6625,393.3649,7.38068,-3.873006,0.9284072,9.307678,99.99689
17.74583,395.0328,7.362276,-4.044468,0.9209822,9.242042,99.99447
17.82916,396.6931,7.343353,-4.22582,0.9131738,9.172426,99.97821
17.9125,398.3625,7.323443,-4.447833,0.9035728,9.084631,100.0268
17.99583,400.0295,7.303168,-4.646887,0.8951361,9.008282,100.0042
18.07916,401.6975,7.282618,-4.750992,0.8911665,8.976519,99.98016
18.1625,403.3652,7.261774,-4.846672,0.8876355,8.949109,100.0107
18.24583,405.0392,7.240393,-4.837078,0.8889408,8.970453,100.0098
18.32916,406.7094,7.2188,-4.78792,0.8920441,9.009972,100.0162
18.4125,408.3853,7.196868,-4.771772,0.8936561,9.034492,99.97795
18.49583,410.0588,7.174684,-4.80389,0.8931075,9.037187,100.0482
18.57916,411.7356,7.152343,-4.823299,0.8931518,9.045884,100.0157
18.6625,413.4142,7.130064,-4.836818,0.893477,9.057434,99.98559
18.74583,415.0985,7.108234,-4.826896,0.8948582,9.079715,99.99472
18.82916,416.7776,7.086411,-4.802159,0.8968957,9.108688,100.0025
18.9125,418.4637,7.065043,-4.759638,0.8997186,9.145668,99.98832
18.99583,420.1452,7.04439,-4.69974,0.9033068,9.190313,99.99728
19.07916,421.8268,7.024032,-4.639702,0.9068894,9.234921,100.0005
19.1625,423.513,7.00429,-4.561284,0.9112541,9.287566,99.98556
19.24583,425.1966,6.98507,-4.475606,0.9159071,9.343225,100.0129
19.32916,426.884,6.966389,-4.383296,0.9208192,9.40161,99.98009
19.4125,428.5684,6.948245,-4.295219,0.9255203,9.457925,100.0086
19.49583,430.2525,6.930288,-4.206231,0.9302313,9.514418,99.9998
19.57916,431.9328,6.913008,-4.111255,0.9351653,9.573261,100.0157
19.6625,433.6137,6.89597,-4.024276,0.9397316,9.628422,100.0064
19.74583,435.2944,6.879322,-3.939716,0.9441684,9.682331,99.99526
19.82916,436.971,6.862728,-3.868041,0.9480384,9.730472,99.96196
19.9125,438.6469,6.846322,-3.799211,0.9517851,9.777238,100.0236
19.99583,440.3258,6.83009,-3.73917,0.9551621,9.820113,99.98414
20.07916,441.9966,6.814129,-3.685229,0.9582674,9.860243,100.029
20.1625,443.6718,6.798156,-3.634122,0.961242,9.899063,100.0031
20.24583,445.3432,6.782212,-3.59771,0.9636014,9.931586,99.99985
20.32916,447.0138,6.766178,-3.57067,0.965571,9.960116,100.0066
20.4125,448.6824,6.750239,-3.54572,0.9674496,9.987731,99.9734
20.49583,450.355,6.73425,-3.527256,0.9690642,10.01265,99.98986
20.57916,452.0223,6.718249,-3.523128,0.9701,10.0316,99.99132
20.6625,453.6911,6.701761,-3.517776,0.9711876,10.05109,99.98741
20.74583,455.3598,6.685515,-3.525087,0.971775,10.06541,99.99108
20.82916,457.0284,6.668762,-3.537097,0.9721876,10.0779,99.98742
20.9125,458.6947,6.651988,-3.559668,0.9722101,10.08616,99.96532
20.99583,460.3628,6.634939,-3.579628,0.9723494,10.0956,99.99207
21.07916,462.03,6.617339,-3.60153,0.9724228,10.10435,99.99101
21.1625,463.701,6.599639,-3.627104,0.9723666,10.11176,99.98964
21.24583,465.3676,6.581503,-3.653285,0.9722978,10.11904,99.97921
21.32916,467.0361,6.563056,-3.683746,0.9720769,10.12471,99.97266
21.4125,468.7048,6.544274,-3.722688,0.9715461,10.12716,99.99599
21.49583,470.3711,6.523347,-3.78582,0.9701105,10.12014,99.96968
21.57916,472.0328,6.489792,-3.92482,0.9658238,10.08331,100.0142
21.6625,473.6972,6.462459,-4.032063,0.9627853,10.05947,100.0286
21.74583,475.3639,6.437844,-4.111017,0.9608478,10.04708,100.0086
21.82916,477.0297,6.414218,-4.183142,0.9591974,10.03763,99.99738
21.9125,478.6918,6.390528,-4.257841,0.9574792,10.02739,99.98964
21.99583,480.3627,6.36744,-4.324887,0.9560736,10.0204,99.97458
22.07916,482.0313,6.344121,-4.386735,0.9548829,10.01564,100.022
22.1625,483.6945,6.320791,-4.447094,0.9537659,10.01163,100.0091
22.24583,485.3605,6.297657,-4.501739,0.952879,10.01002,99.97828
22.32916,487.0278,6.27448,-4.567676,0.9516001,10.00427,99.98554
22.4125,488.693,6.251012,-4.629474,0.9504922,10.0003,99.99224
22.49583,490.3608,6.227562,-4.691309,0.9494035,9.996496,99.99986
22.57916,492.029,6.203938,-4.75595,0.9482342,9.991835,99.99744
22.6625,493.6993,6.180039,-4.81728,0.9472045,9.988624,100.0027
22.74583,495.365,6.155958,-4.880852,0.9461121,9.984728,100.0014
22.82916,497.0326,6.132488,-4.951011,0.9448113,9.978546,100.0144
22.9125,498.6998,6.108888,-5.030256,0.9432128,9.969187,99.99106
22.99583,500.3648,6.085058,-5.106887,0.9417278,9.960991,99.99634
23.07916,502.0335,6.06094,-5.188618,0.9400871,9.951118,100.0241
23.1625,503.695,6.036776,-5.281133,0.9380914,9.937458,100.021
23.24583,505.3654,6.012514,-5.378426,0.9359589,9.922313,99.99726
23.32916,507.033,5.988299,-5.481187,0.9336624,9.905389,99.9972
23.4125,508.6937,5.963898,-5.58625,0.9313097,9.887818,100.028
23.49583,510.3631,5.939669,-5.696312,0.9288176,9.868739,99.98055
23.57916,512.024,5.915634,-5.808062,0.926292,9.849257,99.97338
23.6625,513.6896,5.891633,-5.928228,0.9235084,9.826976,100.0064
23.74583,515.3541,5.868096,-6.050124,0.9206981,9.804343,99.98838
23.82916,517.02,5.844469,-6.175251,0.9178189,9.780812,99.99351
23.9125,518.6824,5.821342,-6.306,0.9147792,9.755509,100.012
23.99583,520.3461,5.79817,-6.44991,0.9113282,9.725766,100.036
24.07916,522.0116,5.775375,-6.5789,0.9084091,9.701653,100.0163
24.1625,523.6726,5.753051,-6.717237,0.9052046,9.674438,99.98211
24.24583,525.3383,5.730918,-6.8633,0.9017754,9.644764,100.0032
24.32916,527.0018,5.709356,-7.004735,0.8985284,9.616991,99.9713
24.4125,528.6671,5.687954,-7.153584,0.8950675,9.586866,100.0174
24.49583,530.3307,5.666882,-7.296945,0.8918152,9.55893,100.0258
24.57916,531.9953,5.646152,-7.454278,0.8881347,9.52634,100.0192
24.6625,533.6612,5.626152,-7.611158,0.8844991,9.494171,100.0015
24.74583,535.3232,5.604155,-7.74536,0.8816278,9.470142,99.97681
24.82916,536.9895,5.584687,-7.86603,0.8792225,9.451025,100.0128
24.9125,538.651,5.565728,-7.999054,0.8764362,9.427766,100.0105
24.99583,540.3142,5.547243,-8.147193,0.8731874,9.399476,99.98906
25.07916,541.9788,5.529326,-8.303316,0.8697095,9.368676,99.96147
25.1625,543.6418,5.511526,-8.469962,0.8659203,9.334454,100.0156
25.24583,545.303,5.494262,-8.646981,0.8618281,9.296902,99.98837
25.32916,546.9641,5.477398,-8.829468,0.8575906,9.257718,99.99509
25.4125,548.6236,5.461013,-9.014996,0.8532848,9.217724,99.97681
25.49583,550.2854,5.445171,-9.212875,0.8486202,9.173782,100.0238
25.57916,551.9478,5.429579,-9.414387,0.8438724,9.128869,100.0325
25.6625,553.6054,5.414356,-9.621124,0.8389891,9.082416,99.99168
25.74583,555.2672,5.399752,-9.822197,0.8343191,9.03813,100.004
25.82916,556.9287,5.38538,-10.03975,0.829173,8.988539,100.0072
25.9125,558.5862,5.371565,-10.26491,0.8238197,8.936624,99.97649
25.99583,560.2456,5.357911,-10.50839,0.8179337,8.87884,100.0026
26.07916,561.9063,5.344771,-10.75192,0.8120795,8.821309,99.9668
26.1625,563.5688,5.331894,-11.00577,0.8059424,8.760619,99.99497
26.24583,565.2246,5.319493,-11.27034,0.7995079,8.696594,99.96864
26.32916,566.8844,5.307429,-11.55029,0.7926424,8.627788,99.98712
26.4125,568.5448,5.295688,-11.83596,0.7856382,8.557364,100.0309
26.49583,570.2024,5.28436,-12.12981,0.7784213,8.484516,100.0082
26.57916,571.8598,5.273266,-12.4382,0.7708011,8.407156,100.0067
26.6625,573.5188,5.262618,-12.76284,0.7627308,8.32477,99.99486
26.74583,575.1785,5.252212,-13.08971,0.7546359,8.241961,99.98124
26.82916,576.8328,5.242263,-13.43478,0.7460339,8.153461,100.0018
26.9125,578.4907,5.232492,-13.7869,0.7372622,8.062972,99.95494
26.99583,580.1488,5.222954,-14.15788,0.7279711,7.966675,99.99657
27.07916,581.804,5.213925,-14.54446,0.7182564,7.8656,100.0284
27.1625,583.4602,5.204981,-14.93317,0.7085205,7.764145,100.0219
27.24583,585.1175,5.19635,-15.34781,0.6980628,7.65464,99.98839
27.32916,586.7735,5.187846,-15.75511,0.6878614,7.547782,100.0546
27.4125,588.4308,5.179679,-16.16402,0.6776535,7.44071,99.99852
27.49583,590.0864,5.171769,-16.56231,0.6677934,7.337307,100.0041
27.57916,591.7402,5.164044,-16.96159,0.657938,7.233805,100.0123
27.6625,593.3932,5.156646,-17.36641,0.647955,7.128752,100.022
27.74583,595.0518,5.14948,-17.76283,0.6382626,7.026634,100.028
27.82916,596.7032,5.142291,-18.13276,0.6293694,6.9331,100.0112
27.9125,598.3651,5.135242,-18.4897,0.6208818,6.843915,100.0086
27.99583,600.0183,5.12837,-18.84378,0.6124934,6.755704,100.0246
28.07916,601.6774,5.121991,-19.19782,0.6041292,6.667644,99.98312
28.1625,603.3367,5.115548,-19.53872,0.5961601,6.583834,99.99397
28.24583,604.9946,5.109181,-19.87308,0.5883941,6.502154,99.99152
28.32916,606.6491,5.103033,-20.21629,0.5803881,6.417711,100.0226
28.4125,608.3068,5.096942,-20.55262,0.5725957,6.335522,99.97101
28.49583,609.9646,5.091076,-20.89673,0.5645967,6.250934,100.0153
28.57916,611.6246,5.085234,-21.23776,0.5567002,6.167372,99.96894
28.6625,613.2867,5.079578,-21.56074,0.5493278,6.089514,99.99014
28.74583,614.9466,5.0742,-21.87037,0.5422856,6.015852,99.97188
28.82916,616.6019,5.068738,-22.16775,0.5355538,5.945968,99.99071
28.9125,618.2648,5.063502,-22.44686,0.5293484,5.881812,100.0273
28.99583,619.9256,5.058187,-22.72144,0.5232769,5.819036,99.99689
29.07916,621.5856,5.052992,-22.98367,0.5175553,5.760042,99.99028
29.1625,623.2462,5.047874,-23.24422,0.5118864,5.701533,100
29.24583,624.9086,5.043009,-23.49816,0.5064058,5.64502,100.0169
29.32916,626.5644,5.038064,-23.75244,0.500916,5.588306,99.98439
29.4125,628.2284,5.033209,-23.99794,0.4956778,5.534307,100.0051
29.49583,629.8882,5.028302,-24.25217,0.4901988,5.477519,99.99522
29.57916,631.547,5.023647,-24.49026,0.485166,5.425618,100.0279
29.6625,633.2082,5.018704,-24.72425,0.4802496,5.374926,99.99715
29.74583,634.87,5.014129,-24.96316,0.4752242,5.322656,99.97645
29.82916,636.5274,5.009492,-25.1747,0.470967,5.278686,100.0012
29.9125,638.1902,5.00508,-25.36886,0.4671861,5.239994,100.0136
29.99583,639.8516,5.000462,-25.5689,0.4632412,5.199404,100.0342
30.07916,641.5122,4.996098,-25.76005,0.4595344,5.161422,100.0013
30.1625,643.1729,4.991706,-25.96018,0.4555801,5.120603,99.98499
30.24583,644.8388,4.987332,-26.15384,0.4518018,5.081698,100.0117
30.32916,646.4994,4.982998,-26.3341,0.448381,5.046759,99.95982
30.4125,648.162,4.97872,-26.51346,0.4449804,5.011992,99.98785
30.49583,649.8235,4.974396,-26.70819,0.4411612,4.972451,100.0038
30.57916,651.4842,4.970176,-26.89216,0.4376293,4.936089,100.0074
30.6625,653.1476,4.966117,-27.08428,0.4338774,4.897188,100.017
30.74583,654.8112,4.961986,-27.27236,0.4302318,4.859432,99.99243
30.82916,656.47,4.957785,-27.46711,0.4264029,4.81954,100.0066
30.9125,658.1332,4.953736,-27.65246,0.4228274,4.782457,100.0156
30.99583,659.7934,4.94978,-27.85108,0.4188946,4.741268,99.99362
31.07916,661.4562,4.945926,-28.05334,0.4148671,4.698945,100.0065
31.1625,663.1178,4.941624,-28.23392,0.4114154,4.663089,99.94916
31.24583,664.7782,4.937675,-28.4271,0.4076283,4.623369,99.98001
31.32916,666.4402,4.93382,-28.61858,0.4038885,4.584128,100.0466
31.4125,668.1,4.93001,-28.81235,0.4000875,4.544131,99.99637
31.49583,669.762,4.92619,-29.01662,0.3960134,4.500969,99.98566
31.57916,671.4221,4.922526,-29.21904,0.3919904,4.458321,100.0097
31.6625,673.0856,4.918759,-29.42351,0.387919,4.415062,99.97528
31.74583,674.743,4.91507,-29.62572,0.3839071,4.372414,99.99419
31.82916,676.4032,4.91145,-29.83186,0.3797991,4.328606,100.001
31.9125,678.0636,4.907848,-30.03344,0.3758155,4.286153,100.039
31.99583,679.724,4.90427,-30.2301,0.371965,4.245158,99.9921
32.07916,681.3864,4.900583,-30.42835,0.3680803,4.203709,99.98991
32.1625,683.0488,4.897193,-30.62666,0.3641997,4.162247,100.014
32.24584,684.71,4.89386,-30.82572,0.3603056,4.12057,99.99522
32.32916,686.3718,4.890481,-31.01118,0.356769,4.082922,100.0204
32.4125,688.0294,4.887168,-31.19311,0.3533264,4.046298,100.019
32.49584,689.6926,4.883884,-31.37573,0.3498761,4.009524,100.0013
32.57916,691.3522,4.880566,-31.55702,0.3464636,3.973137,100.0201
32.6625,693.0159,4.877668,-31.72334,0.3434435,3.941195,99.98858
32.74584,694.679,4.874579,-31.91205,0.3398594,3.902714,99.9741
32.82916,696.3413,4.871614,-32.0939,0.3364614,3.866278,100.0436
32.9125,698.0024,4.868844,-32.27626,0.3330572,3.829717,99.98306
32.99584,699.666,4.86596,-32.45411,0.3297785,3.794547,99.98147
33.07916,701.3274,4.863378,-32.63448,0.3264427,3.75867,100.009
33.1625,702.9913,4.860731,-32.82246,0.322926,3.72066,99.97961
33.24584,704.655,4.858235,-33.01608,0.3192765,3.681062,99.98294
33.32916,706.3171,4.855785,-33.21772,0.315434,3.639181,99.96759
33.4125,707.9793,4.853406,-33.41724,0.3116542,3.597965,99.9733
33.49584,709.6413,4.851181,-33.61127,0.3080205,3.558378,100.0044
33.57916,711.3069,4.848953,-33.82595,0.303885,3.512933,99.9978
33.6625,712.9691,4.846809,-34.04006,0.2997707,3.467672,100.0087
33.74584,714.6338,4.844747,-34.25924,0.2955432,3.421038,99.99741
33.82916,716.2965,4.842794,-34.4924,0.2909797,3.370445,100.0212
33.9125,717.9594,4.840881,-34.726,0.2864166,3.319787,100.0046
33.99584,719.6222,4.83891,-34.95254,0.282038,3.271195,99.99058
34.07916,721.2825,4.83709,-35.17014,0.277885,3.225158,100.0057
34.1625,722.9472,4.835322,-35.40243,0.2733869,3.175045,100.0041
34.24584,724.6063,4.833516,-35.6297,0.2690137,3.126316,99.9977
34.32916,726.2712,4.831892,-35.86666,0.2644202,3.074959,99.98303
34.4125,727.9318,4.830403,-36.09954,0.2599304,3.024735,100.0068
34.49584,729.5937,4.828811,-36.3401,0.2552636,2.972385,99.98045
34.57916,731.256,4.827303,-36.58458,0.2505125,2.918977,100.0275
34.6625,732.9153,4.825828,-36.82335,0.2459031,2.86715,99.99188
34.74584,734.5756,4.824398,-37.0554,0.2414624,2.817219,100.0234
34.82916,736.2384,4.823029,-37.29236,0.2369132,2.765954,100.0312
34.9125,737.8974,4.821488,-37.5312,0.2323206,2.714112,99.97778
34.99584,739.5602,4.820105,-37.77712,0.2275705,2.660356,99.97416
35.07916,741.2201,4.818966,-38.02672,0.2227352,2.605532,100.0194
35.1625,742.8825,4.817606,-38.27,0.2180563,2.552467,100.0042
35.24584,744.5422,4.816309,-38.50259,0.2136314,2.502302,99.98705
35.32916,746.2026,4.815188,-38.7341,0.2092331,2.452384,99.97491
35.4125,747.8631,4.813873,-38.98394,0.2044082,2.397394,100.0152
35.49584,749.5256,4.812868,-39.22594,0.1997707,2.34453,99.99139
35.57916,751.1856,4.811708,-39.46091,0.1952959,2.293503,99.97522
35.6625,752.8461,4.810567,-39.6993,0.190742,2.241481,99.98506
35.74584,754.5058,4.809438,-39.9429,0.1860656,2.187947,100.0356
35.82916,756.1684,4.808356,-40.18685,0.1813852,2.134284,100.0199
35.9125,757.83,4.807272,-40.43609,0.1765812,2.079091,99.9913
35.99584,759.4882,4.806131,-40.67963,0.1719027,2.025303,99.98652
36.07916,761.1504,4.805198,-40.9307,0.1670528,1.969426,99.99382
36.1625,762.8126,4.804313,-41.18282,0.1621759,1.913156,100.0054
36.24584,764.473,4.80334,-41.44766,0.1570042,1.853332,100.0134
36.32916,766.1284,4.80239,-41.70808,0.1519267,1.794542,100.0241
36.4125,767.7951,4.801373,-41.95802,0.147094,1.738569,100.0077
36.49584,769.4532,4.80052,-42.21015,0.1421969,1.681761,100.0096
36.57916,771.1144,4.799488,-42.47241,0.1370681,1.622137,100.0241
36.6625,772.77,4.798674,-42.72889,0.1320589,1.563852,100.0082
36.74584,774.4321,4.797925,-42.99594,0.1268112,1.502664,99.97514
36.82916,776.0932,4.797074,-43.2665,0.1214769,1.440365,99.98074
36.9125,777.75,4.796222,-43.53344,0.1162126,1.378812,100.0059
36.99584,779.4088,4.7953,-43.8065,0.1108047,1.315477,100.0077
37.07916,781.0653,4.794534,-44.07868,0.1054059,1.252167,99.99189
37.1625,782.7265,4.793778,-44.34629,0.1001027,1.189914,99.98981
37.24584,784.3851,4.793034,-44.60778,0.09492074,1.129024,99.99651
37.32916,786.046,4.7922,-44.87641,0.08957035,1.066052,99.96936
37.4125,787.7044,4.79148,-45.15218,0.0840459,1.000928,100.0263
37.49584,789.3594,4.79064,-45.4328,0.07839966,0.9342691,99.94254
37.57916,791.0216,4.789637,-45.71356,0.07274116,0.8673805,100.0198
37.6625,792.68,4.78882,-46.00843,0.06675468,0.7964936,99.98452
37.74584,794.339,4.788156,-46.30626,0.06068945,0.7245778,99.96603
37.82916,795.9989,4.78767,-46.61346,0.05440388,0.649937,100.0003
37.9125,797.66,4.786934,-46.92658,0.0479731,0.5734656,99.98931
37.99584,799.3218,4.786267,-47.23489,0.04163128,0.4979625,99.99769
38.07916,800.9785,4.785634,-47.52141,0.03574115,0.4277724,99.95584
38.1625,802.6406,4.784004,-47.79926,0.0300227,0.3595515,99.99708
38.24584,804.2982,4.783072,-48.05697,0.02471819,0.2962068,100.003
38.32916,805.96,4.782497,-48.28884,0.0199552,0.2392768,99.9712
38.4125,807.6238,4.781886,-48.51434,0.01530832,0.18367,99.94672
38.49584,809.2838,4.781287,-48.72813,0.01089044,0.1307438,100.0053
38.57916,810.945,4.780774,-48.93716,0.006555581,0.0787496,99.96174
38.6625,812.6052,4.780111,-49.1309,0.002527445,0.03037838,100.0045
38.74584,814.2645,4.779445,-49.3286,-1.61E-03,-0.01932222,99.98341
38.82916,815.9278,4.77897,-49.50571,-5.32E-03,-0.06399473,100.0161
38.9125,817.5856,4.778386,-49.69683,-9.35E-03,-0.1126014,99.97332
38.99584,819.2491,4.777818,-49.88609,-0.01335881,-0.1609749,99.99442
39.07916,820.9122,4.777206,-50.06962,-0.01726394,-0.2081586,99.97961
39.1625,822.5735,4.77669,-50.25383,-0.0212007,-0.255782,99.99422
39.24584,824.232,4.776112,-50.43598,-0.02510979,-0.3031289,99.9928
39.32916,825.8934,4.775666,-50.62802,-0.02924395,-0.3532527,100.0324
39.4125,827.554,4.775059,-50.8256,-0.03350928,-0.4050224,99.95226
39.49584,829.2156,4.774607,-51.01766,-0.03766944,-0.4555829,100.0284
39.57916,830.877,4.77405,-51.2132,-0.04191547,-0.507245,99.99322
39.6625,832.5369,4.77357,-51.42334,-0.04648162,-0.5628454,99.97269
39.74584,834.2001,4.77305,-51.61375,-0.05063722,-0.613539,99.96972
39.82916,835.8589,4.772553,-51.83422,-0.05543924,-0.6721301,100.0104
39.9125,837.5197,4.772037,-52.035,-0.05982979,-0.7257971,100.0107
39.99584,839.1816,4.771492,-52.23887,-0.06429208,-0.7803984,100.0055
40.07916,840.8415,4.771028,-52.45839,-0.06908881,-0.8391262,99.99082
40.1625,842.5026,4.770474,-52.66538,-0.07362431,-0.8947494,99.99509
40.24584,844.1639,4.770029,-52.8859,-0.07844691,-0.9539306,100.0122
40.32916,845.8238,4.769516,-53.09503,-0.08303053,-1.010274,100.0018
40.4125,847.4856,4.769024,-53.30289,-0.08758699,-1.066353,99.975
40.49584,849.143,4.768555,-53.51284,-0.09218639,-1.123022,99.98341
40.57916,850.8011,4.768116,-53.73074,-0.09694995,-1.181759,99.99082
40.6625,852.4614,4.767598,-53.93812,-0.1014883,-1.237818,99.98369
40.74584,854.1207,4.76719,-54.15646,-0.1062509,-1.296681,99.99399
40.82916,855.7851,4.766818,-54.36711,-0.1108448,-1.353553,99.989
40.9125,857.4447,4.766321,-54.58489,-0.115581,-1.412232,99.99774
40.99584,859.1056,4.765884,-54.79739,-0.1201976,-1.469517,99.98353
41.07916,860.7655,4.765321,-55.00486,-0.1246989,-1.525459,99.99278
41.1625,862.4259,4.764798,-55.20994,-0.129138,-1.580706,100.0292
41.24584,864.0897,4.764504,-55.43325,-0.1339428,-1.640495,99.97795
41.32916,865.7486,4.76402,-55.63707,-0.1383286,-1.69522,100.0043
41.4125,867.4074,4.76368,-55.84623,-0.1428104,-1.751187,99.99813
41.49584,869.0691,4.763196,-56.0518,-0.1471987,-1.806073,100.0487
41.57916,870.7309,4.762634,-56.2491,-0.1513974,-1.858693,99.98861
41.6625,872.3919,4.76218,-56.43902,-0.1554238,-1.90926,100.0071
41.74584,874.0531,4.761776,-56.64498,-0.159761,-1.963704,100.006
41.82916,875.7144,4.761232,-56.8448,-0.1639478,-2.016363,100.0103
41.9125,877.3749,4.760816,-57.04734,-0.1681683,-2.069484,100.0024
41.99584,879.0347,4.760541,-57.24924,-0.1723514,-2.122192,100.0194
42.07916,880.6947,4.759976,-57.44442,-0.1763687,-2.172918,99.99199
42.1625,882.3556,4.759473,-57.6414,-0.1803942,-2.223801,99.97519
42.24584,884.0161,4.758978,-57.84582,-0.1845433,-2.276266,100.023
42.32916,885.6744,4.758489,-58.05151,-0.1886874,-2.328728,99.98258
42.4125,887.3387,4.758032,-58.2346,-0.1923329,-2.375093,100.0044
42.49584,888.9984,4.757492,-58.43408,-0.1962823,-2.425265,100.0514
42.57916,890.6581,4.756982,-58.62615,-0.2000446,-2.47318,100.001
42.6625,892.3194,4.756492,-58.81655,-0.2037357,-2.52027,100.0173
42.74584,893.9799,4.75591,-59.01168,-0.2074843,-2.568122,100.0222
42.82916,895.6414,4.755565,-59.2139,-0.2113366,-2.617314,100.0167
42.9125,897.3003,4.75509,-59.41294,-0.2150836,-2.665259,99.98551
42.99584,898.962,4.75463,-59.60002,-0.218545,-2.709732,100.0111
43.07916,900.6236,4.754185,-59.80695,-0.2223594,-2.75863,100.0008
43.1625,902.2835,4.753709,-60.01461,-0.2261473,-2.807259,99.99945
43.24584,903.9475,4.75318,-60.21634,-0.2297653,-2.853832,100.0367
43.32916,905.6112,4.752724,-60.4231,-0.2334402,-2.901164,100.0013
43.4125,907.2679,4.752134,-60.63467,-0.237172,-2.949256,100.0487
43.49584,908.9305,4.751481,-60.84065,-0.2407405,-2.995371,100.0346
43.57916,910.5934,4.75123,-61.05541,-0.2444384,-3.043146,100.0022
43.6625,912.2539,4.750738,-61.2793,-0.2482756,-3.092713,100.0483
43.74584,913.9124,4.750168,-61.4959,-0.251923,-3.139968,99.98809
43.82916,915.5732,4.749688,-61.72043,-0.2556799,-3.188643,100.0143
43.9125,917.2363,4.749116,-61.95139,-0.2595158,-3.23835,100.0094
43.99584,918.8968,4.74864,-62.16257,-0.2629211,-3.282706,99.9803
44.07916,920.5558,4.748154,-62.38684,-0.2665418,-3.329797,99.99026
44.1625,922.2172,4.747652,-62.61547,-0.2702002,-3.37741,99.97469
44.24584,923.8776,4.747052,-62.8513,-0.2739554,-3.426284,100.0258
44.32916,925.5366,4.74646,-63.07869,-0.2775018,-3.472601,99.9835
44.4125,927.1999,4.746011,-63.30478,-0.280974,-3.518039,99.96868
44.49584,928.8618,4.745424,-63.52899,-0.284367,-3.562536,100.0089
44.57916,930.5226,4.744964,-63.76708,-0.2879876,-3.609933,99.96821
44.6625,932.1842,4.744444,-63.99976,-0.291457,-3.655485,99.96518
44.74584,933.8469,4.743836,-64.22616,-0.2947591,-3.698984,99.97457
44.82916,935.5062,4.743256,-64.45907,-0.2981487,-3.743632,99.98968
44.9125,937.1655,4.74269,-64.71132,-0.3018684,-3.792474,100.0105
44.99584,938.8276,4.742116,-64.9474,-0.305228,-3.836841,99.99863
45.07916,940.4897,4.741412,-65.20113,-0.3088833,-3.884978,99.98059
45.1625,942.1512,4.740865,-65.45338,-0.3124664,-3.932256,100.0241
45.24584,943.8101,4.740243,-65.69918,-0.3158856,-3.977522,100.022
45.32916,945.4728,4.739674,-65.9408,-0.3191776,-4.021231,100.0099
45.4125,947.128,4.739152,-66.1978,-0.3227304,-4.068274,100.0473
45.49584,948.7863,4.738414,-66.46076,-0.3263475,-4.116179,100.0147
45.57916,950.4482,4.737859,-66.70832,-0.3296262,-4.159866,99.98209
45.6625,952.1094,4.73719,-66.9539,-0.3328281,-4.202629,100.0248
45.74584,953.7676,4.736611,-67.21222,-0.3362328,-4.248,100.0532
45.82916,955.4282,4.735944,-67.47022,-0.3395862,-4.292773,100.0057
45.9125,957.0898,4.735198,-67.72545,-0.342846,-4.336407,99.99965
45.99584,958.7508,4.734634,-67.98153,-0.346083,-4.379785,99.99126
46.07916,960.4088,4.733931,-68.23374,-0.3492169,-4.421891,100.0197
46.1625,962.0706,4.733418,-68.48765,-0.3523352,-4.463848,99.97088
46.24584,963.7334,4.732619,-68.74265,-0.355433,-4.505586,99.9711
46.32916,965.3947,4.731933,-69.006,-0.3586503,-4.548886,99.99491
46.4125,967.0549,4.731384,-69.27134,-0.361865,-4.592196,99.99034
46.49584,968.7166,4.730737,-69.54518,-0.365193,-4.636988,100.0128
46.57916,970.3784,4.73,-69.80953,-0.3683112,-4.679166,99.95884
46.6625,972.0399,4.729338,-70.07588,-0.3714274,-4.72136,100.0155
46.74584,973.6995,4.728588,-70.35469,-0.374735,-4.766032,100.0311
46.82916,975.3585,4.727876,-70.62191,-0.3777968,-4.807623,100.0055
46.9125,977.0179,4.727193,-70.89124,-0.3808582,-4.84925,99.99006
46.99584,978.6788,4.72657,-71.16759,-0.3840075,-4.892042,99.99774
47.07916,980.3384,4.725757,-71.4341,-0.3869473,-4.932208,99.99131
47.1625,981.9981,4.725053,-71.68982,-0.3896628,-4.969554,100.022
47.24584,983.6586,4.724309,-71.95194,-0.3924567,-5.007942,99.96861
47.32916,985.3219,4.723621,-72.22549,-0.3954111,-5.048417,99.99137
47.4125,986.9782,4.722812,-72.50122,-0.398385,-5.089183,99.99332
47.49584,988.6413,4.72208,-72.77716,-0.4013144,-5.12942,99.99285
47.57916,990.3001,4.72135,-73.05947,-0.4043311,-5.170818,99.96
47.6625,991.961,4.720466,-73.32431,-0.4070075,-5.207906,100.0094
47.74584,993.6259,4.71966,-73.58456,-0.4095672,-5.243541,99.99764
47.82916,995.2824,4.718587,-73.85242,-0.4122464,-5.28074,100.0192
47.9125,996.945,4.714754,-74.24419,-0.4169982,-5.344537,99.99949
47.99584,998.6074,4.713821,-74.50882,-0.4195426,-5.380086,100.0002
48.07916,1000.27,4.713076,-74.76926,-0.4219851,-5.414344,100.0112
48.1625,1001.931,4.712424,-75.03272,-0.42446,-5.449054,99.9703
48.24584,1003.593,4.711562,-75.29184,-0.4268277,-5.48242,100.0134
48.32916,1005.252,4.710676,-75.5514,-0.4291821,-5.515647,99.98428
48.4125,1006.917,4.709959,-75.80555,-0.4314054,-5.547222,100.0486
48.49584,1008.576,4.709186,-76.07253,-0.433832,-5.581444,99.99652
48.57916,1010.239,4.708254,-76.3231,-0.4359488,-5.611712,99.99172
48.6625,1011.903,4.707463,-76.59018,-0.4383113,-5.645179,100.0162
48.74584,1013.561,4.706637,-76.85929,-0.4406946,-5.67894,99.99384
48.82916,1015.222,4.705883,-77.11994,-0.4429031,-5.710482,100.0064
48.9125,1016.884,4.705026,-77.38794,-0.445203,-5.743232,99.98924
48.99584,1018.544,4.704218,-77.63689,-0.4471746,-5.771775,99.98403
49.07916,1020.205,4.703294,-77.90112,-0.4493698,-5.803207,99.97276
49.1625,1021.868,4.702516,-78.1571,-0.4514007,-5.832545,100.0193
49.24584,1023.528,4.701656,-78.4297,-0.4536832,-5.86516,100.0227
49.32916,1025.19,4.700833,-78.69266,-0.4557793,-5.8954,100.0064
49.4125,1026.855,4.699882,-78.9541,-0.4578236,-5.925003,100.0135
49.49584,1028.515,4.6991,-79.19994,-0.4596067,-5.95125,100.0025
49.57916,1030.181,4.698215,-79.43978,-0.4612581,-5.975816,100.005
49.6625,1031.843,4.697281,-79.6755,-0.4628347,-5.999438,100.0103
49.74584,1033.504,4.696386,-79.93081,-0.4647,-6.026826,100.0486
49.82916,1035.168,4.695547,-80.20041,-0.466761,-6.056778,100.01
49.9125,1036.828,4.694682,-80.4437,-0.4684008,-6.081294,99.98434
49.99584,1038.493,4.693741,-80.70214,-0.4702398,-6.108418,99.99457
50.07916,1040.154,4.692746,-80.94319,-0.4717982,-6.13192,100.0388
50.1625,1041.817,4.691844,-81.20728,-0.4736889,-6.159766,99.98225
50.24584,1043.477,4.690908,-81.45778,-0.475356,-6.184726,100.0069
50.32916,1045.141,4.690033,-81.69741,-0.4768261,-6.207149,99.99988
50.4125,1046.801,4.689071,-81.96308,-0.4786852,-6.23466,100.0251
50.49584,1048.463,4.688139,-82.21485,-0.4803094,-6.259134,100.0156
50.57916,1050.126,4.687204,-82.46343,-0.4818626,-6.282708,100.0291
50.6625,1051.789,4.686206,-82.71661,-0.4834694,-6.307005,99.99094
50.74584,1053.447,4.685297,-82.96284,-0.484964,-6.329858,99.99859
50.82916,1055.112,4.684306,-83.19746,-0.486249,-6.349994,100.0282
50.9125,1056.774,4.68336,-83.44581,-0.4877312,-6.372726,99.98869
50.99584,1058.437,4.682394,-83.67688,-0.4889412,-6.391871,99.98788
51.07916,1060.097,4.68137,-83.9167,-0.4902932,-6.412623,100.0306
51.1625,1061.758,4.680352,-84.15416,-0.4915962,-6.432715,100.0125
51.24584,1063.422,4.67937,-84.39951,-0.49299,-6.454011,100.0006
51.32917,1065.082,4.678451,-84.62666,-0.4941154,-6.471809,99.96545
51.4125,1066.743,4.677403,-84.84179,-0.4950522,-6.487149,99.97566
51.49584,1068.408,4.676422,-85.06197,-0.4960412,-6.503193,99.98472
51.57917,1070.073,4.675414,-85.29781,-0.4972474,-6.522098,100.0125
51.6625,1071.735,4.674348,-85.52368,-0.4983014,-6.539013,99.99676
51.74584,1073.399,4.673379,-85.77918,-0.4997618,-6.561282,100.0187
51.82917,1075.063,4.672394,-86.02636,-0.5010914,-6.58185,99.97482
51.9125,1076.726,4.671428,-86.26464,-0.5022829,-6.600622,99.99986
51.99584,1078.388,4.670229,-86.50344,-0.5034781,-6.619419,99.97969
52.07917,1080.051,4.669212,-86.71699,-0.504317,-6.633329,100.0157
52.1625,1081.712,4.668256,-86.96222,-0.5055981,-6.653034,99.98978
52.24584,1083.375,4.667153,-87.17705,-0.5064404,-6.666975,99.9796
52.32917,1085.038,4.666085,-87.40516,-0.507459,-6.683249,100.0094
52.4125,1086.699,4.664984,-87.61876,-0.5082739,-6.696848,99.99647
52.49584,1088.362,4.663966,-87.81431,-0.5088272,-6.707008,99.97492
52.57918,1090.026,4.662973,-87.85109,-0.509528,-6.719125,100.0119
52.6625,1091.689,4.66175,-88.00695,-0.5097031,-6.724312,100.0075
52.74584,1093.353,4.660766,-88.1508,-0.509672,-6.726782,100.0417
52.82918,1095.02,4.659634,-88.31062,-0.5098592,-6.73213,100.0084
52.9125,1096.683,4.658512,-88.42657,-0.5094467,-6.729563,99.99872
52.99584,1098.349,4.6575,-88.53726,-0.5089622,-6.726022,100.0221
53.07918,1100.014,4.656406,-88.6158,-0.5080502,-6.7167,100.0182
53.1625,1101.68,4.65528,-88.70169,-0.50724,-6.708692,99.99082
53.24584,1103.346,4.65418,-88.77496,-0.5062578,-6.698402,99.99228
53.32918,1105.015,4.653026,-88.81739,-0.5048556,-6.682544,99.98918
53.4125,1106.682,4.651822,-88.8118,-0.5027992,-6.65801,100.0147
53.49584,1108.349,4.65074,-88.78445,-0.5004503,-6.629576,100.0313
53.57918,1110.02,4.649582,-88.73072,-0.4977429,-6.596368,100.0232
53.6625,1111.687,4.64848,-88.65253,-0.4947055,-6.558756,99.99932
53.74584,1113.352,4.64727,-88.55702,-0.491436,-6.518031,99.97019
53.82918,1115.019,4.646074,-88.45868,-0.48813,-6.476788,99.98257
53.9125,1116.69,4.64491,-88.30766,-0.4841111,-6.426049,100.0153
53.99584,1118.358,4.643772,-88.14028,-0.479874,-6.372348,99.99676
54.07918,1120.028,4.64251,-87.94726,-0.4753036,-6.314026,99.9683
54.1625,1121.696,4.641346,-87.74481,-0.47061,-6.254,100.0028
54.24584,1123.364,4.640166,-87.51618,-0.4655656,-6.189262,99.98276
54.32918,1125.034,4.638947,-87.26132,-0.4601694,-6.119794,99.99764
54.4125,1126.704,4.637903,-86.99285,-0.4545908,-6.047851,100.0199
54.49584,1128.371,4.636664,-86.71613,-0.4489058,-5.974434,99.99518
54.57918,1130.045,4.635468,-86.45859,-0.4434836,-5.904464,100.0342
54.6625,1131.716,4.634374,-86.2337,-0.4385067,-5.84037,100.004
54.74584,1133.385,4.633218,-86.06624,-0.4343116,-5.78664,99.97369
54.82918,1135.052,4.63212,-85.99457,-0.431416,-5.750191,100.0206
54.9125,1136.719,4.630934,-86.06412,-0.4304326,-5.73921,100.0112
54.99584,1138.386,4.629832,-86.3088,-0.4318206,-5.759824,99.94816
55.07918,1140.051,4.628678,-86.7322,-0.435632,-5.812656,100.0177
55.1625,1141.711,4.627441,-87.33103,-0.4418152,-5.897152,99.99571
55.24584,1143.371,4.626106,-88.01884,-0.4491985,-5.997729,99.98043
55.32918,1145.029,4.625066,-88.67988,-0.4562171,-6.093495,100.0141
55.4125,1146.687,4.623851,-89.30781,-0.462785,-6.183304,99.95801
55.49584,1148.342,4.622722,-89.92059,-0.469146,-6.270402,100.0034
55.57918,1150.003,4.6215,-90.51956,-0.4753128,-6.354969,99.98039
55.6625,1151.662,4.620259,-91.11955,-0.4814894,-6.43972,99.99316
55.74584,1153.32,4.619044,-91.75688,-0.4881672,-6.53123,100.0018
55.82918,1154.978,4.617862,-92.42401,-0.4952398,-6.628087,99.99703
55.9125,1156.636,4.616704,-93.06382,-0.501941,-6.720032,99.99819
55.99584,1158.294,4.615326,-93.63091,-0.5076617,-6.79889,99.98004
56.07918,1159.954,4.61417,-94.10488,-0.5121332,-6.86094,99.97532
56.1625,1161.612,4.61305,-94.46387,-0.5150569,-6.902262,99.98066
56.24584,1163.269,4.611783,-94.73703,-0.5168254,-6.928124,99.99642
56.32918,1164.93,4.61058,-94.95176,-0.5178059,-6.943432,99.99881
56.4125,1166.591,4.609287,-95.11126,-0.5180424,-6.948774,100.0127
56.49584,1168.252,4.608233,-95.2442,-0.5179199,-6.9493,100.0171
56.57918,1169.914,4.606957,-95.37931,-0.5178264,-6.950218,99.98695
56.6625,1171.576,4.605744,-95.55474,-0.518274,-6.958398,100.0273
56.74584,1173.243,4.604668,-95.77098,-0.519267,-6.973909,100.0032
56.82918,1174.904,4.603357,-96.01212,-0.5205951,-6.99393,100.0198
56.9125,1176.565,4.602187,-96.2833,-0.5223269,-7.019384,100.0229
56.99584,1178.227,4.601026,-96.57799,-0.524372,-7.04905,99.99328
57.07918,1179.891,4.599676,-96.89275,-0.5266985,-7.082356,99.9866
57.1625,1181.554,4.598539,-97.24828,-0.5295706,-7.122984,99.98731
57.24584,1183.213,4.597338,-97.58722,-0.5322216,-7.160656,100.0032
57.32918,1184.872,4.596145,-97.92324,-0.5348334,-7.197821,100.0229
57.4125,1186.535,4.594966,-98.26092,-0.5374645,-7.235266,100.0034
57.49584,1188.197,4.593666,-98.56842,-0.5396909,-7.267278,99.9935
57.57918,1189.648,4.59243,-99.05125,-0.5443366,-7.331819,99.99444
57.6625,1190.674,4.591113,-101.5118,-0.5758616,-7.758053,100.0009
57.74584,1191.359,4.589693,-106.6604,-0.6437693,-8.674151,100.0146
57.82918,1191.79,4.58844,-113.3534,-0.732668,-9.872881,99.98906
57.9125,1192.056,4.58709,-120.3358,-0.8256658,-11.12669,99.98024
57.99584,1192.227,4.585657,-126.7328,-0.9109754,-12.27676,100.0134
58.07918,1192.364,4.584491,-132.0692,-0.9821675,-13.23652,99.99547
58.1625,1192.486,4.583384,-136.2376,-1.037765,-13.98609,100.0041
58.24584,1192.613,4.582112,-139.3648,-1.079439,-14.54804,100.0348
58.32918,1192.741,4.580917,-141.6654,-1.11005,-14.96093,100.0011
58.4125,1192.884,4.579788,-143.3502,-1.132416,-15.26271,99.98876
58.49584,1193.026,4.578652,-144.6099,-1.149087,-15.48778,99.98206
58.57918,1193.17,4.577488,-145.576,-1.161826,-15.65986,100.0292
58.6625,1193.32,4.57642,-146.3783,-1.172373,-15.80241,100.0359
58.74584,1193.467,4.575183,-147.0747,-1.181503,-15.92588,99.98281
58.82918,1193.611,4.5741,-147.7065,-1.189771,-16.03771,100.0047
58.9125,1193.752,4.57306,-148.3241,-1.197852,-16.14702,99.95884
58.99584,1193.884,4.571934,-148.9366,-1.205869,-16.25548,99.99584
59.07918,1194.018,4.570838,-149.5287,-1.213618,-16.36031,99.96647
59.1625,1194.146,4.569717,-150.1,-1.221095,-16.46146,100.0071
59.24584,1194.269,4.568574,-150.6733,-1.228602,-16.56302,99.99006
59.32918,1194.389,4.567582,-151.2439,-1.236079,-16.66416,99.99168
59.4125,1194.504,4.566591,-151.7904,-1.243238,-16.76102,100.0078
59.49584,1194.616,4.565465,-152.3185,-1.250157,-16.85461,99.96912
59.57918,1194.721,4.564444,-152.8419,-1.257018,-16.94742,100.0023
59.6625,1194.828,4.563391,-153.368,-1.263916,-17.04074,100.0214
59.74584,1194.928,4.562431,-153.8623,-1.270398,-17.12842,100.0303
59.82918,1195.025,4.561448,-154.335,-1.276591,-17.21221,100.0042
59.9125,1195.121,4.560382,-154.8008,-1.282696,-17.29481,99.9889
59.99584,1195.214,4.559376,-155.2434,-1.288496,-17.37327,100.0048
60.07918,1195.301,4.558222,-155.6651,-1.294018,-17.448,99.99639
60.1625,1195.389,4.557266,-156.0812,-1.299469,-17.52176,100.0124
60.24584,1195.474,4.556322,-156.4719,-1.304584,-17.59099,99.98964
60.32918,1195.56,4.555444,-156.8446,-1.30946,-17.65698,100.01
60.4125,1195.637,4.554195,-157.2099,-1.31424,-17.72168,100.0305
60.49584,1195.716,4.55334,-157.5815,-1.319107,-17.78755,99.99055
60.57918,1195.791,4.55245,-157.9373,-1.323766,-17.8506,100.0243
60.6625,1195.863,4.551389,-158.2796,-1.328249,-17.91127,99.98832
60.74584,1195.936,4.550543,-158.6114,-1.33259,-17.97003,99.96352
60.82918,1196.006,4.549484,-158.9278,-1.33673,-18.02608,100.0128
60.9125,1196.073,4.548609,-159.2375,-1.340782,-18.08094,99.97618
60.99584,1196.141,4.547578,-159.5243,-1.344529,-18.13167,99.99955
61.07918,1196.204,4.546738,-159.8041,-1.348186,-18.1812,99.98915
61.1625,1196.267,4.545833,-160.0656,-1.351601,-18.22744,99.97364
61.24584,1196.327,4.544669,-160.3258,-1.355001,-18.27348,100.0097
61.32918,1196.388,4.543834,-160.578,-1.358294,-18.31807,99.96069
61.4125,1196.442,4.543018,-160.8433,-1.361764,-18.36506,100.0346
61.49584,1196.502,4.542086,-161.1082,-1.365232,-18.412,99.96806
61.57918,1196.558,4.541224,-161.3496,-1.368388,-18.45474,99.96786
61.6625,1196.61,4.540402,-161.5812,-1.371414,-18.49572,100.0078
61.74584,1196.663,4.53943,-161.8142,-1.374461,-18.53697,99.99395
61.82918,1196.714,4.538547,-162.0307,-1.377289,-18.57527,99.96275
61.9125,1196.762,4.537665,-162.2436,-1.380071,-18.61296,99.98566
61.99584,1196.808,4.536742,-162.4489,-1.382754,-18.64929,99.9937
62.07918,1196.854,4.535916,-162.6471,-1.385343,-18.68436,99.99508
62.1625,1196.898,4.535059,-162.8329,-1.387769,-18.71722,99.99069
62.24584,1196.941,4.53419,-163.0244,-1.39027,-18.75109,100.0154
62.32918,1196.985,4.533336,-163.2146,-1.392755,-18.78476,100.0313
62.4125,1197.029,4.532486,-163.3941,-1.395099,-18.81649,99.99403
62.49584,1197.07,4.531576,-163.5679,-1.397368,-18.84724,100.0134
62.50416,1197.077,4.5315,-163.5837,-1.397574,-18.85003,100.0387