File: examples/pyrolysis/single_element/1D/gold/experiment_comp/5degpermin_run1.csv
Time (min),Temperature (degC),Weight (mg),Heat Flow (mW),Temperature Difference (degC),Temperature Difference (muV),Sample Purge Flow (mL/min)
8.89E-04,50.68204,11.48794,-7.30787,-0.02548738,-0.1234582,199.6638
0.2458334,50.4212,11.48606,-7.304785,-0.0259289,-0.1254797,99.9907
0.4958334,50.3053,11.48621,-7.281172,-0.0232354,-0.1123863,100.0042
0.7458334,50.47858,11.48645,-7.270278,-0.0214055,-0.1035771,100.0074
0.9958332,51.0011,11.4869,-7.309492,-0.02518114,-0.1220451,100.0019
1.245833,51.89329,11.4871,-7.407556,-0.0356558,-0.1733107,99.983
1.495833,53.09084,11.48744,-7.5685,-0.05341305,-0.260654,99.98914
1.745833,54.50632,11.48771,-7.769179,-0.07551085,-0.3702478,99.99445
1.995833,56.04262,11.48766,-7.984438,-0.09885059,-0.4872201,99.98338
2.245834,57.62658,11.48759,-8.197712,-0.1214993,-0.602076,99.98664
2.495834,59.18357,11.4873,-8.386876,-0.1407876,-0.7013774,99.99074
2.745834,60.67888,11.48715,-8.549322,-0.1566546,-0.784215,99.98634
2.995834,62.07859,11.48673,-8.673374,-0.167744,-0.8433826,100.0259
3.245834,63.39482,11.48626,-8.766631,-0.1751058,-0.8839585,100.0243
3.495834,64.63026,11.48589,-8.826978,-0.1784637,-0.9043289,99.98961
3.745834,65.80364,11.48527,-8.858819,-0.1783686,-0.9070976,99.98043
3.995834,66.94343,11.48475,-8.874632,-0.176367,-0.9000292,99.98891
4.245834,68.06794,11.48428,-8.884992,-0.1737634,-0.8897499,99.9978
4.495834,69.20422,11.48391,-8.886444,-0.1700156,-0.8735291,100.0337
4.741667,70.33716,11.48348,-8.887924,-0.1662993,-0.8573374,100.0122
4.991667,71.5212,11.48278,-8.894788,-0.1631191,-0.843911,100.0013
5.241667,72.73425,11.4822,-8.904718,-0.1602467,-0.832038,100.0087
5.491668,73.98386,11.4817,-8.926836,-0.1587772,-0.827468,100.0091
5.741668,75.25356,11.48118,-8.949147,-0.1572689,-0.8226906,100.0032
5.9875,76.5256,11.48061,-8.978818,-0.1566746,-0.82266,100.002
6.2375,77.82864,11.47996,-9.005891,-0.1556534,-0.8204351,100.0224
6.4875,79.13145,11.47926,-9.035197,-0.1549302,-0.8196632,99.98658
6.7375,80.43407,11.47851,-9.056282,-0.153235,-0.8135131,99.99838
6.9875,81.71914,11.47762,-9.077518,-0.1516074,-0.8076355,99.97888
7.2375,82.9997,11.47695,-9.09423,-0.1494718,-0.7989634,99.99122
7.4875,84.2635,11.47604,-9.106124,-0.1468226,-0.7874242,99.9767
7.7375,85.51792,11.47523,-9.114255,-0.1437528,-0.7735163,99.96639
7.9875,86.76322,11.47434,-9.118097,-0.1402215,-0.756987,99.99084
8.2375,88.00842,11.47348,-9.11925,-0.1363951,-0.7387328,100.032
8.4875,89.25245,11.47247,-9.121459,-0.1327337,-0.7212314,99.99624
8.7375,90.48961,11.47144,-9.119003,-0.1285372,-0.7006855,99.99239
8.9875,91.73944,11.47056,-9.12225,-0.1250342,-0.6837915,100.0071
9.2375,92.98301,11.46948,-9.127892,-0.1218341,-0.6684382,100.0201
9.4875,94.23201,11.46854,-9.126476,-0.1178121,-0.648453,100.0267
9.7375,95.48338,11.46716,-9.12868,-0.1142276,-0.6307492,100.0077
9.9875,96.74364,11.46637,-9.134474,-0.1110797,-0.6153404,99.98762
10.2375,98.00792,11.46526,-9.140918,-0.1080287,-0.6002912,99.99516
10.48333,99.24809,11.46413,-9.143691,-0.1046415,-0.5831372,99.99939
10.73334,100.5145,11.46285,-9.149994,-0.1016154,-0.5679239,100.0004
10.98334,101.7754,11.46162,-9.152656,-0.09820682,-0.550459,99.99276
11.23334,103.0383,11.4605,-9.158074,-0.09512268,-0.5347137,99.99696
11.48334,104.2974,11.4591,-9.166074,-0.0923722,-0.520741,100.0141
11.72917,105.5301,11.45757,-9.169278,-0.08915481,-0.5040138,100.002
11.97917,106.7857,11.45636,-9.173022,-0.08596938,-0.4873837,100.0286
12.22917,108.04,11.45501,-9.174262,-0.08250553,-0.4690726,100.0386
12.47917,109.2942,11.45367,-9.180347,-0.07962031,-0.4539469,100.0048
12.72917,110.5445,11.45224,-9.181806,-0.07624516,-0.4359204,100.0133
12.97917,111.7991,11.45078,-9.186328,-0.07322585,-0.41983,99.98795
13.22917,113.0544,11.44929,-9.190561,-0.07018838,-0.403539,100.0243
13.47917,114.3113,11.44791,-9.197174,-0.06744187,-0.3888265,100.0268
13.72917,115.5606,11.44628,-9.20562,-0.06491542,-0.3752983,99.99145
13.97917,116.8143,11.44481,-9.207235,-0.06166008,-0.3574244,99.99408
14.22917,118.0686,11.4432,-9.212053,-0.05878454,-0.3416114,99.98211
14.47917,119.3248,11.44167,-9.212296,-0.05541089,-0.3228131,99.99181
14.72917,120.5839,11.44013,-9.220981,-0.0529811,-0.3094322,99.99813
14.97917,121.8428,11.43841,-9.229709,-0.05058258,-0.29616,99.97766
15.22917,123.0988,11.43682,-9.235856,-0.04791853,-0.2812576,99.95531
15.47917,124.3476,11.43496,-9.243946,-0.04548436,-0.2676302,100.0262
15.72917,125.6022,11.43332,-9.248562,-0.04268913,-0.2518004,100.0044
15.97917,126.8602,11.43159,-9.255172,-0.04012778,-0.2372726,99.99016
16.225,128.0912,11.42994,-9.261512,-0.03761111,-0.2229256,100.0112
16.475,129.3477,11.4282,-9.266578,-0.03491061,-0.2074234,99.99216
16.725,130.5996,11.42641,-9.273149,-0.03239868,-0.1929649,99.97778
16.975,131.854,11.42459,-9.282299,-0.03018476,-0.1802124,99.99918
17.225,133.1081,11.42294,-9.290191,-0.0278398,-0.166613,100.0077
17.47083,134.343,11.42097,-9.293225,-0.02504425,-0.1502351,100.0344
17.72083,135.5911,11.41922,-9.296309,-0.02222353,-0.1336269,100.0035
17.97083,136.8481,11.41731,-9.303282,-0.01983674,-0.1195343,99.98384
18.22083,138.1063,11.41543,-9.310863,-0.01752518,-0.1058338,99.99049
18.47083,139.3606,11.41366,-9.316822,-0.01506268,-0.09115912,99.96437
18.72083,140.6089,11.41173,-9.323636,-0.01270744,-0.07706978,99.99016
18.97083,141.8658,11.40983,-9.330045,-0.01031941,-0.0627204,99.97339
19.22083,143.1195,11.4079,-9.337589,-8.07E-03,-0.0491378,99.99268
19.47083,144.3737,11.40603,-9.344766,-5.79E-03,-0.03536714,99.95916
19.72083,145.6256,11.40392,-9.355793,-3.95E-03,-0.02414596,99.99038
19.97083,146.8828,11.40202,-9.360303,-1.42E-03,-8.68E-03,99.97832
20.22083,148.1335,11.40012,-9.362792,0.00130543,0.008018851,100.0039
20.47083,149.3897,11.39801,-9.367264,0.00381443,0.02347889,99.98395
20.72083,150.6489,11.39616,-9.373931,0.00606806,0.03742871,100.0201
20.97083,151.8995,11.39412,-9.382064,0.008149075,0.05036864,99.97364
21.22083,153.156,11.3923,-9.386991,0.01055526,0.06537554,99.99468
21.47083,154.408,11.39009,-9.393194,0.01280941,0.07950007,100.0279
21.72083,155.6541,11.38821,-9.397351,0.01525517,0.09486191,99.9942
21.97083,156.9111,11.386,-9.406495,0.01717758,0.1070162,99.95618
22.21667,158.1413,11.3842,-9.407984,0.01983856,0.1238214,100.0201
22.46667,159.3938,11.38219,-9.41658,0.02178684,0.1362336,99.98632
22.71667,160.6483,11.38017,-9.422919,0.02396018,0.1501011,99.99512
22.96667,161.8983,11.37812,-9.4285,0.02619037,0.1643741,99.98993
23.2125,163.1272,11.37614,-9.436519,0.0281174,0.1767876,100.0139
23.4625,164.3789,11.37406,-9.445822,0.02994375,0.1886149,99.98324
23.7125,165.6388,11.37215,-9.45061,0.03223265,0.2034039,99.96712
23.9625,166.8901,11.36996,-9.456818,0.03435495,0.2171907,99.97338
24.2125,168.142,11.36806,-9.469879,0.03576285,0.2265011,99.99914
24.4625,169.3875,11.36607,-9.469708,0.03851043,0.244342,99.96688
24.7125,170.6414,11.36423,-9.480803,0.04009209,0.2548342,100.0004
24.9625,171.8981,11.36216,-9.492572,0.04160198,0.2649059,100.003
25.2125,173.1474,11.3601,-9.491251,0.04443145,0.2834282,100.0334
25.4625,174.3997,11.35816,-9.498269,0.04639831,0.2965016,99.96595
25.7125,175.6543,11.35623,-9.504455,0.04844202,0.3100826,100.0355
25.9625,176.9002,11.35402,-9.510313,0.05051714,0.3238901,100.0112
26.2125,178.153,11.3523,-9.520256,0.05216482,0.3349941,100.0354
26.4625,179.408,11.3504,-9.530255,0.05380421,0.346079,99.99921
26.7125,180.6581,11.34834,-9.534141,0.05604084,0.361043,99.9945
26.9625,181.9112,11.34636,-9.53765,0.05831387,0.3762894,100.024
27.2125,183.1628,11.34447,-9.54688,0.0599952,0.3877559,100.0286
27.4625,184.4178,11.34252,-9.554352,0.06184924,0.4003755,99.98772
27.7125,185.668,11.3405,-9.559055,0.06397305,0.414782,100.0061
27.95833,186.9021,11.33876,-9.568381,0.06557947,0.4258597,99.98976
28.20833,188.1533,11.33682,-9.575838,0.06740493,0.4384046,99.99545
28.45833,189.4043,11.3351,-9.58184,0.06936186,0.4518409,99.98491
28.70833,190.6526,11.33306,-9.592344,0.07086578,0.4623621,99.98547
28.95416,191.8824,11.33126,-9.597949,0.0728089,0.4757716,99.9778
29.20416,193.1351,11.32937,-9.604816,0.07465657,0.4886056,100.0036
29.45416,194.384,11.32751,-9.609816,0.07668015,0.5026303,99.99409
29.70416,195.6406,11.32563,-9.618637,0.07832476,0.5141988,99.98561
29.95416,196.89,11.32375,-9.620018,0.08069934,0.5305426,99.95118
30.20416,198.1442,11.32198,-9.628295,0.08239066,0.5424338,100.0074
30.45416,199.3952,11.32008,-9.63438,0.08428749,0.5557098,99.97095
30.70416,200.648,11.31846,-9.641226,0.08679566,0.5730557,100.0105
30.95416,201.8984,11.31654,-9.640742,0.08885965,0.587513,100.0162
31.20416,203.1535,11.31475,-9.640241,0.09090119,0.6018605,100.0053
31.45416,204.4047,11.31286,-9.643999,0.09248644,0.6132185,99.97901
31.70416,205.6544,11.31103,-9.639576,0.0948204,0.6295768,99.9928
31.95416,206.9099,11.30936,-9.639941,0.09668921,0.642884,100.0004
32.20416,208.1639,11.30746,-9.634582,0.09906665,0.6596118,100.003
32.45416,209.416,11.30574,-9.634757,0.1008794,0.6726213,99.97997
32.70416,210.6675,11.30394,-9.635832,0.1025924,0.6849951,100.0395
32.95416,211.9236,11.30226,-9.625164,0.1053904,0.7046553,99.9753
33.20416,213.1738,11.30034,-9.623186,0.1073396,0.718684,100.0236
33.45416,214.4288,11.29857,-9.613881,0.1099623,0.7372615,100.0318
33.7,215.6571,11.29682,-9.606738,0.1123151,0.7540603,99.99661
33.95,216.9092,11.29492,-9.598672,0.1147818,0.7716431,99.98878
34.2,218.1608,11.29311,-9.597384,0.1166226,0.7850147,99.97296
34.45,219.4158,11.29124,-9.588797,0.119125,0.8028735,99.98751
34.7,220.6638,11.28931,-9.58355,0.1212898,0.8185015,100.001
34.94584,221.8989,11.28752,-9.58103,0.1232007,0.8324295,99.99086
35.19584,223.1462,11.28552,-9.576806,0.1252662,0.8474512,99.96697
35.44584,224.3989,11.28379,-9.572681,0.1273278,0.8624847,100.018
35.69584,225.6492,11.28166,-9.56741,0.1294869,0.8782094,99.99616
35.94584,226.9012,11.27972,-9.563108,0.1315595,0.8933859,99.9912
36.19584,228.1553,11.27782,-9.563976,0.1331871,0.9055712,99.95452
36.44584,229.4017,11.27588,-9.567255,0.1345953,0.9162891,99.98329
36.69584,230.6589,11.27363,-9.573297,0.1357938,0.9256032,100.0374
36.94584,231.9064,11.27158,-9.579809,0.1369442,0.9346062,99.96063
37.19584,233.158,11.26966,-9.59018,0.1377842,0.9415081,99.98149
37.44584,234.4083,11.26757,-9.602465,0.1384747,0.9473985,99.97124
37.69584,235.6548,11.2653,-9.623028,0.1384718,0.9485549,99.97876
37.94584,236.907,11.26309,-9.642048,0.1386322,0.9508308,99.97074
38.19584,238.1562,11.26087,-9.663761,0.1385918,0.9516712,100.0234
38.44584,239.4064,11.2587,-9.69215,0.1380236,0.9488466,99.99006
38.69584,240.6558,11.25641,-9.712257,0.1381716,0.9509451,99.99732
38.94584,241.9039,11.25416,-9.745274,0.1372687,0.9458022,100.0152
39.19584,243.1547,11.25173,-9.780047,0.1362551,0.9398822,100.0206
39.44166,244.3808,11.24938,-9.807356,0.1358509,0.9381375,99.97195
39.69166,245.6289,11.24705,-9.841116,0.1349769,0.9331559,99.99032
39.94166,246.8772,11.24461,-9.88355,0.1334234,0.9234553,99.98044
40.19166,248.122,11.24214,-9.928175,0.1317206,0.912696,100.0056
40.44166,249.3744,11.23954,-9.963202,0.1308463,0.9076606,99.98869
40.6875,250.6002,11.23701,-10.00759,0.1292018,0.8972444,100.0326
40.9375,251.8425,11.23431,-10.0554,0.1273408,0.8853097,99.97519
41.1875,253.0946,11.23144,-10.10201,0.1256281,0.8743852,99.99156
41.4375,254.3416,11.22894,-10.14966,0.1238599,0.8630436,99.99053
41.6875,255.5893,11.226,-10.19962,0.1219413,0.8506256,99.974
41.9375,256.8384,11.22328,-10.24612,0.1203392,0.8403892,99.99141
42.1875,258.0816,11.22038,-10.29979,0.1181897,0.8262984,100.0414
42.4375,259.3299,11.21755,-10.35549,0.1159302,0.8113644,100.013
42.6875,260.5794,11.21461,-10.41272,0.1135896,0.7958056,99.99312
42.9375,261.8268,11.21163,-10.46515,0.111663,0.7831158,100.0475
43.1875,263.0719,11.20868,-10.52285,0.1093536,0.7677126,100.0001
43.4375,264.317,11.20554,-10.5752,0.1074977,0.7554607,100.0112
43.6875,265.5684,11.20237,-10.62938,0.1055396,0.742465,99.9627
43.9375,266.8138,11.19937,-10.68864,0.1032101,0.7268243,100.05
44.1875,268.06,11.19609,-10.73914,0.1015961,0.7161928,99.99064
44.4375,269.3112,11.19282,-10.79868,0.09931732,0.7008496,99.95406
44.6875,270.5567,11.18952,-10.85451,0.09735495,0.6877084,100.0325
44.9375,271.8078,11.1862,-10.90884,0.09554684,0.6756312,100.0105
45.18334,273.0325,11.18276,-10.95991,0.09397238,0.6651694,100.0044
45.43334,274.2799,11.17934,-11.01634,0.09205512,0.6522666,100.0036
45.68334,275.5306,11.1759,-11.07266,0.09018058,0.6396408,100.002
45.93334,276.7727,11.17232,-11.12534,0.08860343,0.6290979,100.012
46.18334,278.0222,11.16868,-11.17791,0.0870691,0.6188368,100.0022
46.42916,279.2484,11.16494,-11.23294,0.08533255,0.6071062,99.97216
46.67916,280.4959,11.16112,-11.28862,0.08361838,0.5954872,99.98109
46.92916,281.7422,11.15733,-11.34342,0.08199702,0.5844947,99.99875
47.17916,282.989,11.15338,-11.40468,0.07991303,0.57018,100.0001
47.42916,284.2384,11.14952,-11.45684,0.07854421,0.560944,100.0292
47.67916,285.482,11.14537,-11.51278,0.07690944,0.5497894,99.9975
47.92916,286.7341,11.14132,-11.57125,0.07511956,0.5375043,100.0444
48.17916,287.9805,11.13695,-11.63792,0.07272866,0.52089,100.0079
48.42916,289.2311,11.13283,-11.69257,0.07127692,0.5109776,100.0038
48.67916,290.4754,11.12846,-11.75023,0.06960995,0.4994994,100.0004
48.92916,291.7248,11.12415,-11.80714,0.06803031,0.4886276,99.97993
49.17916,292.9704,11.11944,-11.85906,0.06683814,0.4805188,99.98999
49.42916,294.2183,11.11495,-11.91014,0.06573175,0.4730122,100.0152
49.67916,295.4662,11.11013,-11.97202,0.06384037,0.4598364,99.97832
49.92916,296.717,11.10543,-12.03284,0.0620555,0.4474044,99.98905
50.17916,297.9653,11.10053,-12.0899,0.06056559,0.437076,100.0014
50.42916,299.2128,11.09554,-12.14898,0.0589494,0.4258163,100.0187
50.67916,300.4588,11.09061,-12.20517,0.05756093,0.4161791,100.0028
50.92916,301.705,11.0853,-12.26496,0.05592813,0.404732,100.005
51.175,302.9318,11.08029,-12.32164,0.05450082,0.3947466,99.99422
51.425,304.1809,11.07503,-12.38196,0.05287012,0.383275,100.022
51.675,305.4297,11.06958,-12.44398,0.05113363,0.3710155,99.98641
51.925,306.6766,11.06406,-12.5016,0.0497324,0.361168,99.99364
52.17083,307.9037,11.05863,-12.56299,0.04802536,0.3490752,99.96938
52.42083,309.151,11.05294,-12.61888,0.04678531,0.3403633,100.0137
52.67082,310.4008,11.0474,-12.67814,0.04531543,0.3299625,100.031
52.92082,311.6452,11.04148,-12.73235,0.04422453,0.3223047,99.99637
53.17082,312.8955,11.03559,-12.78585,0.04320625,0.3151634,99.98162
53.42082,314.1426,11.02959,-12.84211,0.04199545,0.3066034,99.95676
53.67082,315.3925,11.02346,-12.89731,0.04087786,0.2987092,99.9629
53.92082,316.64,11.01734,-12.9583,0.03935066,0.2878053,99.99624
54.17082,317.8908,11.01124,-13.00859,0.03861584,0.2826822,100.0154
54.42082,319.1356,11.00486,-13.06653,0.03733222,0.2735286,99.9916
54.67082,320.3839,10.99844,-13.12273,0.03618018,0.2653232,100.0177
54.92082,321.63,10.99201,-13.17768,0.0351437,0.2579435,99.95751
55.17082,322.8781,10.98551,-13.23124,0.03421088,0.2513048,99.99997
55.42082,324.1272,10.97904,-13.28818,0.03305433,0.2430109,99.99853
55.67082,325.3737,10.97226,-13.33088,0.0329279,0.2422824,99.99769
55.92082,326.6178,10.96567,-13.39042,0.03159106,0.2326387,99.94064
56.17082,327.8672,10.95864,-13.44325,0.03075127,0.2266426,100.0182
56.42082,329.118,10.95172,-13.49994,0.02964823,0.2186951,100.0276
56.67082,330.3674,10.9447,-13.5514,0.02892861,0.2135649,99.9928
56.91666,331.5959,10.93764,-13.60881,0.02774118,0.2049668,100.0041
57.16666,332.8428,10.93031,-13.6677,0.02650095,0.1959666,100.0018
57.41666,334.0907,10.92313,-13.72471,0.02540414,0.1880128,100.0058
57.66666,335.3365,10.91564,-13.78535,0.0240518,0.1781528,100.0019
57.9125,336.5652,10.90831,-13.84845,0.02248566,0.1666894,100.0084
58.1625,337.8108,10.90058,-13.90785,0.02124381,0.1576154,100.0077
58.4125,339.059,10.89284,-13.9688,0.01989362,0.1477214,100.001
58.6625,340.3036,10.88496,-14.03808,0.01796082,0.1334811,99.98715
58.9125,341.553,10.87667,-14.10458,0.01623403,0.1207468,99.97235
59.1625,342.7959,10.86846,-14.17438,0.0142782,0.1062841,100.001
59.4125,344.043,10.86012,-14.24969,0.01194471,0.08898489,99.97613
59.6625,345.2896,10.85155,-14.33525,0.008890174,0.06628228,99.99978
59.9125,346.5376,10.84285,-14.41219,0.006462955,0.04822431,99.98891
60.1625,347.7804,10.83361,-14.50301,0.00304914,0.02276955,99.99488
60.4125,349.0294,10.82434,-14.59168,-1.88E-04,-1.41E-03,99.98912
60.6625,350.2724,10.81488,-14.67977,-3.38E-03,-0.02527383,99.95863
60.9125,351.5168,10.80492,-14.77688,-7.21E-03,-0.0539356,99.98251
61.1625,352.7625,10.79475,-14.8783,-0.01131114,-0.08473915,100.008
61.4125,354.006,10.78423,-14.97949,-0.0153973,-0.1154439,99.96312
61.6625,355.2492,10.77337,-15.08924,-0.02006638,-0.1505723,99.98478
61.9125,356.4926,10.76183,-15.20182,-0.02492394,-0.1871729,100.0057
62.1625,357.741,10.75007,-15.32087,-0.03020864,-0.2270436,100.012
62.4125,358.9822,10.73766,-15.43751,-0.03531808,-0.2656601,100.0072
62.65832,360.2066,10.72506,-15.55608,-0.04059136,-0.3055693,99.99455
62.90832,361.4485,10.71187,-15.67942,-0.04613846,-0.3475955,100.0058
63.15832,362.69,10.69788,-15.80711,-0.0519746,-0.3918638,100.001
63.40832,363.931,10.68368,-15.9365,-0.0579061,-0.4369204,100.011
63.65832,365.1754,10.66869,-16.06755,-0.0639318,-0.4827582,100.0088
63.90418,366.4,10.65344,-16.20045,-0.07011761,-0.5298701,100.0292
64.15418,367.6417,10.63713,-16.33791,-0.07654946,-0.5789222,100.0242
64.40418,368.8893,10.62058,-16.47137,-0.08267776,-0.6257535,100.0097
64.65418,370.1298,10.60336,-16.5984,-0.08834019,-0.669129,99.99897
64.90418,371.3719,10.58584,-16.72564,-0.09400003,-0.7125516,100.0099
65.15418,372.6132,10.55881,-16.91925,-0.1042402,-0.7907891,100.0259
65.40418,373.8551,10.53634,-17.08168,-0.11229,-0.8525184,100.0379
65.65418,375.0966,10.51355,-17.22354,-0.1188893,-0.9033228,99.99496
65.90418,376.3436,10.49008,-17.33681,-0.1234797,-0.9389336,100.0114
66.15418,377.5828,10.46657,-17.44696,-0.1278472,-0.9729024,99.96218
66.40418,378.8309,10.44273,-17.54946,-0.1316565,-1.002675,100.007
66.65418,380.0808,10.41876,-17.63952,-0.1345952,-1.025826,100.0169
66.90418,381.326,10.39426,-17.72994,-0.1375474,-1.049108,99.97759
67.15418,382.5757,10.36973,-17.82494,-0.1407924,-1.074659,99.99531
67.40418,383.82,10.34446,-17.92261,-0.1442107,-1.101573,99.98241
67.65418,385.0669,10.31918,-18.00816,-0.1467819,-1.122051,99.96476
67.90418,386.314,10.29348,-18.08131,-0.1484929,-1.135978,99.99788
68.15418,387.5646,10.26751,-18.1639,-0.1508298,-1.154718,99.98506
68.4,388.791,10.24156,-18.235,-0.1524316,-1.16784,99.98492
68.65,390.0402,10.21503,-18.3114,-0.1543244,-1.183226,99.99744
68.9,391.2886,10.18823,-18.38672,-0.1561315,-1.197977,100.0044
69.15,392.5394,10.16098,-18.4589,-0.1577119,-1.211009,99.98087
69.4,393.788,10.13382,-18.53431,-0.1594991,-1.225649,99.99392
69.64584,395.0166,10.107,-18.60103,-0.1607445,-1.236129,100.0294
69.89584,396.2646,10.07951,-18.67246,-0.1622448,-1.248599,99.98955
70.14584,397.5132,10.0521,-18.73873,-0.1633872,-1.258325,100.0046
70.39584,398.7619,10.02451,-18.80082,-0.164243,-1.265821,100.0107
70.64584,400.0145,9.996872,-18.87435,-0.1658461,-1.279091,100.0134
70.89584,401.2647,9.969312,-18.94302,-0.1671205,-1.289841,100.0289
71.14584,402.5114,9.941789,-19.00705,-0.1680816,-1.298185,99.98634
71.39584,403.7602,9.914328,-19.07252,-0.169128,-1.307199,100.0034
71.64584,405.012,9.887079,-19.14168,-0.1704049,-1.318007,99.99366
71.89584,406.2656,9.859774,-19.20504,-0.1712831,-1.325746,99.97053
72.14584,407.5159,9.83275,-19.27728,-0.1727473,-1.338031,99.93756
72.39584,408.7649,9.805762,-19.34629,-0.1739912,-1.348624,99.99328
72.64584,410.0158,9.779194,-19.41545,-0.1752311,-1.359201,99.96918
72.89584,411.2639,9.752539,-19.47882,-0.176089,-1.366824,100.0269
73.14584,412.516,9.726266,-19.5582,-0.1779794,-1.382478,99.99215
73.39584,413.7638,9.700386,-19.63333,-0.1795895,-1.395971,100.0356
73.64584,415.0131,9.674559,-19.71189,-0.1814109,-1.411124,100.0095
73.89584,416.2618,9.649384,-19.78325,-0.1827552,-1.422569,99.9843
74.14166,417.4894,9.624482,-19.85683,-0.1842944,-1.435515,100.0082
74.39166,418.7414,9.599578,-19.92944,-0.1856979,-1.447438,100.0046
74.64166,419.9888,9.575024,-19.99963,-0.1869479,-1.458175,100.0135
74.89166,421.2397,9.551004,-20.07671,-0.1886256,-1.472264,99.99942
75.14166,422.485,9.5271,-20.15596,-0.1904442,-1.487469,100.0029
75.3875,423.7194,9.504007,-20.22435,-0.1915926,-1.497439,99.99166
75.6375,424.9659,9.480586,-20.29995,-0.1931572,-1.510692,100.0159
75.8875,426.2145,9.457825,-20.37681,-0.1947887,-1.524483,100.0188
76.1375,427.4666,9.435197,-20.45326,-0.1963785,-1.537964,99.95718
76.3875,428.7126,9.413036,-20.53376,-0.1982283,-1.553497,100.0246
76.6375,429.9589,9.391206,-20.61399,-0.2000496,-1.568825,100.0081
76.8875,431.2119,9.369712,-20.70105,-0.2022758,-1.587349,99.97416
77.1375,432.454,9.348361,-20.7832,-0.2042053,-1.603566,100.0389
77.3875,433.7078,9.327457,-20.8636,-0.2059893,-1.618657,100.0166
77.6375,434.9522,9.306766,-20.94792,-0.2080332,-1.635777,100.005
77.8875,436.2018,9.286303,-21.02992,-0.20991,-1.651593,100.0012
78.1375,437.4516,9.266138,-21.11959,-0.2122515,-1.671086,100.0376
78.3875,438.698,9.246231,-21.20022,-0.2140297,-1.686164,99.99616
78.6375,439.948,9.226328,-21.29218,-0.2164876,-1.706618,100.0292
78.8875,441.1959,9.206632,-21.38392,-0.2189227,-1.726915,99.98238
79.1375,442.4439,9.186965,-21.47254,-0.2211534,-1.745622,99.99835
79.3875,443.6888,9.167337,-21.5581,-0.2231938,-1.762846,100.032
79.6375,444.9367,9.147574,-21.63909,-0.2249367,-1.77774,100.0238
79.8875,446.183,9.127753,-21.73335,-0.2274795,-1.798975,100.0311
80.13332,447.4126,9.108668,-21.82696,-0.2300118,-1.820132,100.0089
80.38332,448.6584,9.088879,-21.91536,-0.2321753,-1.838412,99.99119
80.63332,449.9058,9.068824,-22.01299,-0.234878,-1.860986,100.0008
80.88332,451.1518,9.048776,-22.10874,-0.2374562,-1.882598,100.0073
81.12916,452.3789,9.028749,-22.20125,-0.239875,-1.902948,100.0121
81.37916,453.6236,9.008462,-22.29683,-0.242423,-1.924339,100.0039
81.62916,454.8724,8.987692,-22.39798,-0.2452787,-1.94819,100.037
81.87916,456.117,8.966651,-22.4959,-0.2479379,-1.970505,100.0193
82.12916,457.3678,8.945662,-22.59552,-0.2506678,-1.993409,99.97444
82.37916,458.6118,8.924203,-22.697,-0.2535092,-2.017225,99.99108
82.62916,459.8606,8.902587,-22.79339,-0.2560244,-2.03847,100.0001
82.87916,461.106,8.880639,-22.90124,-0.259205,-2.065039,99.98299
83.12916,462.355,8.858545,-23.00026,-0.2618444,-2.087324,99.96098
83.37916,463.6016,8.836116,-23.10692,-0.2649198,-2.113111,100.007
83.62916,464.846,8.813195,-23.20496,-0.2674852,-2.134854,99.99204
83.87916,466.0928,8.790601,-23.30838,-0.2703409,-2.15894,99.98492
84.12916,467.3382,8.767984,-23.41387,-0.2733036,-2.183904,100.0324
84.37916,468.5859,8.744658,-23.51678,-0.2760972,-2.207548,100.013
84.62916,469.8307,8.721587,-23.62802,-0.2793584,-2.234955,99.97708
84.87916,471.08,8.698328,-23.73525,-0.2823622,-2.260334,99.98407
85.12916,472.33,8.674866,-23.841,-0.2852662,-2.284935,99.97399
85.37916,473.5766,8.651259,-23.94916,-0.2882988,-2.310583,100.0098
85.62916,474.824,8.627591,-24.05894,-0.2914048,-2.33685,100.0082
85.875,476.049,8.604371,-24.16991,-0.2946167,-2.363969,99.98364
86.125,477.2946,8.580559,-24.28407,-0.29794,-2.392036,100.0116
86.375,478.5425,8.556584,-24.4008,-0.3013824,-2.421091,100.0078
86.625,479.7871,8.532834,-24.52807,-0.3054018,-2.454812,99.99211
86.87084,481.0092,8.509131,-24.65458,-0.3094137,-2.488486,99.97064
87.12084,482.2576,8.485191,-24.77679,-0.3130965,-2.51957,99.98957
87.37084,483.5027,8.461163,-24.90759,-0.3172449,-2.55444,100.0098
87.62084,484.7507,8.437049,-25.03733,-0.3213018,-2.58861,99.99461
87.87084,485.9932,8.413145,-25.16232,-0.3250905,-2.620652,99.98414
88.12084,487.2394,8.388732,-25.29661,-0.3293561,-2.656574,99.97616
88.37084,488.4866,8.364684,-25.4273,-0.3333992,-2.690742,100.0032
88.62084,489.7314,8.340968,-25.56248,-0.3376704,-2.726789,99.99822
88.87084,490.976,8.317447,-25.69551,-0.3418007,-2.761728,100.0375
89.12084,492.2216,8.293672,-25.8253,-0.3457322,-2.795089,99.97625
89.37084,493.4652,8.270363,-25.96197,-0.3500175,-2.831345,100.0128
89.62084,494.7134,8.247184,-26.10037,-0.3543582,-2.868087,99.98121
89.87084,495.9574,8.224295,-26.2389,-0.3586945,-2.904834,100.0102
90.12084,497.2054,8.201874,-26.37745,-0.3629933,-2.941315,100.0133
90.37084,498.451,8.179902,-26.5192,-0.3674446,-2.979068,99.99556
90.62084,499.6912,8.157772,-26.65924,-0.3717971,-3.016062,100.0197
90.87084,500.9346,8.136102,-26.80256,-0.376288,-3.054215,99.9765
91.12084,502.1806,8.114765,-26.94425,-0.3806586,-3.091429,99.9954
91.37084,503.4279,8.093591,-27.08718,-0.3850687,-3.12901,100.0013
91.61668,504.6544,8.073194,-27.23094,-0.3895478,-3.167158,100.0055
91.86668,505.8974,8.05251,-27.37568,-0.394014,-3.20527,99.97941
92.11668,507.1444,8.032482,-27.51996,-0.3984212,-3.242945,99.99381
92.36668,508.3862,8.012691,-27.6786,-0.4035631,-3.286636,100.0094
92.61668,509.6332,7.993266,-27.82679,-0.4081216,-3.325622,99.98774
92.8625,510.8576,7.97448,-27.9848,-0.4132217,-3.369004,100.0372
93.1125,512.1068,7.955644,-28.13247,-0.417705,-3.407425,100.0069
93.3625,513.3564,7.937256,-28.28953,-0.4226433,-3.4496,99.9964
93.6125,514.6116,7.919192,-28.44456,-0.4274371,-3.490642,99.98366
93.8625,515.8588,7.901522,-28.6144,-0.4329816,-3.537852,99.99436
94.1125,517.1082,7.884091,-28.77806,-0.4381784,-3.582272,100.0294
94.3625,518.3541,7.867014,-28.94589,-0.4435682,-3.628314,99.97209
94.6125,519.6045,7.850142,-29.12805,-0.4496408,-3.679989,100.0347
94.8625,520.854,7.8337,-29.31669,-0.4560106,-3.73415,99.97049
95.1125,522.1011,7.81771,-29.49466,-0.461819,-3.783767,99.99141
95.3625,523.3482,7.801844,-29.68382,-0.4681569,-3.837774,100.0046
95.6125,524.5955,7.786484,-29.87046,-0.4743364,-3.890538,99.99184
95.8625,525.8461,7.771634,-30.07055,-0.4811444,-3.948514,100.036
96.1125,527.0932,7.756952,-30.26847,-0.4878201,-4.005462,100.0253
96.3625,528.3426,7.742942,-30.46587,-0.4944301,-4.061929,99.97186
96.6125,529.5875,7.728832,-30.68181,-0.5019329,-4.125786,99.9839
96.8625,530.8334,7.71508,-30.88607,-0.5088244,-4.184661,99.99866
97.1125,532.0824,7.701966,-31.09256,-0.5157828,-4.244145,100.0142
97.35834,533.3111,7.689149,-31.30448,-0.5230237,-4.305978,99.99793
97.60834,534.5554,7.676592,-31.52375,-0.5305492,-4.37025,100.0079
97.85834,535.8028,7.664032,-31.74225,-0.5379916,-4.433906,100.0044
98.10834,537.05,7.652851,-31.93894,-0.5443418,-4.488612,99.99219
98.35834,538.2978,7.64097,-32.1063,-0.5492452,-4.531445,99.99797
98.60416,539.5256,7.629418,-32.29724,-0.5553136,-4.583892,100.0133
98.85416,540.7726,7.618206,-32.5084,-0.5622786,-4.643839,100.0237
99.10416,542.0234,7.607112,-32.72802,-0.569605,-4.706828,100.0153
99.35416,543.2706,7.59634,-32.95242,-0.5771363,-4.771576,100.008
99.60416,544.5164,7.585832,-33.1828,-0.5849211,-4.838481,100.0109
99.85416,545.7626,7.57544,-33.41307,-0.5926636,-4.9051,100.0094
100.1042,547.0085,7.565276,-33.64363,-0.6003856,-4.971616,99.9466
100.3542,548.254,7.5554,-33.86799,-0.6077807,-5.035489,100.0274
100.6042,549.4984,7.545884,-34.09295,-0.6151757,-5.099414,99.99578
100.8542,550.7474,7.536566,-34.31057,-0.6221868,-5.160174,99.99661
101.1042,551.993,7.52744,-34.53222,-0.6293663,-5.222384,99.99906
101.3542,553.2406,7.518444,-34.76148,-0.6368652,-5.28731,99.99797
101.6042,554.4862,7.509666,-34.96721,-0.6432418,-5.342972,100.0087
101.8542,555.734,7.501222,-35.18705,-0.6502422,-5.403874,100.0304
102.1042,556.9805,7.492832,-35.39635,-0.6567307,-5.460581,100.0331
102.3542,558.2299,7.484854,-35.60476,-0.663143,-5.5167,99.96699
102.6042,559.4758,7.476676,-35.81416,-0.6695869,-5.573135,100.0206
102.8542,560.7258,7.46918,-36.03052,-0.6763139,-5.631985,100.0245
103.1,561.952,7.461695,-36.2216,-0.68192,-5.68151,99.99092
103.35,563.2006,7.453979,-36.4285,-0.6881712,-5.7365,100.018
103.6,564.4472,7.446722,-36.62514,-0.6939369,-5.787488,99.98574
103.85,565.6979,7.439582,-36.82393,-0.699771,-5.839102,99.98941
104.1,566.947,7.432471,-37.02152,-0.7055344,-5.890174,100.0036
104.3458,568.175,7.425554,-37.20226,-0.7105712,-5.935169,99.9745
104.5958,569.4229,7.418745,-37.37228,-0.7150599,-5.975671,99.99457
104.8458,570.6704,7.41187,-37.55686,-0.7201966,-6.021601,99.98534
105.0958,571.9209,7.405266,-37.73665,-0.7250938,-6.065567,100.007
105.3458,573.1704,7.398688,-37.91697,-0.7300054,-6.109695,99.98806
105.5958,574.4176,7.39243,-38.0922,-0.7346832,-6.151904,100.011
105.8458,575.6661,7.386012,-38.26492,-0.7392343,-6.193089,99.98111
106.0958,576.9179,7.379996,-38.45088,-0.7443528,-6.239071,100.0099
106.3458,578.169,7.37397,-38.64449,-0.749797,-6.287822,99.9839
106.5958,579.421,7.368001,-38.83276,-0.7549894,-6.334504,99.98828
106.8458,580.6688,7.362231,-39.01919,-0.7600991,-6.380532,99.98875
107.0958,581.9137,7.356458,-39.2154,-0.7656338,-6.430172,99.96469
107.3458,583.1622,7.350839,-39.39741,-0.7705219,-6.47442,99.99239
107.5958,584.4132,7.345149,-39.58381,-0.775583,-6.520159,99.95957
107.8458,585.6604,7.339493,-39.78044,-0.7810908,-6.569703,100.0139
108.0958,586.9086,7.33418,-39.96584,-0.7860932,-6.615034,99.9954
108.3458,588.1574,7.328546,-40.15709,-0.7913384,-6.662452,100.0362
108.5958,589.4093,7.322997,-40.32982,-0.7957624,-6.702982,100.022
108.8458,590.6582,7.317724,-40.51562,-0.8007684,-6.748325,99.97001
109.0916,591.8868,7.312734,-40.7045,-0.8059462,-6.795092,100.0049
109.3416,593.1345,7.30766,-40.8849,-0.8107042,-6.838408,99.97197
109.5916,594.3824,7.302334,-41.06739,-0.8155435,-6.882446,100.0048
109.8416,595.631,7.297061,-41.2386,-0.8198915,-6.922376,99.96425
110.0875,596.8618,7.292078,-41.4129,-0.8244084,-6.963718,99.98203
110.3375,598.1112,7.287112,-41.58265,-0.828682,-7.003086,99.9935
110.5875,599.3612,7.282019,-41.75846,-0.8332072,-7.044618,99.99379
110.8375,600.6132,7.277105,-41.92954,-0.8375219,-7.084403,100.0034
111.0875,601.8657,7.271997,-42.10372,-0.841963,-7.125294,99.97028
111.3375,603.1146,7.267136,-42.27534,-0.8462997,-7.165331,99.99805
111.5875,604.3638,7.262401,-42.4409,-0.8503785,-7.203216,99.99318
111.8375,605.612,7.257522,-42.61602,-0.8548582,-7.244526,99.96942
112.0875,606.8641,7.252699,-42.7834,-0.8589996,-7.283006,99.96386
112.3375,608.1145,7.247968,-42.94422,-0.8628701,-7.31922,99.99994
112.5875,609.3649,7.243015,-43.09934,-0.8665028,-7.353447,100.017
112.8375,610.6178,7.238411,-43.26078,-0.8702922,-7.389853,100.011
113.0875,611.8614,7.23375,-43.42922,-0.8743766,-7.428964,100.0207
113.3375,613.1158,7.22903,-43.58158,-0.8777648,-7.46221,100.015
113.5875,614.366,7.22439,-43.74519,-0.8816275,-7.499516,99.99908
113.8375,615.615,7.219661,-43.91528,-0.8857592,-7.539157,100.0448
114.0875,616.8661,7.215107,-44.08057,-0.8896848,-7.57708,100.0344
114.3375,618.117,7.210564,-44.23295,-0.8930805,-7.610518,100.0066
114.5875,619.3661,7.206069,-44.39131,-0.8967266,-7.64613,100.0048
114.8334,620.5941,7.20155,-44.56191,-0.9009179,-7.686352,99.99706
115.0834,621.8451,7.19715,-44.72,-0.9045468,-7.72189,100.0115
115.3334,623.0962,7.192724,-44.88116,-0.9082991,-7.75852,99.97439
115.5834,624.348,7.188339,-45.03584,-0.9117882,-7.792944,99.99957
115.8292,625.5766,7.184662,-45.19268,-0.9154169,-7.828503,99.98194
116.0792,626.8266,7.180328,-45.35208,-0.9191022,-7.864666,99.94634
116.3292,628.077,7.175912,-45.49938,-0.9223007,-7.896699,99.99681
116.5792,629.3262,7.171592,-45.65805,-0.9259601,-7.932696,99.98925
116.8292,630.5751,7.167331,-45.82938,-0.9301597,-7.973082,99.98644
117.0792,631.825,7.163026,-45.99096,-0.9339991,-8.010161,99.99355
117.3292,633.0766,7.158914,-46.15019,-0.9377416,-8.046432,99.99281
117.5792,634.3272,7.15451,-46.31098,-0.9415486,-8.083288,100.0219
117.8292,635.5814,7.150442,-46.4683,-0.9452124,-8.11896,99.98507
118.0792,636.8291,7.146176,-46.63074,-0.9490949,-8.15653,99.94559
118.3292,638.0816,7.142094,-46.79,-0.9528436,-8.192992,99.9742
118.5792,639.3295,7.138199,-46.95085,-0.9566651,-8.230102,100.041
118.8292,640.5805,7.134119,-47.106,-0.9602589,-8.265288,99.99976
119.0792,641.8305,7.130176,-47.27034,-0.9642176,-8.303651,100.0035
119.3292,643.08,7.12603,-47.43557,-0.9682132,-8.342363,99.99116
119.5792,644.3283,7.12197,-47.5855,-0.9716161,-8.375995,100.0039
119.8292,645.5828,7.11795,-47.74481,-0.9753745,-8.412735,99.99243
120.0792,646.8297,7.113931,-47.89903,-0.9789538,-8.447949,99.98499
120.3292,648.0812,7.110003,-48.05432,-0.9825684,-8.483505,100.0311
120.575,649.31,7.10625,-48.20258,-0.9859581,-8.517072,99.9965
120.825,650.5613,7.102386,-48.35063,-0.9893012,-8.55034,99.9955
121.075,651.8101,7.098811,-48.51389,-0.99324,-8.588788,100.0002
121.325,653.0615,7.094956,-48.66124,-0.9965644,-8.621954,99.99788
121.575,654.3114,7.091101,-48.8167,-1.000208,-8.657911,99.99781
121.8208,655.5418,7.087549,-49.02368,-1.005862,-8.711244,99.98241
122.0708,656.792,7.083916,-49.1683,-1.009096,-8.743718,99.99472
122.3208,658.0411,7.080462,-49.32578,-1.012826,-8.780524,99.94892
122.5708,659.2934,7.077064,-49.46832,-1.015986,-8.812418,99.9586
122.8208,660.543,7.073437,-49.63264,-1.019984,-8.851618,99.99095
123.0708,661.7912,7.069768,-49.77908,-1.023311,-8.885018,99.97716
123.3208,663.0424,7.066339,-49.93312,-1.026924,-8.920928,99.99528
123.5708,664.2918,7.063038,-50.09136,-1.030706,-8.958344,100.0058
123.8208,665.5425,7.059622,-50.24422,-1.034285,-8.994025,100.0211
124.0708,666.793,7.056284,-50.3856,-1.03744,-9.026049,100.0096
124.3208,668.045,7.052611,-50.53688,-1.04097,-9.061368,99.99113
124.5708,669.2971,7.049366,-50.67593,-1.044047,-9.092774,99.97725
124.8208,670.5478,7.045997,-50.81802,-1.04725,-9.125301,99.97285
125.0708,671.8007,7.042744,-50.97744,-1.051098,-9.16348,100.0344
125.3208,673.0474,7.039434,-51.11004,-1.053967,-9.193147,99.98155
125.5708,674.3008,7.036213,-51.2477,-1.05702,-9.224452,99.97556
125.8208,675.5486,7.033097,-51.39336,-1.060388,-9.258528,100.0116
126.0708,676.7984,7.029639,-51.53968,-1.063782,-9.29285,100.021
126.3166,678.0312,7.026456,-51.67304,-1.066732,-9.32325,99.99579
126.5666,679.2803,7.023395,-51.81928,-1.070139,-9.35775,99.99951
126.8166,680.5316,7.0205,-51.95188,-1.073049,-9.387938,99.98511
127.0666,681.7854,7.017368,-52.08793,-1.076089,-9.419282,99.98004
127.3166,683.0345,7.014261,-52.22896,-1.07933,-9.452414,99.98884
127.5625,684.2642,7.011386,-52.37554,-1.082811,-9.487602,100.0154
127.8125,685.5191,7.008505,-52.51001,-1.085815,-9.518712,100
128.0625,686.7671,7.005488,-52.6588,-1.089364,-9.554626,100.0242
128.3125,688.0166,7.00255,-52.79738,-1.092547,-9.587359,99.99901
128.5625,689.27,6.999576,-52.93634,-1.095744,-9.620241,100.0099
128.8125,690.5195,6.996675,-53.0753,-1.098958,-9.653305,99.99882
129.0625,691.7688,6.993732,-53.20754,-1.101938,-9.684318,99.99941
129.3125,693.0171,6.991088,-53.34394,-1.105091,-9.716786,100.022
129.5625,694.2664,6.9877,-53.46051,-1.107535,-9.743051,100.0031
129.8125,695.5178,6.985109,-53.59092,-1.110487,-9.773819,100.0039
130.0625,696.7736,6.982518,-53.7195,-1.113374,-9.804038,100.009
130.3125,698.0253,6.979968,-53.83911,-1.115959,-9.83162,100.0118
130.5625,699.278,6.977451,-53.97624,-1.119181,-9.864838,100.0123
130.8125,700.5306,6.974918,-54.12361,-1.122776,-9.901374,99.97766
131.0625,701.78,6.972339,-54.24879,-1.125596,-9.93109,99.97999
131.3125,703.0292,6.969978,-54.38711,-1.128892,-9.96504,99.99508
131.5625,704.2839,6.96763,-54.52912,-1.13232,-10.00019,100.0255
131.8125,705.5328,6.965046,-54.6652,-1.135552,-10.03361,99.99262
132.0584,706.7634,6.96272,-54.79676,-1.138654,-10.06585,99.99576
132.3084,708.0147,6.960324,-54.93234,-1.141879,-10.09928,99.98712
132.5584,709.266,6.958141,-55.0644,-1.144985,-10.13169,99.98301
132.8084,710.5149,6.955813,-55.19363,-1.148002,-10.16332,99.99722
133.0584,711.7668,6.953761,-55.31759,-1.150833,-10.19335,100.0079
133.3042,712.9992,6.951404,-55.43239,-1.153373,-10.22073,100.0146
133.5542,714.2524,6.949532,-55.55867,-1.156296,-10.25162,99.94555
133.8042,715.5034,6.947459,-55.68346,-1.159174,-10.28212,100.0235
134.0542,716.7528,6.945499,-55.79876,-1.161727,-10.30978,100.0294
134.3042,718.0056,6.94339,-55.92078,-1.164512,-10.33951,100.0279
134.5542,719.2543,6.941515,-56.03906,-1.167179,-10.36821,99.99397
134.8042,720.5074,6.939631,-56.16166,-1.169988,-10.39819,99.99342
135.0542,721.7528,6.937741,-56.28884,-1.172973,-10.42977,99.99905
135.3042,723.0076,6.936122,-56.39791,-1.175314,-10.45563,99.98511
135.5542,724.2578,6.934221,-56.50998,-1.17777,-10.48256,100.0114
135.8042,725.5079,6.932718,-56.60869,-1.179764,-10.50538,100.036
136.0542,726.764,6.931048,-56.72027,-1.182197,-10.53214,99.96559
136.3042,728.017,6.92953,-56.84064,-1.184936,-10.56165,99.99209
136.5542,729.2675,6.927978,-56.95754,-1.18756,-10.59015,99.99669
136.8042,730.5196,6.926522,-57.06882,-1.189984,-10.61687,100.0166
137.0542,731.7684,6.925212,-57.16344,-1.191843,-10.63858,99.99285
137.3042,733.0198,6.92388,-57.26861,-1.194058,-10.66349,100.0007
137.5542,734.2725,6.92255,-57.36742,-1.196052,-10.68645,99.99632
137.8042,735.5259,6.921328,-57.46019,-1.197838,-10.70756,100.0073
138.05,736.7587,6.9201,-57.56015,-1.19989,-10.73099,99.98814
138.3,738.0074,6.918944,-57.66132,-1.201962,-10.75468,100.0108
138.55,739.259,6.91767,-57.74942,-1.203584,-10.77437,99.98715
138.8,740.5115,6.916594,-57.84414,-1.205426,-10.79605,99.99742
139.0458,741.7459,6.915412,-57.91463,-1.206463,-10.81044,100.0134
139.2958,742.9959,6.914319,-58.00006,-1.207988,-10.8293,99.987
139.5458,744.2508,6.913264,-58.08222,-1.209391,-10.84708,100.0195
139.7958,745.5016,6.912272,-58.17043,-1.210999,-10.86672,99.98351
140.0458,746.7525,6.91116,-58.2548,-1.212473,-10.88516,99.99024
140.2958,748.0055,6.910261,-58.3235,-1.213413,-10.89883,99.94522
140.5458,749.2599,6.909158,-58.40805,-1.214877,-10.9172,99.98941
140.7958,750.5106,6.908276,-58.48994,-1.216251,-10.93478,100.0015
141.0458,751.764,6.907288,-58.55124,-1.216927,-10.94609,99.98712
141.2958,753.0178,6.906422,-58.62462,-1.217999,-10.96098,99.98369
141.5458,754.2722,6.905196,-58.68863,-1.218755,-10.973,99.98735
141.7958,755.522,6.904374,-58.75811,-1.219698,-10.98669,99.97274
142.0458,756.7766,6.90315,-58.83876,-1.220994,-11.00356,99.98609
142.2958,758.0324,6.902466,-58.9143,-1.22211,-11.01882,99.96465
142.5458,759.2811,6.901522,-58.98301,-1.223003,-11.03207,99.95545
142.7958,760.535,6.900638,-59.04416,-1.22363,-11.04295,100.0009
143.0458,761.792,6.899757,-59.10058,-1.224087,-11.05228,100.0226
143.2958,763.0422,6.898862,-59.1664,-1.224858,-11.06446,99.96074
143.5458,764.2945,6.897871,-59.22563,-1.225396,-11.07454,100.0195
143.7917,765.5282,6.897153,-59.27118,-1.225498,-11.08058,100.0018
144.0417,766.781,6.896319,-59.33966,-1.226323,-11.09327,100.0006
144.2917,768.0371,6.895318,-59.3728,-1.225975,-11.09534,99.9925
144.5417,769.289,6.894696,-59.37799,-1.22472,-11.0892,100.0066
144.7875,770.5228,6.893726,-59.43825,-1.225268,-11.0993,99.97084
145.0375,771.777,6.892844,-59.50418,-1.225963,-11.11082,99.99946
145.2875,773.0301,6.892169,-59.57469,-1.226797,-11.12361,99.98544
145.5375,774.2815,6.891294,-59.63391,-1.227255,-11.13299,99.97094
145.7875,775.5392,6.890411,-59.68788,-1.227523,-11.1406,99.983
146.0375,776.7906,6.88979,-59.73354,-1.227525,-11.14579,99.98741
146.2875,778.046,6.889019,-59.79125,-1.227895,-11.15434,100.0132
146.5375,779.2988,6.88811,-59.86392,-1.228736,-11.16715,100.0305
146.7875,780.551,6.887275,-59.91611,-1.228904,-11.17386,100.027
147.0375,781.8038,6.886506,-59.97269,-1.2292,-11.18173,100.0068
147.2875,783.057,6.885757,-60.02618,-1.229381,-11.18856,100.051
147.5375,784.3124,6.884934,-60.08611,-1.229747,-11.19707,99.98461
147.7875,785.5639,6.884153,-60.14533,-1.230085,-11.20534,99.98062
148.0375,786.8204,6.883418,-60.20692,-1.23047,-11.21404,100.0219
148.2875,788.075,6.88257,-60.26303,-1.23067,-11.22105,100.005
148.5375,789.3297,6.881822,-60.31306,-1.230662,-11.22617,99.99934
148.7875,790.5821,6.8811,-60.387,-1.231395,-11.23806,100.0246
149.0375,791.834,6.880407,-60.44328,-1.231553,-11.24469,99.98601
149.2875,793.088,6.879741,-60.51824,-1.232276,-11.25648,100.0271
149.5333,794.3189,6.878739,-60.57172,-1.23234,-11.26217,100.0079
149.7833,795.5734,6.878169,-60.612,-1.231942,-11.26371,99.99848
150.0333,796.8282,6.877295,-60.66922,-1.232061,-11.26995,99.99482
150.2833,798.0844,6.87662,-60.72476,-1.232108,-11.27554,99.99592
150.5333,799.3399,6.875746,-60.79922,-1.232725,-11.28633,99.99822
150.7792,800.5702,6.87518,-60.87284,-1.23333,-11.29692,100.0007
151.0292,801.8212,6.874299,-60.9473,-1.23391,-11.30738,100.0012
151.2792,803.0741,6.873597,-61.01016,-1.23411,-11.31436,99.9566
151.5292,804.3269,6.872826,-61.08806,-1.234756,-11.32544,100.029
151.7792,805.5797,6.872137,-61.1609,-1.235226,-11.3349,99.96493
152.0292,806.835,6.871284,-61.22374,-1.235364,-11.34134,99.96884
152.2792,808.0924,6.870612,-61.29576,-1.235758,-11.35012,100.0114
152.5292,809.3475,6.86989,-61.37011,-1.236215,-11.35949,99.98332
152.7792,810.5981,6.869064,-61.45509,-1.236984,-11.37171,99.99624
153.0292,811.8524,6.868339,-61.52563,-1.237286,-11.37966,100.0087
153.2792,813.1045,6.867799,-61.59476,-1.237531,-11.38708,99.99866
153.5292,814.3561,6.866764,-61.68774,-1.238485,-11.40104,99.98159
153.7792,815.6103,6.866262,-61.76793,-1.239025,-11.41119,100.0345
154.0292,816.8621,6.865512,-61.85484,-1.239756,-11.4231,99.96401
154.2792,818.1166,6.864756,-61.9311,-1.240142,-11.43183,100.0196
154.5292,819.3703,6.86398,-62.01155,-1.240641,-11.44162,100.0086
154.7792,820.6238,6.86332,-62.08554,-1.24093,-11.44947,100.0381
155.0292,821.879,6.862549,-62.17953,-1.241796,-11.46266,99.99381
155.275,823.11,6.86177,-62.27584,-1.242752,-11.4766,100.0243
155.525,824.3631,6.861093,-62.3651,-1.243447,-11.48822,99.99195
155.775,825.6182,6.860493,-62.46132,-1.244326,-11.50154,100.0028
156.025,826.8697,6.85983,-62.56582,-1.24544,-11.51704,100.0194
156.275,828.123,6.859136,-62.66228,-1.246297,-11.53019,100.0164
156.5208,829.3556,6.858261,-62.77049,-1.247511,-11.54654,100.0037
156.7708,830.6108,6.8576,-62.8646,-1.248262,-11.55873,99.99653
157.0208,831.8624,6.856782,-62.95757,-1.24897,-11.57051,100.0437
157.2708,833.1124,6.856126,-63.06749,-1.25016,-11.58676,99.9837
157.5208,834.3647,6.855405,-63.18721,-1.251612,-11.60546,99.99452
157.7708,835.618,6.854678,-63.3072,-1.253049,-11.62402,99.95699
158.0208,836.8688,6.853915,-63.42918,-1.254534,-11.64303,99.97559
158.2708,838.1201,6.853153,-63.54765,-1.255906,-11.66097,99.98172
158.5208,839.3732,6.852388,-63.65229,-1.256858,-11.67501,100.0264
158.7708,840.6261,6.851758,-63.77312,-1.258257,-11.69321,100.023
159.0208,841.878,6.851014,-63.88938,-1.259513,-11.71011,99.99461
159.2708,843.133,6.850128,-64.02012,-1.261153,-11.73058,99.96509
159.5208,844.3831,6.849387,-64.14771,-1.262705,-11.75025,99.98869
159.7708,845.6335,6.848618,-64.2774,-1.264294,-11.77027,100.0198
160.0208,846.8878,6.847876,-64.41162,-1.265986,-11.79128,99.98504
160.2708,848.1382,6.847119,-64.54819,-1.267737,-11.81284,100.0182
160.5208,849.391,6.846426,-64.68911,-1.269584,-11.83532,99.99305
160.7708,850.6437,6.845798,-64.83236,-1.271479,-11.85826,99.98637
161.0166,851.8736,6.844954,-64.99266,-1.273874,-11.88579,99.99658
161.2666,853.1259,6.844216,-65.14033,-1.275856,-11.90957,99.99768
161.5166,854.3766,6.843431,-65.28399,-1.277714,-11.93222,99.99257
161.7666,855.6297,6.842676,-65.44203,-1.279945,-11.95836,99.9936
162.0166,856.8818,6.84198,-65.61353,-1.282532,-11.98786,99.99731
162.2625,858.1139,6.841348,-65.77819,-1.28494,-12.01561,99.99806
162.5125,859.3625,6.840532,-65.9454,-1.287382,-12.04379,99.99024
162.7625,860.6095,6.839825,-66.1158,-1.289893,-12.07264,100.0113
163.0125,861.8651,6.838956,-66.29306,-1.292545,-12.10283,100.0023
163.2625,863.115,6.838418,-66.4874,-1.295658,-12.13735,99.98889
163.5125,864.3662,6.837688,-66.6675,-1.298357,-12.16802,100.009
163.7625,865.6194,6.836772,-66.86786,-1.301581,-12.20366,99.98925
164.0125,866.8714,6.83605,-67.06274,-1.304635,-12.23771,99.97879
164.2625,868.12,6.835278,-67.26,-1.307741,-12.27228,100.0068
164.5125,869.3682,6.834559,-67.4594,-1.310881,-12.30719,100.0062
164.7625,870.6208,6.833731,-67.64729,-1.313681,-12.33894,100.03
165.0125,871.8719,6.832929,-67.8445,-1.316709,-12.37286,99.99297
165.2625,873.1228,6.832148,-68.05002,-1.319938,-12.40869,100.0051
165.5125,874.3726,6.831391,-68.25497,-1.323136,-12.44426,99.95652
165.7625,875.6184,6.830531,-68.46264,-1.326394,-12.48041,99.97197
166.0125,876.8707,6.829706,-68.67019,-1.329607,-12.51618,100.029
166.2625,878.1222,6.8289,-68.87684,-1.33278,-12.55157,100.0295
166.5125,879.3769,6.828228,-69.10507,-1.336496,-12.59202,100.0163
166.7625,880.6269,6.827422,-69.32616,-1.340015,-12.63063,100.0079
167.0083,881.8538,6.826544,-69.54589,-1.343519,-12.66904,99.99092
167.2583,883.1036,6.825728,-69.76736,-1.347004,-12.70739,99.98572
167.5083,884.3549,6.82498,-69.97764,-1.350166,-12.74273,100.0133
167.7583,885.6041,6.824169,-70.18762,-1.353311,-12.77793,99.99094
168.0042,886.8322,6.823266,-70.42726,-1.357234,-12.82042,99.99062
168.2542,888.0834,6.822384,-70.63713,-1.360324,-12.85515,100.0021
168.5042,889.3351,6.821522,-70.85579,-1.363619,-12.89186,99.98337
168.7542,890.5905,6.820632,-71.07056,-1.366778,-12.92732,100.0078
169.0042,891.8422,6.819839,-71.3012,-1.37034,-12.96662,100.0339
169.2542,893.0906,6.819069,-71.54187,-1.374144,-13.00824,99.97406
169.5042,894.3424,6.818262,-71.78205,-1.377894,-13.04936,100.0314
169.7542,895.5921,6.817439,-72.01,-1.381318,-13.08744,100.0117
170.0042,896.8394,6.816482,-72.24937,-1.385016,-13.12813,100.0172
170.2542,898.0918,6.815631,-72.4678,-1.38815,-13.16351,99.99259
170.5042,899.3441,6.814645,-72.69038,-1.391359,-13.19969,100.004
170.7542,900.5921,6.813757,-72.93681,-1.39517,-13.24164,100.0078
171.0042,901.8418,6.81292,-73.16199,-1.398406,-13.27812,100.0078
171.2542,903.0991,6.812049,-73.40303,-1.402002,-13.3181,99.97866
171.5042,904.3449,6.811132,-73.63769,-1.405452,-13.35668,99.99384
171.7542,905.595,6.810428,-73.85126,-1.408345,-13.39002,100.0068
172.0042,906.8442,6.809425,-74.0849,-1.411718,-13.42793,99.99984
172.2542,908.0965,6.8085,-74.30728,-1.414784,-13.46298,100.0167
172.5042,909.3445,6.807632,-74.52543,-1.41774,-13.49698,99.99791
172.75,910.5762,6.806718,-74.7597,-1.421096,-13.53473,100.0129
173,911.8281,6.805994,-74.95929,-1.423554,-13.56405,99.99806
173.25,913.077,6.805032,-75.15922,-1.426013,-13.5934,99.99871
173.5,914.3282,6.804089,-75.34976,-1.428222,-13.62041,100.0169
173.7458,915.5586,6.803169,-75.52831,-1.430172,-13.64485,99.98031
173.9958,916.8089,6.8022,-75.73861,-1.432834,-13.67622,100.0274
174.2458,918.0644,6.801344,-75.95502,-1.435605,-13.70863,100.0172
174.4958,919.3142,6.800324,-76.16656,-1.438273,-13.74002,99.98218
174.7458,920.5649,6.799254,-76.37579,-1.440874,-13.77074,100.0196
174.9958,921.8197,6.798391,-76.58253,-1.443384,-13.80062,100.0102
175.2458,923.0712,6.797334,-76.76616,-1.445346,-13.82528,100.0477
175.4958,924.3197,6.79647,-76.9758,-1.447917,-13.85576,99.98387
175.7458,925.5726,6.79531,-77.15852,-1.449824,-13.87993,99.98859
175.9958,926.8228,6.794415,-77.35855,-1.452138,-13.90802,99.97436
176.2458,928.0731,6.793335,-77.5625,-1.45453,-13.93687,100.0252
176.4958,929.3234,6.792341,-77.7622,-1.456802,-13.96458,100.0396
176.7458,930.5761,6.79128,-77.95755,-1.458956,-13.99118,99.99926
176.9958,931.8268,6.790353,-78.13568,-1.460706,-14.01394,100.0215
177.2458,933.078,6.789419,-78.31513,-1.462475,-14.03689,100.0097
177.4958,934.3297,6.788363,-78.50331,-1.464435,-14.06171,100.0051
177.7458,935.5809,6.787428,-78.70661,-1.466729,-14.08974,99.97992
177.9958,936.8329,6.786418,-78.8991,-1.468758,-14.11524,99.99678
178.2458,938.084,6.785636,-79.07675,-1.470443,-14.13746,100.0351
178.4917,939.3156,6.784506,-79.28168,-1.472771,-14.16578,99.98811
178.7417,940.5672,6.783492,-79.47662,-1.474826,-14.19159,100.003
178.9917,941.8195,6.782614,-79.66606,-1.476741,-14.21609,100.0115
179.2417,943.0704,6.781545,-79.85631,-1.47867,-14.24073,100.0111
179.4917,944.3234,6.7805,-80.03419,-1.480302,-14.26252,99.99801
179.7375,945.5531,6.779407,-80.20063,-1.481714,-14.28211,100.0049
179.9875,946.8062,6.77809,-80.38699,-1.483518,-14.3056,100.0425
180.2375,948.0581,6.777384,-80.58503,-1.485574,-14.33154,100.0041
180.4875,949.3084,6.776282,-80.77848,-1.487523,-14.35646,100.0365
180.7375,950.5608,6.775138,-80.96934,-1.489395,-14.38066,99.96282
180.9875,951.8125,6.774091,-81.1502,-1.49104,-14.40267,100.023
181.2375,953.0649,6.773019,-81.32269,-1.49249,-14.42283,100.0023
181.4875,954.3155,6.772026,-81.52852,-1.494668,-14.45004,100.0031
181.7375,955.5688,6.770794,-81.7128,-1.496356,-14.47253,100.0028
181.9875,956.8184,6.769684,-81.89265,-1.497951,-14.49414,99.99453
182.2375,958.0731,6.768699,-82.08879,-1.49987,-14.5189,99.98547
182.4875,959.3228,6.767628,-82.2793,-1.501682,-14.54263,99.99934
182.7375,960.5741,6.766547,-82.47232,-1.503534,-14.5667,100.017
182.9875,961.8274,6.7654,-82.632,-1.504651,-14.58367,100.0063
183.2375,963.0806,6.764122,-82.81152,-1.50619,-14.60475,100.0074
183.4875,964.3319,6.763269,-83.00493,-1.508025,-14.62871,100.0082
183.7375,965.5826,6.761864,-83.18297,-1.509528,-14.64946,99.99969
183.9875,966.8382,6.76085,-83.37126,-1.511226,-14.67212,99.9688
184.2334,968.068,6.759714,-83.55507,-1.512876,-14.69422,99.98738
184.4834,969.3195,6.758441,-83.74822,-1.514671,-14.71785,100.0029
184.7334,970.5739,6.757228,-83.93539,-1.516328,-14.74016,100.001
184.9834,971.8257,6.756079,-84.13951,-1.518341,-14.76594,100.0096
185.2334,973.0788,6.75486,-84.32066,-1.519861,-14.78695,100.0001
185.4792,974.3119,6.75394,-84.54249,-1.522252,-14.81633,99.9803
185.7292,975.5603,6.752524,-84.74575,-1.524226,-14.84177,99.98671
185.9792,976.8129,6.751363,-84.93888,-1.525972,-14.86502,100.0099
186.2292,978.065,6.750024,-85.13598,-1.527791,-14.88898,99.99318
186.4792,979.3144,6.7489,-85.33324,-1.529616,-14.91302,99.97518
186.7292,980.567,6.747612,-85.50762,-1.530954,-14.93233,99.99288
186.9792,981.8211,6.746395,-85.71547,-1.532964,-14.9582,99.9759
187.2292,983.0691,6.745257,-85.92358,-1.534989,-14.98423,100.0019
187.4792,984.3238,6.744091,-86.12196,-1.536787,-15.00807,99.9922
187.7292,985.5765,6.74288,-86.32411,-1.538659,-15.03264,100.0212
187.9792,986.8274,6.741626,-86.52043,-1.540415,-15.0561,99.96141
188.2292,988.0812,6.7405,-86.6727,-1.541891,-15.07684,99.98456
188.4792,989.3353,6.739197,-86.8783,-1.543554,-15.09941,100.0241
188.7292,990.5853,6.737984,-87.08712,-1.54528,-15.12262,100.0322
188.9792,991.8368,6.736768,-87.31345,-1.547359,-15.1493,100.0271
189.2292,993.0881,6.735474,-87.51372,-1.548914,-15.17085,99.99247
189.4792,994.3376,6.734132,-87.72201,-1.550632,-15.194,100.0253
189.6792,995.339,6.733085,-87.90819,-1.552392,-15.21633,99.99665